[2024-01-18T09:57:12.110+0000] {taskinstance.py:1957} INFO - Dependencies all met for dep_context=non-requeueable deps ti=<TaskInstance: company_profile_pipeline.CheckTableExisting scheduled__2024-01-14T00:00:00+00:00 [queued]>
[2024-01-18T09:57:12.115+0000] {taskinstance.py:1957} INFO - Dependencies all met for dep_context=requeueable deps ti=<TaskInstance: company_profile_pipeline.CheckTableExisting scheduled__2024-01-14T00:00:00+00:00 [queued]>
[2024-01-18T09:57:12.115+0000] {taskinstance.py:2171} INFO - Starting attempt 1 of 1
[2024-01-18T09:57:12.122+0000] {taskinstance.py:2192} INFO - Executing <Task(BranchPythonOperator): CheckTableExisting> on 2024-01-14 00:00:00+00:00
[2024-01-18T09:57:12.126+0000] {standard_task_runner.py:60} INFO - Started process 107 to run task
[2024-01-18T09:57:12.129+0000] {standard_task_runner.py:87} INFO - Running: ['***', 'tasks', 'run', 'company_profile_pipeline', 'CheckTableExisting', 'scheduled__2024-01-14T00:00:00+00:00', '--job-id', '31', '--raw', '--subdir', 'DAGS_FOLDER/CrawlCompanyInfo.py', '--cfg-path', '/tmp/tmplh6ckb_a']
[2024-01-18T09:57:12.130+0000] {standard_task_runner.py:88} INFO - Job 31: Subtask CheckTableExisting
[2024-01-18T09:57:12.162+0000] {task_command.py:423} INFO - Running <TaskInstance: company_profile_pipeline.CheckTableExisting scheduled__2024-01-14T00:00:00+00:00 [running]> on host a56b2d2a6d76
[2024-01-18T09:57:12.201+0000] {taskinstance.py:2481} INFO - Exporting env vars: AIRFLOW_CTX_DAG_EMAIL='anh.ho@tititada.com' AIRFLOW_CTX_DAG_OWNER='anh.ho' AIRFLOW_CTX_DAG_ID='company_profile_pipeline' AIRFLOW_CTX_TASK_ID='CheckTableExisting' AIRFLOW_CTX_EXECUTION_DATE='2024-01-14T00:00:00+00:00' AIRFLOW_CTX_TRY_NUMBER='1' AIRFLOW_CTX_DAG_RUN_ID='scheduled__2024-01-14T00:00:00+00:00'
[2024-01-18T09:57:12.202+0000] {taskinstance.py:2699} ERROR - Task failed with exception
Traceback (most recent call last):
  File "/home/airflow/.local/lib/python3.8/site-packages/airflow/models/taskinstance.py", line 433, in _execute_task
    result = execute_callable(context=context, **execute_callable_kwargs)
  File "/home/airflow/.local/lib/python3.8/site-packages/airflow/operators/python.py", line 233, in execute
    return self.do_branch(context, super().execute(context))
  File "/home/airflow/.local/lib/python3.8/site-packages/airflow/operators/python.py", line 199, in execute
    return_value = self.execute_callable()
  File "/home/airflow/.local/lib/python3.8/site-packages/airflow/operators/python.py", line 216, in execute_callable
    return self.python_callable(*self.op_args, **self.op_kwargs)
  File "/opt/airflow/dags/CrawlCompanyInfo.py", line 55, in CheckTableExisting
    cursor = ConnectPostgres().cursor()
  File "/opt/airflow/dags/CrawlCompanyInfo.py", line 27, in ConnectPostgres
    params = ReadConfigFile(relative_path,section)
  File "/opt/airflow/dags/GetAuthInfoFuncton.py", line 25, in ReadConfigFile
    raise Exception('Section {0} not found in the {1} file'.format(section, text_file_path))
Exception: Section Postgresql not found in the /Users/anhho/Desktop/DataEngineer/CrawlStockData/CrawlFunction/Authorization.ini file
[2024-01-18T09:57:12.207+0000] {taskinstance.py:1138} INFO - Marking task as FAILED. dag_id=company_profile_pipeline, task_id=CheckTableExisting, execution_date=20240114T000000, start_date=20240118T095712, end_date=20240118T095712
[2024-01-18T09:57:12.213+0000] {warnings.py:109} WARNING - /home/***/.local/lib/python3.8/site-packages/***/utils/email.py:154: RemovedInAirflow3Warning: Fetching SMTP credentials from configuration variables will be deprecated in a future release. Please set credentials using a connection instead.
  send_mime_email(e_from=mail_from, e_to=recipients, mime_msg=msg, conn_id=conn_id, dryrun=dryrun)

[2024-01-18T09:57:12.213+0000] {configuration.py:1046} WARNING - section/key [smtp/smtp_user] not found in config
[2024-01-18T09:57:12.214+0000] {email.py:270} INFO - Email alerting: attempt 1
[2024-01-18T09:57:12.218+0000] {configuration.py:1046} WARNING - section/key [smtp/smtp_user] not found in config
[2024-01-18T09:57:12.219+0000] {email.py:270} INFO - Email alerting: attempt 1
[2024-01-18T09:57:12.219+0000] {taskinstance.py:826} ERROR - Failed to send email to: anh.ho@tititada.com
Traceback (most recent call last):
  File "/home/airflow/.local/lib/python3.8/site-packages/airflow/models/taskinstance.py", line 2335, in _run_raw_task
    self._execute_task_with_callbacks(context, test_mode, session=session)
  File "/home/airflow/.local/lib/python3.8/site-packages/airflow/models/taskinstance.py", line 2500, in _execute_task_with_callbacks
    result = self._execute_task(context, task_orig)
  File "/home/airflow/.local/lib/python3.8/site-packages/airflow/models/taskinstance.py", line 2517, in _execute_task
    return _execute_task(self, context, task_orig)
  File "/home/airflow/.local/lib/python3.8/site-packages/airflow/models/taskinstance.py", line 433, in _execute_task
    result = execute_callable(context=context, **execute_callable_kwargs)
  File "/home/airflow/.local/lib/python3.8/site-packages/airflow/operators/python.py", line 233, in execute
    return self.do_branch(context, super().execute(context))
  File "/home/airflow/.local/lib/python3.8/site-packages/airflow/operators/python.py", line 199, in execute
    return_value = self.execute_callable()
  File "/home/airflow/.local/lib/python3.8/site-packages/airflow/operators/python.py", line 216, in execute_callable
    return self.python_callable(*self.op_args, **self.op_kwargs)
  File "/opt/airflow/dags/CrawlCompanyInfo.py", line 55, in CheckTableExisting
    cursor = ConnectPostgres().cursor()
  File "/opt/airflow/dags/CrawlCompanyInfo.py", line 27, in ConnectPostgres
    params = ReadConfigFile(relative_path,section)
  File "/opt/airflow/dags/GetAuthInfoFuncton.py", line 25, in ReadConfigFile
    raise Exception('Section {0} not found in the {1} file'.format(section, text_file_path))
Exception: Section Postgresql not found in the /Users/anhho/Desktop/DataEngineer/CrawlStockData/CrawlFunction/Authorization.ini file

During handling of the above exception, another exception occurred:

Traceback (most recent call last):
  File "/home/airflow/.local/lib/python3.8/site-packages/airflow/models/taskinstance.py", line 1000, in _email_alert
    send_email(task.email, subject, html_content)
  File "/home/airflow/.local/lib/python3.8/site-packages/airflow/utils/email.py", line 80, in send_email
    return backend(
  File "/home/airflow/.local/lib/python3.8/site-packages/airflow/utils/email.py", line 154, in send_email_smtp
    send_mime_email(e_from=mail_from, e_to=recipients, mime_msg=msg, conn_id=conn_id, dryrun=dryrun)
  File "/home/airflow/.local/lib/python3.8/site-packages/airflow/utils/email.py", line 272, in send_mime_email
    smtp_conn = _get_smtp_connection(smtp_host, smtp_port, smtp_timeout, smtp_ssl)
  File "/home/airflow/.local/lib/python3.8/site-packages/airflow/utils/email.py", line 316, in _get_smtp_connection
    return smtplib.SMTP(host=host, port=port, timeout=timeout)
  File "/usr/local/lib/python3.8/smtplib.py", line 255, in __init__
    (code, msg) = self.connect(host, port)
  File "/usr/local/lib/python3.8/smtplib.py", line 339, in connect
    self.sock = self._get_socket(host, port, self.timeout)
  File "/usr/local/lib/python3.8/smtplib.py", line 310, in _get_socket
    return socket.create_connection((host, port), timeout,
  File "/usr/local/lib/python3.8/socket.py", line 808, in create_connection
    raise err
  File "/usr/local/lib/python3.8/socket.py", line 796, in create_connection
    sock.connect(sa)
OSError: [Errno 99] Cannot assign requested address

During handling of the above exception, another exception occurred:

Traceback (most recent call last):
  File "/home/airflow/.local/lib/python3.8/site-packages/airflow/models/taskinstance.py", line 824, in _handle_failure
    task_instance.email_alert(error, failure_context["task"])
  File "/home/airflow/.local/lib/python3.8/site-packages/airflow/models/taskinstance.py", line 2947, in email_alert
    _email_alert(task_instance=self, exception=exception, task=task)
  File "/home/airflow/.local/lib/python3.8/site-packages/airflow/models/taskinstance.py", line 1002, in _email_alert
    send_email(task.email, subject, html_content_err)
  File "/home/airflow/.local/lib/python3.8/site-packages/airflow/utils/email.py", line 80, in send_email
    return backend(
  File "/home/airflow/.local/lib/python3.8/site-packages/airflow/utils/email.py", line 154, in send_email_smtp
    send_mime_email(e_from=mail_from, e_to=recipients, mime_msg=msg, conn_id=conn_id, dryrun=dryrun)
  File "/home/airflow/.local/lib/python3.8/site-packages/airflow/utils/email.py", line 272, in send_mime_email
    smtp_conn = _get_smtp_connection(smtp_host, smtp_port, smtp_timeout, smtp_ssl)
  File "/home/airflow/.local/lib/python3.8/site-packages/airflow/utils/email.py", line 316, in _get_smtp_connection
    return smtplib.SMTP(host=host, port=port, timeout=timeout)
  File "/usr/local/lib/python3.8/smtplib.py", line 255, in __init__
    (code, msg) = self.connect(host, port)
  File "/usr/local/lib/python3.8/smtplib.py", line 339, in connect
    self.sock = self._get_socket(host, port, self.timeout)
  File "/usr/local/lib/python3.8/smtplib.py", line 310, in _get_socket
    return socket.create_connection((host, port), timeout,
  File "/usr/local/lib/python3.8/socket.py", line 808, in create_connection
    raise err
  File "/usr/local/lib/python3.8/socket.py", line 796, in create_connection
    sock.connect(sa)
OSError: [Errno 99] Cannot assign requested address
[2024-01-18T09:57:12.227+0000] {standard_task_runner.py:107} ERROR - Failed to execute job 31 for task CheckTableExisting (Section Postgresql not found in the /Users/anhho/Desktop/DataEngineer/CrawlStockData/CrawlFunction/Authorization.ini file; 107)
[2024-01-18T09:57:12.262+0000] {local_task_job_runner.py:234} INFO - Task exited with return code 1
[2024-01-18T09:57:12.277+0000] {taskinstance.py:3281} INFO - 0 downstream tasks scheduled from follow-on schedule check
[2024-01-18T10:00:59.726+0000] {taskinstance.py:1957} INFO - Dependencies all met for dep_context=non-requeueable deps ti=<TaskInstance: company_profile_pipeline.CheckTableExisting scheduled__2024-01-14T00:00:00+00:00 [queued]>
[2024-01-18T10:00:59.731+0000] {taskinstance.py:1957} INFO - Dependencies all met for dep_context=requeueable deps ti=<TaskInstance: company_profile_pipeline.CheckTableExisting scheduled__2024-01-14T00:00:00+00:00 [queued]>
[2024-01-18T10:00:59.732+0000] {taskinstance.py:2171} INFO - Starting attempt 1 of 1
[2024-01-18T10:00:59.737+0000] {taskinstance.py:2192} INFO - Executing <Task(BranchPythonOperator): CheckTableExisting> on 2024-01-14 00:00:00+00:00
[2024-01-18T10:00:59.740+0000] {standard_task_runner.py:60} INFO - Started process 198 to run task
[2024-01-18T10:00:59.743+0000] {standard_task_runner.py:87} INFO - Running: ['***', 'tasks', 'run', 'company_profile_pipeline', 'CheckTableExisting', 'scheduled__2024-01-14T00:00:00+00:00', '--job-id', '49', '--raw', '--subdir', 'DAGS_FOLDER/CrawlCompanyInfo.py', '--cfg-path', '/tmp/tmpcpr9kak0']
[2024-01-18T10:00:59.744+0000] {standard_task_runner.py:88} INFO - Job 49: Subtask CheckTableExisting
[2024-01-18T10:00:59.771+0000] {task_command.py:423} INFO - Running <TaskInstance: company_profile_pipeline.CheckTableExisting scheduled__2024-01-14T00:00:00+00:00 [running]> on host a56b2d2a6d76
[2024-01-18T10:00:59.808+0000] {taskinstance.py:2481} INFO - Exporting env vars: AIRFLOW_CTX_DAG_EMAIL='anh.ho@tititada.com' AIRFLOW_CTX_DAG_OWNER='anh.ho' AIRFLOW_CTX_DAG_ID='company_profile_pipeline' AIRFLOW_CTX_TASK_ID='CheckTableExisting' AIRFLOW_CTX_EXECUTION_DATE='2024-01-14T00:00:00+00:00' AIRFLOW_CTX_TRY_NUMBER='1' AIRFLOW_CTX_DAG_RUN_ID='scheduled__2024-01-14T00:00:00+00:00'
[2024-01-18T10:00:59.809+0000] {taskinstance.py:2699} ERROR - Task failed with exception
Traceback (most recent call last):
  File "/home/airflow/.local/lib/python3.8/site-packages/airflow/models/taskinstance.py", line 433, in _execute_task
    result = execute_callable(context=context, **execute_callable_kwargs)
  File "/home/airflow/.local/lib/python3.8/site-packages/airflow/operators/python.py", line 233, in execute
    return self.do_branch(context, super().execute(context))
  File "/home/airflow/.local/lib/python3.8/site-packages/airflow/operators/python.py", line 199, in execute
    return_value = self.execute_callable()
  File "/home/airflow/.local/lib/python3.8/site-packages/airflow/operators/python.py", line 216, in execute_callable
    return self.python_callable(*self.op_args, **self.op_kwargs)
  File "/opt/airflow/dags/CrawlCompanyInfo.py", line 55, in CheckTableExisting
    cursor = ConnectPostgres().cursor()
  File "/opt/airflow/dags/CrawlCompanyInfo.py", line 27, in ConnectPostgres
    params = ReadConfigFile(relative_path,section)
  File "/opt/airflow/dags/GetAuthInfoFuncton.py", line 25, in ReadConfigFile
    raise Exception('Section {section} not found in the {text_file_path} file'.format(section=section, text_file_path=text_file_path))
Exception: Section Postgresql not found in the /Users/anhho/Desktop/DataEngineer/CrawlStockData/ApacheAirflow/Authorization.ini file
[2024-01-18T10:00:59.814+0000] {taskinstance.py:1138} INFO - Marking task as FAILED. dag_id=company_profile_pipeline, task_id=CheckTableExisting, execution_date=20240114T000000, start_date=20240118T100059, end_date=20240118T100059
[2024-01-18T10:00:59.821+0000] {warnings.py:109} WARNING - /home/***/.local/lib/python3.8/site-packages/***/utils/email.py:154: RemovedInAirflow3Warning: Fetching SMTP credentials from configuration variables will be deprecated in a future release. Please set credentials using a connection instead.
  send_mime_email(e_from=mail_from, e_to=recipients, mime_msg=msg, conn_id=conn_id, dryrun=dryrun)

[2024-01-18T10:00:59.821+0000] {configuration.py:1046} WARNING - section/key [smtp/smtp_user] not found in config
[2024-01-18T10:00:59.821+0000] {email.py:270} INFO - Email alerting: attempt 1
[2024-01-18T10:00:59.825+0000] {configuration.py:1046} WARNING - section/key [smtp/smtp_user] not found in config
[2024-01-18T10:00:59.825+0000] {email.py:270} INFO - Email alerting: attempt 1
[2024-01-18T10:00:59.825+0000] {taskinstance.py:826} ERROR - Failed to send email to: anh.ho@tititada.com
Traceback (most recent call last):
  File "/home/airflow/.local/lib/python3.8/site-packages/airflow/models/taskinstance.py", line 2335, in _run_raw_task
    self._execute_task_with_callbacks(context, test_mode, session=session)
  File "/home/airflow/.local/lib/python3.8/site-packages/airflow/models/taskinstance.py", line 2500, in _execute_task_with_callbacks
    result = self._execute_task(context, task_orig)
  File "/home/airflow/.local/lib/python3.8/site-packages/airflow/models/taskinstance.py", line 2517, in _execute_task
    return _execute_task(self, context, task_orig)
  File "/home/airflow/.local/lib/python3.8/site-packages/airflow/models/taskinstance.py", line 433, in _execute_task
    result = execute_callable(context=context, **execute_callable_kwargs)
  File "/home/airflow/.local/lib/python3.8/site-packages/airflow/operators/python.py", line 233, in execute
    return self.do_branch(context, super().execute(context))
  File "/home/airflow/.local/lib/python3.8/site-packages/airflow/operators/python.py", line 199, in execute
    return_value = self.execute_callable()
  File "/home/airflow/.local/lib/python3.8/site-packages/airflow/operators/python.py", line 216, in execute_callable
    return self.python_callable(*self.op_args, **self.op_kwargs)
  File "/opt/airflow/dags/CrawlCompanyInfo.py", line 55, in CheckTableExisting
    cursor = ConnectPostgres().cursor()
  File "/opt/airflow/dags/CrawlCompanyInfo.py", line 27, in ConnectPostgres
    params = ReadConfigFile(relative_path,section)
  File "/opt/airflow/dags/GetAuthInfoFuncton.py", line 25, in ReadConfigFile
    raise Exception('Section {section} not found in the {text_file_path} file'.format(section=section, text_file_path=text_file_path))
Exception: Section Postgresql not found in the /Users/anhho/Desktop/DataEngineer/CrawlStockData/ApacheAirflow/Authorization.ini file

During handling of the above exception, another exception occurred:

Traceback (most recent call last):
  File "/home/airflow/.local/lib/python3.8/site-packages/airflow/models/taskinstance.py", line 1000, in _email_alert
    send_email(task.email, subject, html_content)
  File "/home/airflow/.local/lib/python3.8/site-packages/airflow/utils/email.py", line 80, in send_email
    return backend(
  File "/home/airflow/.local/lib/python3.8/site-packages/airflow/utils/email.py", line 154, in send_email_smtp
    send_mime_email(e_from=mail_from, e_to=recipients, mime_msg=msg, conn_id=conn_id, dryrun=dryrun)
  File "/home/airflow/.local/lib/python3.8/site-packages/airflow/utils/email.py", line 272, in send_mime_email
    smtp_conn = _get_smtp_connection(smtp_host, smtp_port, smtp_timeout, smtp_ssl)
  File "/home/airflow/.local/lib/python3.8/site-packages/airflow/utils/email.py", line 316, in _get_smtp_connection
    return smtplib.SMTP(host=host, port=port, timeout=timeout)
  File "/usr/local/lib/python3.8/smtplib.py", line 255, in __init__
    (code, msg) = self.connect(host, port)
  File "/usr/local/lib/python3.8/smtplib.py", line 339, in connect
    self.sock = self._get_socket(host, port, self.timeout)
  File "/usr/local/lib/python3.8/smtplib.py", line 310, in _get_socket
    return socket.create_connection((host, port), timeout,
  File "/usr/local/lib/python3.8/socket.py", line 808, in create_connection
    raise err
  File "/usr/local/lib/python3.8/socket.py", line 796, in create_connection
    sock.connect(sa)
OSError: [Errno 99] Cannot assign requested address

During handling of the above exception, another exception occurred:

Traceback (most recent call last):
  File "/home/airflow/.local/lib/python3.8/site-packages/airflow/models/taskinstance.py", line 824, in _handle_failure
    task_instance.email_alert(error, failure_context["task"])
  File "/home/airflow/.local/lib/python3.8/site-packages/airflow/models/taskinstance.py", line 2947, in email_alert
    _email_alert(task_instance=self, exception=exception, task=task)
  File "/home/airflow/.local/lib/python3.8/site-packages/airflow/models/taskinstance.py", line 1002, in _email_alert
    send_email(task.email, subject, html_content_err)
  File "/home/airflow/.local/lib/python3.8/site-packages/airflow/utils/email.py", line 80, in send_email
    return backend(
  File "/home/airflow/.local/lib/python3.8/site-packages/airflow/utils/email.py", line 154, in send_email_smtp
    send_mime_email(e_from=mail_from, e_to=recipients, mime_msg=msg, conn_id=conn_id, dryrun=dryrun)
  File "/home/airflow/.local/lib/python3.8/site-packages/airflow/utils/email.py", line 272, in send_mime_email
    smtp_conn = _get_smtp_connection(smtp_host, smtp_port, smtp_timeout, smtp_ssl)
  File "/home/airflow/.local/lib/python3.8/site-packages/airflow/utils/email.py", line 316, in _get_smtp_connection
    return smtplib.SMTP(host=host, port=port, timeout=timeout)
  File "/usr/local/lib/python3.8/smtplib.py", line 255, in __init__
    (code, msg) = self.connect(host, port)
  File "/usr/local/lib/python3.8/smtplib.py", line 339, in connect
    self.sock = self._get_socket(host, port, self.timeout)
  File "/usr/local/lib/python3.8/smtplib.py", line 310, in _get_socket
    return socket.create_connection((host, port), timeout,
  File "/usr/local/lib/python3.8/socket.py", line 808, in create_connection
    raise err
  File "/usr/local/lib/python3.8/socket.py", line 796, in create_connection
    sock.connect(sa)
OSError: [Errno 99] Cannot assign requested address
[2024-01-18T10:00:59.832+0000] {standard_task_runner.py:107} ERROR - Failed to execute job 49 for task CheckTableExisting (Section Postgresql not found in the /Users/anhho/Desktop/DataEngineer/CrawlStockData/ApacheAirflow/Authorization.ini file; 198)
[2024-01-18T10:00:59.876+0000] {local_task_job_runner.py:234} INFO - Task exited with return code 1
[2024-01-18T10:00:59.894+0000] {taskinstance.py:3281} INFO - 0 downstream tasks scheduled from follow-on schedule check
[2024-01-19T02:23:45.531+0000] {taskinstance.py:1957} INFO - Dependencies all met for dep_context=non-requeueable deps ti=<TaskInstance: company_profile_pipeline.CheckTableExisting scheduled__2024-01-14T00:00:00+00:00 [queued]>
[2024-01-19T02:23:45.538+0000] {taskinstance.py:1957} INFO - Dependencies all met for dep_context=requeueable deps ti=<TaskInstance: company_profile_pipeline.CheckTableExisting scheduled__2024-01-14T00:00:00+00:00 [queued]>
[2024-01-19T02:23:45.538+0000] {taskinstance.py:2171} INFO - Starting attempt 1 of 1
[2024-01-19T02:23:45.548+0000] {taskinstance.py:2192} INFO - Executing <Task(BranchPythonOperator): CheckTableExisting> on 2024-01-14 00:00:00+00:00
[2024-01-19T02:23:45.555+0000] {standard_task_runner.py:60} INFO - Started process 135 to run task
[2024-01-19T02:23:45.576+0000] {standard_task_runner.py:87} INFO - Running: ['***', 'tasks', 'run', 'company_profile_pipeline', 'CheckTableExisting', 'scheduled__2024-01-14T00:00:00+00:00', '--job-id', '83', '--raw', '--subdir', 'DAGS_FOLDER/CrawlCompanyInfo.py', '--cfg-path', '/tmp/tmpvtwxy9rw']
[2024-01-19T02:23:45.577+0000] {standard_task_runner.py:88} INFO - Job 83: Subtask CheckTableExisting
[2024-01-19T02:23:45.626+0000] {task_command.py:423} INFO - Running <TaskInstance: company_profile_pipeline.CheckTableExisting scheduled__2024-01-14T00:00:00+00:00 [running]> on host a56b2d2a6d76
[2024-01-19T02:23:45.670+0000] {taskinstance.py:2481} INFO - Exporting env vars: AIRFLOW_CTX_DAG_EMAIL='anh.ho@tititada.com' AIRFLOW_CTX_DAG_OWNER='anh.ho' AIRFLOW_CTX_DAG_ID='company_profile_pipeline' AIRFLOW_CTX_TASK_ID='CheckTableExisting' AIRFLOW_CTX_EXECUTION_DATE='2024-01-14T00:00:00+00:00' AIRFLOW_CTX_TRY_NUMBER='1' AIRFLOW_CTX_DAG_RUN_ID='scheduled__2024-01-14T00:00:00+00:00'
[2024-01-19T02:23:45.670+0000] {logging_mixin.py:188} INFO - Connecting to the PostgreSQL database...
[2024-01-19T02:25:56.791+0000] {taskinstance.py:2699} ERROR - Task failed with exception
Traceback (most recent call last):
  File "/home/airflow/.local/lib/python3.8/site-packages/airflow/models/taskinstance.py", line 433, in _execute_task
    result = execute_callable(context=context, **execute_callable_kwargs)
  File "/home/airflow/.local/lib/python3.8/site-packages/airflow/operators/python.py", line 233, in execute
    return self.do_branch(context, super().execute(context))
  File "/home/airflow/.local/lib/python3.8/site-packages/airflow/operators/python.py", line 199, in execute
    return_value = self.execute_callable()
  File "/home/airflow/.local/lib/python3.8/site-packages/airflow/operators/python.py", line 216, in execute_callable
    return self.python_callable(*self.op_args, **self.op_kwargs)
  File "/opt/airflow/dags/CrawlCompanyInfo.py", line 50, in CheckTableExisting
    cursor = ConnectPostgres().cursor()
  File "/opt/airflow/dags/CrawlCompanyInfo.py", line 41, in ConnectPostgres
    raise e
  File "/opt/airflow/dags/CrawlCompanyInfo.py", line 26, in ConnectPostgres
    conn = psycopg2.connect(**params)
  File "/home/airflow/.local/lib/python3.8/site-packages/psycopg2/__init__.py", line 122, in connect
    conn = _connect(dsn, connection_factory=connection_factory, **kwasync)
psycopg2.OperationalError: connection to server at "172.17.0.2", port 5432 failed: Connection timed out
	Is the server running on that host and accepting TCP/IP connections?

[2024-01-19T02:25:56.847+0000] {taskinstance.py:1138} INFO - Marking task as FAILED. dag_id=company_profile_pipeline, task_id=CheckTableExisting, execution_date=20240114T000000, start_date=20240119T022345, end_date=20240119T022556
[2024-01-19T02:25:56.889+0000] {warnings.py:109} WARNING - /home/***/.local/lib/python3.8/site-packages/***/utils/email.py:154: RemovedInAirflow3Warning: Fetching SMTP credentials from configuration variables will be deprecated in a future release. Please set credentials using a connection instead.
  send_mime_email(e_from=mail_from, e_to=recipients, mime_msg=msg, conn_id=conn_id, dryrun=dryrun)

[2024-01-19T02:25:56.892+0000] {configuration.py:1046} WARNING - section/key [smtp/smtp_user] not found in config
[2024-01-19T02:25:56.893+0000] {email.py:270} INFO - Email alerting: attempt 1
[2024-01-19T02:25:56.900+0000] {configuration.py:1046} WARNING - section/key [smtp/smtp_user] not found in config
[2024-01-19T02:25:56.902+0000] {email.py:270} INFO - Email alerting: attempt 1
[2024-01-19T02:25:56.903+0000] {taskinstance.py:826} ERROR - Failed to send email to: anh.ho@tititada.com
Traceback (most recent call last):
  File "/home/airflow/.local/lib/python3.8/site-packages/airflow/models/taskinstance.py", line 2335, in _run_raw_task
    self._execute_task_with_callbacks(context, test_mode, session=session)
  File "/home/airflow/.local/lib/python3.8/site-packages/airflow/models/taskinstance.py", line 2500, in _execute_task_with_callbacks
    result = self._execute_task(context, task_orig)
  File "/home/airflow/.local/lib/python3.8/site-packages/airflow/models/taskinstance.py", line 2517, in _execute_task
    return _execute_task(self, context, task_orig)
  File "/home/airflow/.local/lib/python3.8/site-packages/airflow/models/taskinstance.py", line 433, in _execute_task
    result = execute_callable(context=context, **execute_callable_kwargs)
  File "/home/airflow/.local/lib/python3.8/site-packages/airflow/operators/python.py", line 233, in execute
    return self.do_branch(context, super().execute(context))
  File "/home/airflow/.local/lib/python3.8/site-packages/airflow/operators/python.py", line 199, in execute
    return_value = self.execute_callable()
  File "/home/airflow/.local/lib/python3.8/site-packages/airflow/operators/python.py", line 216, in execute_callable
    return self.python_callable(*self.op_args, **self.op_kwargs)
  File "/opt/airflow/dags/CrawlCompanyInfo.py", line 50, in CheckTableExisting
    cursor = ConnectPostgres().cursor()
  File "/opt/airflow/dags/CrawlCompanyInfo.py", line 41, in ConnectPostgres
    raise e
  File "/opt/airflow/dags/CrawlCompanyInfo.py", line 26, in ConnectPostgres
    conn = psycopg2.connect(**params)
  File "/home/airflow/.local/lib/python3.8/site-packages/psycopg2/__init__.py", line 122, in connect
    conn = _connect(dsn, connection_factory=connection_factory, **kwasync)
psycopg2.OperationalError: connection to server at "172.17.0.2", port 5432 failed: Connection timed out
	Is the server running on that host and accepting TCP/IP connections?


During handling of the above exception, another exception occurred:

Traceback (most recent call last):
  File "/home/airflow/.local/lib/python3.8/site-packages/airflow/models/taskinstance.py", line 1000, in _email_alert
    send_email(task.email, subject, html_content)
  File "/home/airflow/.local/lib/python3.8/site-packages/airflow/utils/email.py", line 80, in send_email
    return backend(
  File "/home/airflow/.local/lib/python3.8/site-packages/airflow/utils/email.py", line 154, in send_email_smtp
    send_mime_email(e_from=mail_from, e_to=recipients, mime_msg=msg, conn_id=conn_id, dryrun=dryrun)
  File "/home/airflow/.local/lib/python3.8/site-packages/airflow/utils/email.py", line 272, in send_mime_email
    smtp_conn = _get_smtp_connection(smtp_host, smtp_port, smtp_timeout, smtp_ssl)
  File "/home/airflow/.local/lib/python3.8/site-packages/airflow/utils/email.py", line 316, in _get_smtp_connection
    return smtplib.SMTP(host=host, port=port, timeout=timeout)
  File "/usr/local/lib/python3.8/smtplib.py", line 255, in __init__
    (code, msg) = self.connect(host, port)
  File "/usr/local/lib/python3.8/smtplib.py", line 339, in connect
    self.sock = self._get_socket(host, port, self.timeout)
  File "/usr/local/lib/python3.8/smtplib.py", line 310, in _get_socket
    return socket.create_connection((host, port), timeout,
  File "/usr/local/lib/python3.8/socket.py", line 808, in create_connection
    raise err
  File "/usr/local/lib/python3.8/socket.py", line 796, in create_connection
    sock.connect(sa)
OSError: [Errno 99] Cannot assign requested address

During handling of the above exception, another exception occurred:

Traceback (most recent call last):
  File "/home/airflow/.local/lib/python3.8/site-packages/airflow/models/taskinstance.py", line 824, in _handle_failure
    task_instance.email_alert(error, failure_context["task"])
  File "/home/airflow/.local/lib/python3.8/site-packages/airflow/models/taskinstance.py", line 2947, in email_alert
    _email_alert(task_instance=self, exception=exception, task=task)
  File "/home/airflow/.local/lib/python3.8/site-packages/airflow/models/taskinstance.py", line 1002, in _email_alert
    send_email(task.email, subject, html_content_err)
  File "/home/airflow/.local/lib/python3.8/site-packages/airflow/utils/email.py", line 80, in send_email
    return backend(
  File "/home/airflow/.local/lib/python3.8/site-packages/airflow/utils/email.py", line 154, in send_email_smtp
    send_mime_email(e_from=mail_from, e_to=recipients, mime_msg=msg, conn_id=conn_id, dryrun=dryrun)
  File "/home/airflow/.local/lib/python3.8/site-packages/airflow/utils/email.py", line 272, in send_mime_email
    smtp_conn = _get_smtp_connection(smtp_host, smtp_port, smtp_timeout, smtp_ssl)
  File "/home/airflow/.local/lib/python3.8/site-packages/airflow/utils/email.py", line 316, in _get_smtp_connection
    return smtplib.SMTP(host=host, port=port, timeout=timeout)
  File "/usr/local/lib/python3.8/smtplib.py", line 255, in __init__
    (code, msg) = self.connect(host, port)
  File "/usr/local/lib/python3.8/smtplib.py", line 339, in connect
    self.sock = self._get_socket(host, port, self.timeout)
  File "/usr/local/lib/python3.8/smtplib.py", line 310, in _get_socket
    return socket.create_connection((host, port), timeout,
  File "/usr/local/lib/python3.8/socket.py", line 808, in create_connection
    raise err
  File "/usr/local/lib/python3.8/socket.py", line 796, in create_connection
    sock.connect(sa)
OSError: [Errno 99] Cannot assign requested address
[2024-01-19T02:25:56.919+0000] {standard_task_runner.py:107} ERROR - Failed to execute job 83 for task CheckTableExisting (connection to server at "172.17.0.2", port 5432 failed: Connection timed out
	Is the server running on that host and accepting TCP/IP connections?
; 135)
[2024-01-19T02:25:56.952+0000] {local_task_job_runner.py:234} INFO - Task exited with return code 1
[2024-01-19T02:25:57.000+0000] {taskinstance.py:3281} INFO - 0 downstream tasks scheduled from follow-on schedule check
[2024-01-19T02:30:19.388+0000] {taskinstance.py:1957} INFO - Dependencies all met for dep_context=non-requeueable deps ti=<TaskInstance: company_profile_pipeline.CheckTableExisting scheduled__2024-01-14T00:00:00+00:00 [queued]>
[2024-01-19T02:30:19.392+0000] {taskinstance.py:1957} INFO - Dependencies all met for dep_context=requeueable deps ti=<TaskInstance: company_profile_pipeline.CheckTableExisting scheduled__2024-01-14T00:00:00+00:00 [queued]>
[2024-01-19T02:30:19.393+0000] {taskinstance.py:2171} INFO - Starting attempt 1 of 1
[2024-01-19T02:30:19.398+0000] {taskinstance.py:2192} INFO - Executing <Task(BranchPythonOperator): CheckTableExisting> on 2024-01-14 00:00:00+00:00
[2024-01-19T02:30:19.402+0000] {standard_task_runner.py:60} INFO - Started process 277 to run task
[2024-01-19T02:30:19.406+0000] {standard_task_runner.py:87} INFO - Running: ['***', 'tasks', 'run', 'company_profile_pipeline', 'CheckTableExisting', 'scheduled__2024-01-14T00:00:00+00:00', '--job-id', '102', '--raw', '--subdir', 'DAGS_FOLDER/CrawlCompanyInfo.py', '--cfg-path', '/tmp/tmpwl0l1e3g']
[2024-01-19T02:30:19.407+0000] {standard_task_runner.py:88} INFO - Job 102: Subtask CheckTableExisting
[2024-01-19T02:30:19.464+0000] {task_command.py:423} INFO - Running <TaskInstance: company_profile_pipeline.CheckTableExisting scheduled__2024-01-14T00:00:00+00:00 [running]> on host a56b2d2a6d76
[2024-01-19T02:30:19.503+0000] {taskinstance.py:2481} INFO - Exporting env vars: AIRFLOW_CTX_DAG_EMAIL='anh.ho@tititada.com' AIRFLOW_CTX_DAG_OWNER='anh.ho' AIRFLOW_CTX_DAG_ID='company_profile_pipeline' AIRFLOW_CTX_TASK_ID='CheckTableExisting' AIRFLOW_CTX_EXECUTION_DATE='2024-01-14T00:00:00+00:00' AIRFLOW_CTX_TRY_NUMBER='1' AIRFLOW_CTX_DAG_RUN_ID='scheduled__2024-01-14T00:00:00+00:00'
[2024-01-19T02:30:19.504+0000] {logging_mixin.py:188} INFO - Connecting to the PostgreSQL database...
[2024-01-19T03:14:26.254+0000] {taskinstance.py:1957} INFO - Dependencies all met for dep_context=non-requeueable deps ti=<TaskInstance: company_profile_pipeline.CheckTableExisting scheduled__2024-01-14T00:00:00+00:00 [queued]>
[2024-01-19T03:14:26.262+0000] {taskinstance.py:1957} INFO - Dependencies all met for dep_context=requeueable deps ti=<TaskInstance: company_profile_pipeline.CheckTableExisting scheduled__2024-01-14T00:00:00+00:00 [queued]>
[2024-01-19T03:14:26.262+0000] {taskinstance.py:2171} INFO - Starting attempt 1 of 1
[2024-01-19T03:14:26.271+0000] {taskinstance.py:2192} INFO - Executing <Task(BranchPythonOperator): CheckTableExisting> on 2024-01-14 00:00:00+00:00
[2024-01-19T03:14:26.277+0000] {standard_task_runner.py:60} INFO - Started process 166 to run task
[2024-01-19T03:14:26.286+0000] {standard_task_runner.py:87} INFO - Running: ['***', 'tasks', 'run', 'company_profile_pipeline', 'CheckTableExisting', 'scheduled__2024-01-14T00:00:00+00:00', '--job-id', '154', '--raw', '--subdir', 'DAGS_FOLDER/CrawlCompanyInfo.py', '--cfg-path', '/tmp/tmpmt7re5b_']
[2024-01-19T03:14:26.288+0000] {standard_task_runner.py:88} INFO - Job 154: Subtask CheckTableExisting
[2024-01-19T03:14:26.368+0000] {task_command.py:423} INFO - Running <TaskInstance: company_profile_pipeline.CheckTableExisting scheduled__2024-01-14T00:00:00+00:00 [running]> on host a56b2d2a6d76
[2024-01-19T03:14:26.424+0000] {taskinstance.py:2481} INFO - Exporting env vars: AIRFLOW_CTX_DAG_EMAIL='anh.ho@tititada.com' AIRFLOW_CTX_DAG_OWNER='anh.ho' AIRFLOW_CTX_DAG_ID='company_profile_pipeline' AIRFLOW_CTX_TASK_ID='CheckTableExisting' AIRFLOW_CTX_EXECUTION_DATE='2024-01-14T00:00:00+00:00' AIRFLOW_CTX_TRY_NUMBER='1' AIRFLOW_CTX_DAG_RUN_ID='scheduled__2024-01-14T00:00:00+00:00'
[2024-01-19T03:14:26.426+0000] {logging_mixin.py:188} INFO - Connecting to the PostgreSQL database...
[2024-01-19T03:14:26.426+0000] {taskinstance.py:2699} ERROR - Task failed with exception
Traceback (most recent call last):
  File "/home/airflow/.local/lib/python3.8/site-packages/airflow/models/taskinstance.py", line 433, in _execute_task
    result = execute_callable(context=context, **execute_callable_kwargs)
  File "/home/airflow/.local/lib/python3.8/site-packages/airflow/operators/python.py", line 233, in execute
    return self.do_branch(context, super().execute(context))
  File "/home/airflow/.local/lib/python3.8/site-packages/airflow/operators/python.py", line 199, in execute
    return_value = self.execute_callable()
  File "/home/airflow/.local/lib/python3.8/site-packages/airflow/operators/python.py", line 216, in execute_callable
    return self.python_callable(*self.op_args, **self.op_kwargs)
  File "/opt/airflow/dags/CrawlCompanyInfo.py", line 50, in CheckTableExisting
    cursor = ConnectPostgres().cursor()
  File "/opt/airflow/dags/CrawlCompanyInfo.py", line 41, in ConnectPostgres
    raise e
  File "/opt/airflow/dags/CrawlCompanyInfo.py", line 26, in ConnectPostgres
    conn = psycopg2.connect(**params)
  File "/home/airflow/.local/lib/python3.8/site-packages/psycopg2/__init__.py", line 122, in connect
    conn = _connect(dsn, connection_factory=connection_factory, **kwasync)
psycopg2.OperationalError: connection to server at "0.0.0.0", port 5432 failed: Connection refused
	Is the server running on that host and accepting TCP/IP connections?

[2024-01-19T03:14:26.434+0000] {taskinstance.py:1138} INFO - Marking task as FAILED. dag_id=company_profile_pipeline, task_id=CheckTableExisting, execution_date=20240114T000000, start_date=20240119T031426, end_date=20240119T031426
[2024-01-19T03:14:26.441+0000] {warnings.py:109} WARNING - /home/***/.local/lib/python3.8/site-packages/***/utils/email.py:154: RemovedInAirflow3Warning: Fetching SMTP credentials from configuration variables will be deprecated in a future release. Please set credentials using a connection instead.
  send_mime_email(e_from=mail_from, e_to=recipients, mime_msg=msg, conn_id=conn_id, dryrun=dryrun)

[2024-01-19T03:14:26.442+0000] {configuration.py:1046} WARNING - section/key [smtp/smtp_user] not found in config
[2024-01-19T03:14:26.442+0000] {email.py:270} INFO - Email alerting: attempt 1
[2024-01-19T03:14:26.448+0000] {configuration.py:1046} WARNING - section/key [smtp/smtp_user] not found in config
[2024-01-19T03:14:26.449+0000] {email.py:270} INFO - Email alerting: attempt 1
[2024-01-19T03:14:26.449+0000] {taskinstance.py:826} ERROR - Failed to send email to: anh.ho@tititada.com
Traceback (most recent call last):
  File "/home/airflow/.local/lib/python3.8/site-packages/airflow/models/taskinstance.py", line 2335, in _run_raw_task
    self._execute_task_with_callbacks(context, test_mode, session=session)
  File "/home/airflow/.local/lib/python3.8/site-packages/airflow/models/taskinstance.py", line 2500, in _execute_task_with_callbacks
    result = self._execute_task(context, task_orig)
  File "/home/airflow/.local/lib/python3.8/site-packages/airflow/models/taskinstance.py", line 2517, in _execute_task
    return _execute_task(self, context, task_orig)
  File "/home/airflow/.local/lib/python3.8/site-packages/airflow/models/taskinstance.py", line 433, in _execute_task
    result = execute_callable(context=context, **execute_callable_kwargs)
  File "/home/airflow/.local/lib/python3.8/site-packages/airflow/operators/python.py", line 233, in execute
    return self.do_branch(context, super().execute(context))
  File "/home/airflow/.local/lib/python3.8/site-packages/airflow/operators/python.py", line 199, in execute
    return_value = self.execute_callable()
  File "/home/airflow/.local/lib/python3.8/site-packages/airflow/operators/python.py", line 216, in execute_callable
    return self.python_callable(*self.op_args, **self.op_kwargs)
  File "/opt/airflow/dags/CrawlCompanyInfo.py", line 50, in CheckTableExisting
    cursor = ConnectPostgres().cursor()
  File "/opt/airflow/dags/CrawlCompanyInfo.py", line 41, in ConnectPostgres
    raise e
  File "/opt/airflow/dags/CrawlCompanyInfo.py", line 26, in ConnectPostgres
    conn = psycopg2.connect(**params)
  File "/home/airflow/.local/lib/python3.8/site-packages/psycopg2/__init__.py", line 122, in connect
    conn = _connect(dsn, connection_factory=connection_factory, **kwasync)
psycopg2.OperationalError: connection to server at "0.0.0.0", port 5432 failed: Connection refused
	Is the server running on that host and accepting TCP/IP connections?


During handling of the above exception, another exception occurred:

Traceback (most recent call last):
  File "/home/airflow/.local/lib/python3.8/site-packages/airflow/models/taskinstance.py", line 1000, in _email_alert
    send_email(task.email, subject, html_content)
  File "/home/airflow/.local/lib/python3.8/site-packages/airflow/utils/email.py", line 80, in send_email
    return backend(
  File "/home/airflow/.local/lib/python3.8/site-packages/airflow/utils/email.py", line 154, in send_email_smtp
    send_mime_email(e_from=mail_from, e_to=recipients, mime_msg=msg, conn_id=conn_id, dryrun=dryrun)
  File "/home/airflow/.local/lib/python3.8/site-packages/airflow/utils/email.py", line 272, in send_mime_email
    smtp_conn = _get_smtp_connection(smtp_host, smtp_port, smtp_timeout, smtp_ssl)
  File "/home/airflow/.local/lib/python3.8/site-packages/airflow/utils/email.py", line 316, in _get_smtp_connection
    return smtplib.SMTP(host=host, port=port, timeout=timeout)
  File "/usr/local/lib/python3.8/smtplib.py", line 255, in __init__
    (code, msg) = self.connect(host, port)
  File "/usr/local/lib/python3.8/smtplib.py", line 339, in connect
    self.sock = self._get_socket(host, port, self.timeout)
  File "/usr/local/lib/python3.8/smtplib.py", line 310, in _get_socket
    return socket.create_connection((host, port), timeout,
  File "/usr/local/lib/python3.8/socket.py", line 808, in create_connection
    raise err
  File "/usr/local/lib/python3.8/socket.py", line 796, in create_connection
    sock.connect(sa)
OSError: [Errno 99] Cannot assign requested address

During handling of the above exception, another exception occurred:

Traceback (most recent call last):
  File "/home/airflow/.local/lib/python3.8/site-packages/airflow/models/taskinstance.py", line 824, in _handle_failure
    task_instance.email_alert(error, failure_context["task"])
  File "/home/airflow/.local/lib/python3.8/site-packages/airflow/models/taskinstance.py", line 2947, in email_alert
    _email_alert(task_instance=self, exception=exception, task=task)
  File "/home/airflow/.local/lib/python3.8/site-packages/airflow/models/taskinstance.py", line 1002, in _email_alert
    send_email(task.email, subject, html_content_err)
  File "/home/airflow/.local/lib/python3.8/site-packages/airflow/utils/email.py", line 80, in send_email
    return backend(
  File "/home/airflow/.local/lib/python3.8/site-packages/airflow/utils/email.py", line 154, in send_email_smtp
    send_mime_email(e_from=mail_from, e_to=recipients, mime_msg=msg, conn_id=conn_id, dryrun=dryrun)
  File "/home/airflow/.local/lib/python3.8/site-packages/airflow/utils/email.py", line 272, in send_mime_email
    smtp_conn = _get_smtp_connection(smtp_host, smtp_port, smtp_timeout, smtp_ssl)
  File "/home/airflow/.local/lib/python3.8/site-packages/airflow/utils/email.py", line 316, in _get_smtp_connection
    return smtplib.SMTP(host=host, port=port, timeout=timeout)
  File "/usr/local/lib/python3.8/smtplib.py", line 255, in __init__
    (code, msg) = self.connect(host, port)
  File "/usr/local/lib/python3.8/smtplib.py", line 339, in connect
    self.sock = self._get_socket(host, port, self.timeout)
  File "/usr/local/lib/python3.8/smtplib.py", line 310, in _get_socket
    return socket.create_connection((host, port), timeout,
  File "/usr/local/lib/python3.8/socket.py", line 808, in create_connection
    raise err
  File "/usr/local/lib/python3.8/socket.py", line 796, in create_connection
    sock.connect(sa)
OSError: [Errno 99] Cannot assign requested address
[2024-01-19T03:14:26.457+0000] {standard_task_runner.py:107} ERROR - Failed to execute job 154 for task CheckTableExisting (connection to server at "0.0.0.0", port 5432 failed: Connection refused
	Is the server running on that host and accepting TCP/IP connections?
; 166)
[2024-01-19T03:14:26.476+0000] {local_task_job_runner.py:234} INFO - Task exited with return code 1
[2024-01-19T03:14:26.495+0000] {taskinstance.py:3281} INFO - 0 downstream tasks scheduled from follow-on schedule check
[2024-01-19T03:16:04.401+0000] {taskinstance.py:1957} INFO - Dependencies all met for dep_context=non-requeueable deps ti=<TaskInstance: company_profile_pipeline.CheckTableExisting scheduled__2024-01-14T00:00:00+00:00 [queued]>
[2024-01-19T03:16:04.405+0000] {taskinstance.py:1957} INFO - Dependencies all met for dep_context=requeueable deps ti=<TaskInstance: company_profile_pipeline.CheckTableExisting scheduled__2024-01-14T00:00:00+00:00 [queued]>
[2024-01-19T03:16:04.406+0000] {taskinstance.py:2171} INFO - Starting attempt 1 of 1
[2024-01-19T03:16:04.411+0000] {taskinstance.py:2192} INFO - Executing <Task(BranchPythonOperator): CheckTableExisting> on 2024-01-14 00:00:00+00:00
[2024-01-19T03:16:04.414+0000] {standard_task_runner.py:60} INFO - Started process 241 to run task
[2024-01-19T03:16:04.417+0000] {standard_task_runner.py:87} INFO - Running: ['***', 'tasks', 'run', 'company_profile_pipeline', 'CheckTableExisting', 'scheduled__2024-01-14T00:00:00+00:00', '--job-id', '181', '--raw', '--subdir', 'DAGS_FOLDER/CrawlCompanyInfo.py', '--cfg-path', '/tmp/tmpjotbhop5']
[2024-01-19T03:16:04.418+0000] {standard_task_runner.py:88} INFO - Job 181: Subtask CheckTableExisting
[2024-01-19T03:16:04.443+0000] {task_command.py:423} INFO - Running <TaskInstance: company_profile_pipeline.CheckTableExisting scheduled__2024-01-14T00:00:00+00:00 [running]> on host a56b2d2a6d76
[2024-01-19T03:16:04.476+0000] {taskinstance.py:2481} INFO - Exporting env vars: AIRFLOW_CTX_DAG_EMAIL='anh.ho@tititada.com' AIRFLOW_CTX_DAG_OWNER='anh.ho' AIRFLOW_CTX_DAG_ID='company_profile_pipeline' AIRFLOW_CTX_TASK_ID='CheckTableExisting' AIRFLOW_CTX_EXECUTION_DATE='2024-01-14T00:00:00+00:00' AIRFLOW_CTX_TRY_NUMBER='1' AIRFLOW_CTX_DAG_RUN_ID='scheduled__2024-01-14T00:00:00+00:00'
[2024-01-19T03:16:04.477+0000] {logging_mixin.py:188} INFO - Connecting to the PostgreSQL database...
[2024-01-19T03:16:04.477+0000] {taskinstance.py:2699} ERROR - Task failed with exception
Traceback (most recent call last):
  File "/home/airflow/.local/lib/python3.8/site-packages/airflow/models/taskinstance.py", line 433, in _execute_task
    result = execute_callable(context=context, **execute_callable_kwargs)
  File "/home/airflow/.local/lib/python3.8/site-packages/airflow/operators/python.py", line 233, in execute
    return self.do_branch(context, super().execute(context))
  File "/home/airflow/.local/lib/python3.8/site-packages/airflow/operators/python.py", line 199, in execute
    return_value = self.execute_callable()
  File "/home/airflow/.local/lib/python3.8/site-packages/airflow/operators/python.py", line 216, in execute_callable
    return self.python_callable(*self.op_args, **self.op_kwargs)
  File "/opt/airflow/dags/CrawlCompanyInfo.py", line 50, in CheckTableExisting
    cursor = ConnectPostgres().cursor()
  File "/opt/airflow/dags/CrawlCompanyInfo.py", line 41, in ConnectPostgres
    raise e
  File "/opt/airflow/dags/CrawlCompanyInfo.py", line 26, in ConnectPostgres
    conn = psycopg2.connect(**params)
  File "/home/airflow/.local/lib/python3.8/site-packages/psycopg2/__init__.py", line 122, in connect
    conn = _connect(dsn, connection_factory=connection_factory, **kwasync)
psycopg2.OperationalError: connection to server at "0.0.0.0", port 5432 failed: Connection refused
	Is the server running on that host and accepting TCP/IP connections?

[2024-01-19T03:16:04.482+0000] {taskinstance.py:1138} INFO - Marking task as FAILED. dag_id=company_profile_pipeline, task_id=CheckTableExisting, execution_date=20240114T000000, start_date=20240119T031604, end_date=20240119T031604
[2024-01-19T03:16:04.488+0000] {warnings.py:109} WARNING - /home/***/.local/lib/python3.8/site-packages/***/utils/email.py:154: RemovedInAirflow3Warning: Fetching SMTP credentials from configuration variables will be deprecated in a future release. Please set credentials using a connection instead.
  send_mime_email(e_from=mail_from, e_to=recipients, mime_msg=msg, conn_id=conn_id, dryrun=dryrun)

[2024-01-19T03:16:04.488+0000] {configuration.py:1046} WARNING - section/key [smtp/smtp_user] not found in config
[2024-01-19T03:16:04.488+0000] {email.py:270} INFO - Email alerting: attempt 1
[2024-01-19T03:16:04.492+0000] {configuration.py:1046} WARNING - section/key [smtp/smtp_user] not found in config
[2024-01-19T03:16:04.492+0000] {email.py:270} INFO - Email alerting: attempt 1
[2024-01-19T03:16:04.492+0000] {taskinstance.py:826} ERROR - Failed to send email to: anh.ho@tititada.com
Traceback (most recent call last):
  File "/home/airflow/.local/lib/python3.8/site-packages/airflow/models/taskinstance.py", line 2335, in _run_raw_task
    self._execute_task_with_callbacks(context, test_mode, session=session)
  File "/home/airflow/.local/lib/python3.8/site-packages/airflow/models/taskinstance.py", line 2500, in _execute_task_with_callbacks
    result = self._execute_task(context, task_orig)
  File "/home/airflow/.local/lib/python3.8/site-packages/airflow/models/taskinstance.py", line 2517, in _execute_task
    return _execute_task(self, context, task_orig)
  File "/home/airflow/.local/lib/python3.8/site-packages/airflow/models/taskinstance.py", line 433, in _execute_task
    result = execute_callable(context=context, **execute_callable_kwargs)
  File "/home/airflow/.local/lib/python3.8/site-packages/airflow/operators/python.py", line 233, in execute
    return self.do_branch(context, super().execute(context))
  File "/home/airflow/.local/lib/python3.8/site-packages/airflow/operators/python.py", line 199, in execute
    return_value = self.execute_callable()
  File "/home/airflow/.local/lib/python3.8/site-packages/airflow/operators/python.py", line 216, in execute_callable
    return self.python_callable(*self.op_args, **self.op_kwargs)
  File "/opt/airflow/dags/CrawlCompanyInfo.py", line 50, in CheckTableExisting
    cursor = ConnectPostgres().cursor()
  File "/opt/airflow/dags/CrawlCompanyInfo.py", line 41, in ConnectPostgres
    raise e
  File "/opt/airflow/dags/CrawlCompanyInfo.py", line 26, in ConnectPostgres
    conn = psycopg2.connect(**params)
  File "/home/airflow/.local/lib/python3.8/site-packages/psycopg2/__init__.py", line 122, in connect
    conn = _connect(dsn, connection_factory=connection_factory, **kwasync)
psycopg2.OperationalError: connection to server at "0.0.0.0", port 5432 failed: Connection refused
	Is the server running on that host and accepting TCP/IP connections?


During handling of the above exception, another exception occurred:

Traceback (most recent call last):
  File "/home/airflow/.local/lib/python3.8/site-packages/airflow/models/taskinstance.py", line 1000, in _email_alert
    send_email(task.email, subject, html_content)
  File "/home/airflow/.local/lib/python3.8/site-packages/airflow/utils/email.py", line 80, in send_email
    return backend(
  File "/home/airflow/.local/lib/python3.8/site-packages/airflow/utils/email.py", line 154, in send_email_smtp
    send_mime_email(e_from=mail_from, e_to=recipients, mime_msg=msg, conn_id=conn_id, dryrun=dryrun)
  File "/home/airflow/.local/lib/python3.8/site-packages/airflow/utils/email.py", line 272, in send_mime_email
    smtp_conn = _get_smtp_connection(smtp_host, smtp_port, smtp_timeout, smtp_ssl)
  File "/home/airflow/.local/lib/python3.8/site-packages/airflow/utils/email.py", line 316, in _get_smtp_connection
    return smtplib.SMTP(host=host, port=port, timeout=timeout)
  File "/usr/local/lib/python3.8/smtplib.py", line 255, in __init__
    (code, msg) = self.connect(host, port)
  File "/usr/local/lib/python3.8/smtplib.py", line 339, in connect
    self.sock = self._get_socket(host, port, self.timeout)
  File "/usr/local/lib/python3.8/smtplib.py", line 310, in _get_socket
    return socket.create_connection((host, port), timeout,
  File "/usr/local/lib/python3.8/socket.py", line 808, in create_connection
    raise err
  File "/usr/local/lib/python3.8/socket.py", line 796, in create_connection
    sock.connect(sa)
OSError: [Errno 99] Cannot assign requested address

During handling of the above exception, another exception occurred:

Traceback (most recent call last):
  File "/home/airflow/.local/lib/python3.8/site-packages/airflow/models/taskinstance.py", line 824, in _handle_failure
    task_instance.email_alert(error, failure_context["task"])
  File "/home/airflow/.local/lib/python3.8/site-packages/airflow/models/taskinstance.py", line 2947, in email_alert
    _email_alert(task_instance=self, exception=exception, task=task)
  File "/home/airflow/.local/lib/python3.8/site-packages/airflow/models/taskinstance.py", line 1002, in _email_alert
    send_email(task.email, subject, html_content_err)
  File "/home/airflow/.local/lib/python3.8/site-packages/airflow/utils/email.py", line 80, in send_email
    return backend(
  File "/home/airflow/.local/lib/python3.8/site-packages/airflow/utils/email.py", line 154, in send_email_smtp
    send_mime_email(e_from=mail_from, e_to=recipients, mime_msg=msg, conn_id=conn_id, dryrun=dryrun)
  File "/home/airflow/.local/lib/python3.8/site-packages/airflow/utils/email.py", line 272, in send_mime_email
    smtp_conn = _get_smtp_connection(smtp_host, smtp_port, smtp_timeout, smtp_ssl)
  File "/home/airflow/.local/lib/python3.8/site-packages/airflow/utils/email.py", line 316, in _get_smtp_connection
    return smtplib.SMTP(host=host, port=port, timeout=timeout)
  File "/usr/local/lib/python3.8/smtplib.py", line 255, in __init__
    (code, msg) = self.connect(host, port)
  File "/usr/local/lib/python3.8/smtplib.py", line 339, in connect
    self.sock = self._get_socket(host, port, self.timeout)
  File "/usr/local/lib/python3.8/smtplib.py", line 310, in _get_socket
    return socket.create_connection((host, port), timeout,
  File "/usr/local/lib/python3.8/socket.py", line 808, in create_connection
    raise err
  File "/usr/local/lib/python3.8/socket.py", line 796, in create_connection
    sock.connect(sa)
OSError: [Errno 99] Cannot assign requested address
[2024-01-19T03:16:04.499+0000] {standard_task_runner.py:107} ERROR - Failed to execute job 181 for task CheckTableExisting (connection to server at "0.0.0.0", port 5432 failed: Connection refused
	Is the server running on that host and accepting TCP/IP connections?
; 241)
[2024-01-19T03:16:04.509+0000] {local_task_job_runner.py:234} INFO - Task exited with return code 1
[2024-01-19T03:16:04.524+0000] {taskinstance.py:3281} INFO - 0 downstream tasks scheduled from follow-on schedule check
[2024-01-19T04:05:38.578+0000] {taskinstance.py:1957} INFO - Dependencies all met for dep_context=non-requeueable deps ti=<TaskInstance: company_profile_pipeline.CheckTableExisting scheduled__2024-01-14T00:00:00+00:00 [queued]>
[2024-01-19T04:05:38.583+0000] {taskinstance.py:1957} INFO - Dependencies all met for dep_context=requeueable deps ti=<TaskInstance: company_profile_pipeline.CheckTableExisting scheduled__2024-01-14T00:00:00+00:00 [queued]>
[2024-01-19T04:05:38.583+0000] {taskinstance.py:2171} INFO - Starting attempt 1 of 1
[2024-01-19T04:05:38.588+0000] {taskinstance.py:2192} INFO - Executing <Task(BranchPythonOperator): CheckTableExisting> on 2024-01-14 00:00:00+00:00
[2024-01-19T04:05:38.592+0000] {standard_task_runner.py:60} INFO - Started process 114 to run task
[2024-01-19T04:05:38.594+0000] {standard_task_runner.py:87} INFO - Running: ['***', 'tasks', 'run', 'company_profile_pipeline', 'CheckTableExisting', 'scheduled__2024-01-14T00:00:00+00:00', '--job-id', '215', '--raw', '--subdir', 'DAGS_FOLDER/CrawlCompanyInfo.py', '--cfg-path', '/tmp/tmp7u2q35ir']
[2024-01-19T04:05:38.595+0000] {standard_task_runner.py:88} INFO - Job 215: Subtask CheckTableExisting
[2024-01-19T04:05:38.620+0000] {task_command.py:423} INFO - Running <TaskInstance: company_profile_pipeline.CheckTableExisting scheduled__2024-01-14T00:00:00+00:00 [running]> on host f27b64f975c2
[2024-01-19T04:05:38.655+0000] {taskinstance.py:2481} INFO - Exporting env vars: AIRFLOW_CTX_DAG_EMAIL='anh.ho@tititada.com' AIRFLOW_CTX_DAG_OWNER='anh.ho' AIRFLOW_CTX_DAG_ID='company_profile_pipeline' AIRFLOW_CTX_TASK_ID='CheckTableExisting' AIRFLOW_CTX_EXECUTION_DATE='2024-01-14T00:00:00+00:00' AIRFLOW_CTX_TRY_NUMBER='1' AIRFLOW_CTX_DAG_RUN_ID='scheduled__2024-01-14T00:00:00+00:00'
[2024-01-19T04:05:38.655+0000] {logging_mixin.py:188} INFO - Connecting to the PostgreSQL database...
[2024-01-19T04:05:38.657+0000] {logging_mixin.py:188} INFO - PostgreSQL database version:
[2024-01-19T04:05:38.658+0000] {logging_mixin.py:188} INFO - Successfully connect to Postgresql
[2024-01-19T04:05:38.658+0000] {logging_mixin.py:188} INFO - ('PostgreSQL 13.13 (Debian 13.13-1.pgdg120+1) on aarch64-unknown-linux-gnu, compiled by gcc (Debian 12.2.0-14) 12.2.0, 64-bit',)
[2024-01-19T04:05:38.658+0000] {logging_mixin.py:188} INFO - Checking existing table...
[2024-01-19T04:05:38.659+0000] {python.py:201} INFO - Done. Returned value was: InsertDataFunction
[2024-01-19T04:05:38.659+0000] {branch.py:35} INFO - Branch into InsertDataFunction
[2024-01-19T04:05:38.659+0000] {skipmixin.py:178} INFO - Following branch InsertDataFunction
[2024-01-19T04:05:38.664+0000] {taskinstance.py:2699} ERROR - Task failed with exception
Traceback (most recent call last):
  File "/home/airflow/.local/lib/python3.8/site-packages/airflow/models/taskinstance.py", line 433, in _execute_task
    result = execute_callable(context=context, **execute_callable_kwargs)
  File "/home/airflow/.local/lib/python3.8/site-packages/airflow/operators/python.py", line 233, in execute
    return self.do_branch(context, super().execute(context))
  File "/home/airflow/.local/lib/python3.8/site-packages/airflow/operators/branch.py", line 36, in do_branch
    self.skip_all_except(context["ti"], branches_to_execute)
  File "/home/airflow/.local/lib/python3.8/site-packages/airflow/models/skipmixin.py", line 213, in skip_all_except
    raise AirflowException(
airflow.exceptions.AirflowException: 'branch_task_ids' must contain only valid task_ids. Invalid tasks found: {'InsertDataFunction'}.
[2024-01-19T04:05:38.666+0000] {taskinstance.py:1138} INFO - Marking task as FAILED. dag_id=company_profile_pipeline, task_id=CheckTableExisting, execution_date=20240114T000000, start_date=20240119T040538, end_date=20240119T040538
[2024-01-19T04:05:38.672+0000] {warnings.py:109} WARNING - /home/***/.local/lib/python3.8/site-packages/***/utils/email.py:154: RemovedInAirflow3Warning: Fetching SMTP credentials from configuration variables will be deprecated in a future release. Please set credentials using a connection instead.
  send_mime_email(e_from=mail_from, e_to=recipients, mime_msg=msg, conn_id=conn_id, dryrun=dryrun)

[2024-01-19T04:05:38.673+0000] {configuration.py:1046} WARNING - section/key [smtp/smtp_user] not found in config
[2024-01-19T04:05:38.673+0000] {email.py:270} INFO - Email alerting: attempt 1
[2024-01-19T04:05:38.677+0000] {configuration.py:1046} WARNING - section/key [smtp/smtp_user] not found in config
[2024-01-19T04:05:38.677+0000] {email.py:270} INFO - Email alerting: attempt 1
[2024-01-19T04:05:38.677+0000] {taskinstance.py:826} ERROR - Failed to send email to: anh.ho@tititada.com
Traceback (most recent call last):
  File "/home/airflow/.local/lib/python3.8/site-packages/airflow/models/taskinstance.py", line 2335, in _run_raw_task
    self._execute_task_with_callbacks(context, test_mode, session=session)
  File "/home/airflow/.local/lib/python3.8/site-packages/airflow/models/taskinstance.py", line 2500, in _execute_task_with_callbacks
    result = self._execute_task(context, task_orig)
  File "/home/airflow/.local/lib/python3.8/site-packages/airflow/models/taskinstance.py", line 2517, in _execute_task
    return _execute_task(self, context, task_orig)
  File "/home/airflow/.local/lib/python3.8/site-packages/airflow/models/taskinstance.py", line 433, in _execute_task
    result = execute_callable(context=context, **execute_callable_kwargs)
  File "/home/airflow/.local/lib/python3.8/site-packages/airflow/operators/python.py", line 233, in execute
    return self.do_branch(context, super().execute(context))
  File "/home/airflow/.local/lib/python3.8/site-packages/airflow/operators/branch.py", line 36, in do_branch
    self.skip_all_except(context["ti"], branches_to_execute)
  File "/home/airflow/.local/lib/python3.8/site-packages/airflow/models/skipmixin.py", line 213, in skip_all_except
    raise AirflowException(
airflow.exceptions.AirflowException: 'branch_task_ids' must contain only valid task_ids. Invalid tasks found: {'InsertDataFunction'}.

During handling of the above exception, another exception occurred:

Traceback (most recent call last):
  File "/home/airflow/.local/lib/python3.8/site-packages/airflow/models/taskinstance.py", line 1000, in _email_alert
    send_email(task.email, subject, html_content)
  File "/home/airflow/.local/lib/python3.8/site-packages/airflow/utils/email.py", line 80, in send_email
    return backend(
  File "/home/airflow/.local/lib/python3.8/site-packages/airflow/utils/email.py", line 154, in send_email_smtp
    send_mime_email(e_from=mail_from, e_to=recipients, mime_msg=msg, conn_id=conn_id, dryrun=dryrun)
  File "/home/airflow/.local/lib/python3.8/site-packages/airflow/utils/email.py", line 272, in send_mime_email
    smtp_conn = _get_smtp_connection(smtp_host, smtp_port, smtp_timeout, smtp_ssl)
  File "/home/airflow/.local/lib/python3.8/site-packages/airflow/utils/email.py", line 316, in _get_smtp_connection
    return smtplib.SMTP(host=host, port=port, timeout=timeout)
  File "/usr/local/lib/python3.8/smtplib.py", line 255, in __init__
    (code, msg) = self.connect(host, port)
  File "/usr/local/lib/python3.8/smtplib.py", line 339, in connect
    self.sock = self._get_socket(host, port, self.timeout)
  File "/usr/local/lib/python3.8/smtplib.py", line 310, in _get_socket
    return socket.create_connection((host, port), timeout,
  File "/usr/local/lib/python3.8/socket.py", line 808, in create_connection
    raise err
  File "/usr/local/lib/python3.8/socket.py", line 796, in create_connection
    sock.connect(sa)
OSError: [Errno 99] Cannot assign requested address

During handling of the above exception, another exception occurred:

Traceback (most recent call last):
  File "/home/airflow/.local/lib/python3.8/site-packages/airflow/models/taskinstance.py", line 824, in _handle_failure
    task_instance.email_alert(error, failure_context["task"])
  File "/home/airflow/.local/lib/python3.8/site-packages/airflow/models/taskinstance.py", line 2947, in email_alert
    _email_alert(task_instance=self, exception=exception, task=task)
  File "/home/airflow/.local/lib/python3.8/site-packages/airflow/models/taskinstance.py", line 1002, in _email_alert
    send_email(task.email, subject, html_content_err)
  File "/home/airflow/.local/lib/python3.8/site-packages/airflow/utils/email.py", line 80, in send_email
    return backend(
  File "/home/airflow/.local/lib/python3.8/site-packages/airflow/utils/email.py", line 154, in send_email_smtp
    send_mime_email(e_from=mail_from, e_to=recipients, mime_msg=msg, conn_id=conn_id, dryrun=dryrun)
  File "/home/airflow/.local/lib/python3.8/site-packages/airflow/utils/email.py", line 272, in send_mime_email
    smtp_conn = _get_smtp_connection(smtp_host, smtp_port, smtp_timeout, smtp_ssl)
  File "/home/airflow/.local/lib/python3.8/site-packages/airflow/utils/email.py", line 316, in _get_smtp_connection
    return smtplib.SMTP(host=host, port=port, timeout=timeout)
  File "/usr/local/lib/python3.8/smtplib.py", line 255, in __init__
    (code, msg) = self.connect(host, port)
  File "/usr/local/lib/python3.8/smtplib.py", line 339, in connect
    self.sock = self._get_socket(host, port, self.timeout)
  File "/usr/local/lib/python3.8/smtplib.py", line 310, in _get_socket
    return socket.create_connection((host, port), timeout,
  File "/usr/local/lib/python3.8/socket.py", line 808, in create_connection
    raise err
  File "/usr/local/lib/python3.8/socket.py", line 796, in create_connection
    sock.connect(sa)
OSError: [Errno 99] Cannot assign requested address
[2024-01-19T04:05:38.683+0000] {standard_task_runner.py:107} ERROR - Failed to execute job 215 for task CheckTableExisting ('branch_task_ids' must contain only valid task_ids. Invalid tasks found: {'InsertDataFunction'}.; 114)
[2024-01-19T04:05:38.728+0000] {local_task_job_runner.py:234} INFO - Task exited with return code 1
[2024-01-19T04:05:38.746+0000] {taskinstance.py:3281} INFO - 0 downstream tasks scheduled from follow-on schedule check
[2024-01-19T04:39:28.614+0000] {taskinstance.py:1957} INFO - Dependencies all met for dep_context=non-requeueable deps ti=<TaskInstance: company_profile_pipeline.CheckTableExisting scheduled__2024-01-14T00:00:00+00:00 [queued]>
[2024-01-19T04:39:28.620+0000] {taskinstance.py:1957} INFO - Dependencies all met for dep_context=requeueable deps ti=<TaskInstance: company_profile_pipeline.CheckTableExisting scheduled__2024-01-14T00:00:00+00:00 [queued]>
[2024-01-19T04:39:28.620+0000] {taskinstance.py:2171} INFO - Starting attempt 1 of 1
[2024-01-19T04:39:28.628+0000] {taskinstance.py:2192} INFO - Executing <Task(BranchPythonOperator): CheckTableExisting> on 2024-01-14 00:00:00+00:00
[2024-01-19T04:39:28.633+0000] {standard_task_runner.py:60} INFO - Started process 240 to run task
[2024-01-19T04:39:28.636+0000] {standard_task_runner.py:87} INFO - Running: ['***', 'tasks', 'run', 'company_profile_pipeline', 'CheckTableExisting', 'scheduled__2024-01-14T00:00:00+00:00', '--job-id', '23', '--raw', '--subdir', 'DAGS_FOLDER/CrawlCompanyInfo.py', '--cfg-path', '/tmp/tmp2yfr_4v6']
[2024-01-19T04:39:28.638+0000] {standard_task_runner.py:88} INFO - Job 23: Subtask CheckTableExisting
[2024-01-19T04:39:28.680+0000] {task_command.py:423} INFO - Running <TaskInstance: company_profile_pipeline.CheckTableExisting scheduled__2024-01-14T00:00:00+00:00 [running]> on host ae6c997f1cf2
[2024-01-19T04:39:28.726+0000] {taskinstance.py:2481} INFO - Exporting env vars: AIRFLOW_CTX_DAG_EMAIL='anh.ho@tititada.com' AIRFLOW_CTX_DAG_OWNER='anh.ho' AIRFLOW_CTX_DAG_ID='company_profile_pipeline' AIRFLOW_CTX_TASK_ID='CheckTableExisting' AIRFLOW_CTX_EXECUTION_DATE='2024-01-14T00:00:00+00:00' AIRFLOW_CTX_TRY_NUMBER='1' AIRFLOW_CTX_DAG_RUN_ID='scheduled__2024-01-14T00:00:00+00:00'
[2024-01-19T04:39:28.727+0000] {logging_mixin.py:188} INFO - Connecting to the PostgreSQL database...
[2024-01-19T04:39:28.729+0000] {logging_mixin.py:188} INFO - PostgreSQL database version:
[2024-01-19T04:39:28.730+0000] {logging_mixin.py:188} INFO - Successfully connect to Postgresql
[2024-01-19T04:39:28.730+0000] {logging_mixin.py:188} INFO - ('PostgreSQL 13.13 (Debian 13.13-1.pgdg120+1) on aarch64-unknown-linux-gnu, compiled by gcc (Debian 12.2.0-14) 12.2.0, 64-bit',)
[2024-01-19T04:39:28.730+0000] {logging_mixin.py:188} INFO - Checking existing table...
[2024-01-19T04:39:28.731+0000] {python.py:201} INFO - Done. Returned value was: InsertDataFunction
[2024-01-19T04:39:28.731+0000] {branch.py:35} INFO - Branch into InsertDataFunction
[2024-01-19T04:39:28.732+0000] {skipmixin.py:178} INFO - Following branch InsertDataFunction
[2024-01-19T04:39:28.736+0000] {taskinstance.py:2699} ERROR - Task failed with exception
Traceback (most recent call last):
  File "/home/airflow/.local/lib/python3.8/site-packages/airflow/models/taskinstance.py", line 433, in _execute_task
    result = execute_callable(context=context, **execute_callable_kwargs)
  File "/home/airflow/.local/lib/python3.8/site-packages/airflow/operators/python.py", line 233, in execute
    return self.do_branch(context, super().execute(context))
  File "/home/airflow/.local/lib/python3.8/site-packages/airflow/operators/branch.py", line 36, in do_branch
    self.skip_all_except(context["ti"], branches_to_execute)
  File "/home/airflow/.local/lib/python3.8/site-packages/airflow/models/skipmixin.py", line 213, in skip_all_except
    raise AirflowException(
airflow.exceptions.AirflowException: 'branch_task_ids' must contain only valid task_ids. Invalid tasks found: {'InsertDataFunction'}.
[2024-01-19T04:39:28.738+0000] {taskinstance.py:1138} INFO - Marking task as FAILED. dag_id=company_profile_pipeline, task_id=CheckTableExisting, execution_date=20240114T000000, start_date=20240119T043928, end_date=20240119T043928
[2024-01-19T04:39:28.746+0000] {warnings.py:109} WARNING - /home/***/.local/lib/python3.8/site-packages/***/utils/email.py:154: RemovedInAirflow3Warning: Fetching SMTP credentials from configuration variables will be deprecated in a future release. Please set credentials using a connection instead.
  send_mime_email(e_from=mail_from, e_to=recipients, mime_msg=msg, conn_id=conn_id, dryrun=dryrun)

[2024-01-19T04:39:28.747+0000] {configuration.py:1046} WARNING - section/key [smtp/smtp_user] not found in config
[2024-01-19T04:39:28.747+0000] {email.py:270} INFO - Email alerting: attempt 1
[2024-01-19T04:39:28.751+0000] {configuration.py:1046} WARNING - section/key [smtp/smtp_user] not found in config
[2024-01-19T04:39:28.752+0000] {email.py:270} INFO - Email alerting: attempt 1
[2024-01-19T04:39:28.753+0000] {taskinstance.py:826} ERROR - Failed to send email to: anh.ho@tititada.com
Traceback (most recent call last):
  File "/home/airflow/.local/lib/python3.8/site-packages/airflow/models/taskinstance.py", line 2335, in _run_raw_task
    self._execute_task_with_callbacks(context, test_mode, session=session)
  File "/home/airflow/.local/lib/python3.8/site-packages/airflow/models/taskinstance.py", line 2500, in _execute_task_with_callbacks
    result = self._execute_task(context, task_orig)
  File "/home/airflow/.local/lib/python3.8/site-packages/airflow/models/taskinstance.py", line 2517, in _execute_task
    return _execute_task(self, context, task_orig)
  File "/home/airflow/.local/lib/python3.8/site-packages/airflow/models/taskinstance.py", line 433, in _execute_task
    result = execute_callable(context=context, **execute_callable_kwargs)
  File "/home/airflow/.local/lib/python3.8/site-packages/airflow/operators/python.py", line 233, in execute
    return self.do_branch(context, super().execute(context))
  File "/home/airflow/.local/lib/python3.8/site-packages/airflow/operators/branch.py", line 36, in do_branch
    self.skip_all_except(context["ti"], branches_to_execute)
  File "/home/airflow/.local/lib/python3.8/site-packages/airflow/models/skipmixin.py", line 213, in skip_all_except
    raise AirflowException(
airflow.exceptions.AirflowException: 'branch_task_ids' must contain only valid task_ids. Invalid tasks found: {'InsertDataFunction'}.

During handling of the above exception, another exception occurred:

Traceback (most recent call last):
  File "/home/airflow/.local/lib/python3.8/site-packages/airflow/models/taskinstance.py", line 1000, in _email_alert
    send_email(task.email, subject, html_content)
  File "/home/airflow/.local/lib/python3.8/site-packages/airflow/utils/email.py", line 80, in send_email
    return backend(
  File "/home/airflow/.local/lib/python3.8/site-packages/airflow/utils/email.py", line 154, in send_email_smtp
    send_mime_email(e_from=mail_from, e_to=recipients, mime_msg=msg, conn_id=conn_id, dryrun=dryrun)
  File "/home/airflow/.local/lib/python3.8/site-packages/airflow/utils/email.py", line 272, in send_mime_email
    smtp_conn = _get_smtp_connection(smtp_host, smtp_port, smtp_timeout, smtp_ssl)
  File "/home/airflow/.local/lib/python3.8/site-packages/airflow/utils/email.py", line 316, in _get_smtp_connection
    return smtplib.SMTP(host=host, port=port, timeout=timeout)
  File "/usr/local/lib/python3.8/smtplib.py", line 255, in __init__
    (code, msg) = self.connect(host, port)
  File "/usr/local/lib/python3.8/smtplib.py", line 339, in connect
    self.sock = self._get_socket(host, port, self.timeout)
  File "/usr/local/lib/python3.8/smtplib.py", line 310, in _get_socket
    return socket.create_connection((host, port), timeout,
  File "/usr/local/lib/python3.8/socket.py", line 808, in create_connection
    raise err
  File "/usr/local/lib/python3.8/socket.py", line 796, in create_connection
    sock.connect(sa)
OSError: [Errno 99] Cannot assign requested address

During handling of the above exception, another exception occurred:

Traceback (most recent call last):
  File "/home/airflow/.local/lib/python3.8/site-packages/airflow/models/taskinstance.py", line 824, in _handle_failure
    task_instance.email_alert(error, failure_context["task"])
  File "/home/airflow/.local/lib/python3.8/site-packages/airflow/models/taskinstance.py", line 2947, in email_alert
    _email_alert(task_instance=self, exception=exception, task=task)
  File "/home/airflow/.local/lib/python3.8/site-packages/airflow/models/taskinstance.py", line 1002, in _email_alert
    send_email(task.email, subject, html_content_err)
  File "/home/airflow/.local/lib/python3.8/site-packages/airflow/utils/email.py", line 80, in send_email
    return backend(
  File "/home/airflow/.local/lib/python3.8/site-packages/airflow/utils/email.py", line 154, in send_email_smtp
    send_mime_email(e_from=mail_from, e_to=recipients, mime_msg=msg, conn_id=conn_id, dryrun=dryrun)
  File "/home/airflow/.local/lib/python3.8/site-packages/airflow/utils/email.py", line 272, in send_mime_email
    smtp_conn = _get_smtp_connection(smtp_host, smtp_port, smtp_timeout, smtp_ssl)
  File "/home/airflow/.local/lib/python3.8/site-packages/airflow/utils/email.py", line 316, in _get_smtp_connection
    return smtplib.SMTP(host=host, port=port, timeout=timeout)
  File "/usr/local/lib/python3.8/smtplib.py", line 255, in __init__
    (code, msg) = self.connect(host, port)
  File "/usr/local/lib/python3.8/smtplib.py", line 339, in connect
    self.sock = self._get_socket(host, port, self.timeout)
  File "/usr/local/lib/python3.8/smtplib.py", line 310, in _get_socket
    return socket.create_connection((host, port), timeout,
  File "/usr/local/lib/python3.8/socket.py", line 808, in create_connection
    raise err
  File "/usr/local/lib/python3.8/socket.py", line 796, in create_connection
    sock.connect(sa)
OSError: [Errno 99] Cannot assign requested address
[2024-01-19T04:39:28.760+0000] {standard_task_runner.py:107} ERROR - Failed to execute job 23 for task CheckTableExisting ('branch_task_ids' must contain only valid task_ids. Invalid tasks found: {'InsertDataFunction'}.; 240)
[2024-01-19T04:39:28.771+0000] {local_task_job_runner.py:234} INFO - Task exited with return code 1
[2024-01-19T04:39:28.788+0000] {taskinstance.py:3281} INFO - 0 downstream tasks scheduled from follow-on schedule check
[2024-01-19T08:13:33.250+0000] {taskinstance.py:1957} INFO - Dependencies all met for dep_context=non-requeueable deps ti=<TaskInstance: company_profile_pipeline.CheckTableExisting scheduled__2024-01-14T00:00:00+00:00 [queued]>
[2024-01-19T08:13:33.261+0000] {taskinstance.py:1957} INFO - Dependencies all met for dep_context=requeueable deps ti=<TaskInstance: company_profile_pipeline.CheckTableExisting scheduled__2024-01-14T00:00:00+00:00 [queued]>
[2024-01-19T08:13:33.261+0000] {taskinstance.py:2171} INFO - Starting attempt 1 of 1
[2024-01-19T08:13:33.271+0000] {taskinstance.py:2192} INFO - Executing <Task(BranchPythonOperator): CheckTableExisting> on 2024-01-14 00:00:00+00:00
[2024-01-19T08:13:33.278+0000] {standard_task_runner.py:60} INFO - Started process 659 to run task
[2024-01-19T08:13:33.283+0000] {standard_task_runner.py:87} INFO - Running: ['***', 'tasks', 'run', 'company_profile_pipeline', 'CheckTableExisting', 'scheduled__2024-01-14T00:00:00+00:00', '--job-id', '50', '--raw', '--subdir', 'DAGS_FOLDER/CrawlCompanyInfo.py', '--cfg-path', '/tmp/tmpok_oiq5q']
[2024-01-19T08:13:33.290+0000] {standard_task_runner.py:88} INFO - Job 50: Subtask CheckTableExisting
[2024-01-19T08:13:33.360+0000] {task_command.py:423} INFO - Running <TaskInstance: company_profile_pipeline.CheckTableExisting scheduled__2024-01-14T00:00:00+00:00 [running]> on host 945ee41ba0c4
[2024-01-19T08:13:33.411+0000] {taskinstance.py:2481} INFO - Exporting env vars: AIRFLOW_CTX_DAG_EMAIL='anh.ho@tititada.com' AIRFLOW_CTX_DAG_OWNER='anh.ho' AIRFLOW_CTX_DAG_ID='company_profile_pipeline' AIRFLOW_CTX_TASK_ID='CheckTableExisting' AIRFLOW_CTX_EXECUTION_DATE='2024-01-14T00:00:00+00:00' AIRFLOW_CTX_TRY_NUMBER='1' AIRFLOW_CTX_DAG_RUN_ID='scheduled__2024-01-14T00:00:00+00:00'
[2024-01-19T08:13:33.413+0000] {logging_mixin.py:188} INFO - Connecting to the PostgreSQL database...
[2024-01-19T08:13:33.415+0000] {logging_mixin.py:188} INFO - PostgreSQL database version:
[2024-01-19T08:13:33.417+0000] {logging_mixin.py:188} INFO - Successfully connect to Postgresql
[2024-01-19T08:13:33.418+0000] {logging_mixin.py:188} INFO - ('PostgreSQL 13.13 (Debian 13.13-1.pgdg120+1) on aarch64-unknown-linux-gnu, compiled by gcc (Debian 12.2.0-14) 12.2.0, 64-bit',)
[2024-01-19T08:13:33.419+0000] {logging_mixin.py:188} INFO - Checking existing table...
[2024-01-19T08:13:33.420+0000] {python.py:201} INFO - Done. Returned value was: ExistingCompanyProfile
[2024-01-19T08:13:33.420+0000] {branch.py:35} INFO - Branch into ExistingCompanyProfile
[2024-01-19T08:13:33.421+0000] {skipmixin.py:178} INFO - Following branch ExistingCompanyProfile
[2024-01-19T08:13:33.434+0000] {skipmixin.py:244} INFO - Skipping tasks [('CreateCompanyProfileTable', -1)]
[2024-01-19T08:13:33.467+0000] {taskinstance.py:1138} INFO - Marking task as SUCCESS. dag_id=company_profile_pipeline, task_id=CheckTableExisting, execution_date=20240114T000000, start_date=20240119T081333, end_date=20240119T081333
[2024-01-19T08:13:33.503+0000] {local_task_job_runner.py:234} INFO - Task exited with return code 0
[2024-01-19T08:13:33.525+0000] {taskinstance.py:3281} INFO - 1 downstream tasks scheduled from follow-on schedule check
