[2024-01-18T09:57:06.839+0000] {taskinstance.py:1957} INFO - Dependencies all met for dep_context=non-requeueable deps ti=<TaskInstance: company_profile_pipeline.CheckTableExisting scheduled__2024-01-01T00:00:00+00:00 [queued]>
[2024-01-18T09:57:06.844+0000] {taskinstance.py:1957} INFO - Dependencies all met for dep_context=requeueable deps ti=<TaskInstance: company_profile_pipeline.CheckTableExisting scheduled__2024-01-01T00:00:00+00:00 [queued]>
[2024-01-18T09:57:06.845+0000] {taskinstance.py:2171} INFO - Starting attempt 1 of 1
[2024-01-18T09:57:06.855+0000] {taskinstance.py:2192} INFO - Executing <Task(BranchPythonOperator): CheckTableExisting> on 2024-01-01 00:00:00+00:00
[2024-01-18T09:57:06.861+0000] {standard_task_runner.py:60} INFO - Started process 82 to run task
[2024-01-18T09:57:06.863+0000] {standard_task_runner.py:87} INFO - Running: ['***', 'tasks', 'run', 'company_profile_pipeline', 'CheckTableExisting', 'scheduled__2024-01-01T00:00:00+00:00', '--job-id', '18', '--raw', '--subdir', 'DAGS_FOLDER/CrawlCompanyInfo.py', '--cfg-path', '/tmp/tmp4y7hh0rq']
[2024-01-18T09:57:06.864+0000] {standard_task_runner.py:88} INFO - Job 18: Subtask CheckTableExisting
[2024-01-18T09:57:06.909+0000] {task_command.py:423} INFO - Running <TaskInstance: company_profile_pipeline.CheckTableExisting scheduled__2024-01-01T00:00:00+00:00 [running]> on host a56b2d2a6d76
[2024-01-18T09:57:06.972+0000] {taskinstance.py:2481} INFO - Exporting env vars: AIRFLOW_CTX_DAG_EMAIL='anh.ho@tititada.com' AIRFLOW_CTX_DAG_OWNER='anh.ho' AIRFLOW_CTX_DAG_ID='company_profile_pipeline' AIRFLOW_CTX_TASK_ID='CheckTableExisting' AIRFLOW_CTX_EXECUTION_DATE='2024-01-01T00:00:00+00:00' AIRFLOW_CTX_TRY_NUMBER='1' AIRFLOW_CTX_DAG_RUN_ID='scheduled__2024-01-01T00:00:00+00:00'
[2024-01-18T09:57:06.974+0000] {taskinstance.py:2699} ERROR - Task failed with exception
Traceback (most recent call last):
  File "/home/airflow/.local/lib/python3.8/site-packages/airflow/models/taskinstance.py", line 433, in _execute_task
    result = execute_callable(context=context, **execute_callable_kwargs)
  File "/home/airflow/.local/lib/python3.8/site-packages/airflow/operators/python.py", line 233, in execute
    return self.do_branch(context, super().execute(context))
  File "/home/airflow/.local/lib/python3.8/site-packages/airflow/operators/python.py", line 199, in execute
    return_value = self.execute_callable()
  File "/home/airflow/.local/lib/python3.8/site-packages/airflow/operators/python.py", line 216, in execute_callable
    return self.python_callable(*self.op_args, **self.op_kwargs)
  File "/opt/airflow/dags/CrawlCompanyInfo.py", line 55, in CheckTableExisting
    cursor = ConnectPostgres().cursor()
  File "/opt/airflow/dags/CrawlCompanyInfo.py", line 27, in ConnectPostgres
    params = ReadConfigFile(relative_path,section)
  File "/opt/airflow/dags/GetAuthInfoFuncton.py", line 25, in ReadConfigFile
    raise Exception('Section {0} not found in the {1} file'.format(section, text_file_path))
Exception: Section Postgresql not found in the /Users/anhho/Desktop/DataEngineer/CrawlStockData/CrawlFunction/Authorization.ini file
[2024-01-18T09:57:06.983+0000] {taskinstance.py:1138} INFO - Marking task as FAILED. dag_id=company_profile_pipeline, task_id=CheckTableExisting, execution_date=20240101T000000, start_date=20240118T095706, end_date=20240118T095706
[2024-01-18T09:57:06.996+0000] {warnings.py:109} WARNING - /home/***/.local/lib/python3.8/site-packages/***/utils/email.py:154: RemovedInAirflow3Warning: Fetching SMTP credentials from configuration variables will be deprecated in a future release. Please set credentials using a connection instead.
  send_mime_email(e_from=mail_from, e_to=recipients, mime_msg=msg, conn_id=conn_id, dryrun=dryrun)

[2024-01-18T09:57:06.997+0000] {configuration.py:1046} WARNING - section/key [smtp/smtp_user] not found in config
[2024-01-18T09:57:06.998+0000] {email.py:270} INFO - Email alerting: attempt 1
[2024-01-18T09:57:07.005+0000] {configuration.py:1046} WARNING - section/key [smtp/smtp_user] not found in config
[2024-01-18T09:57:07.007+0000] {email.py:270} INFO - Email alerting: attempt 1
[2024-01-18T09:57:07.008+0000] {taskinstance.py:826} ERROR - Failed to send email to: anh.ho@tititada.com
Traceback (most recent call last):
  File "/home/airflow/.local/lib/python3.8/site-packages/airflow/models/taskinstance.py", line 2335, in _run_raw_task
    self._execute_task_with_callbacks(context, test_mode, session=session)
  File "/home/airflow/.local/lib/python3.8/site-packages/airflow/models/taskinstance.py", line 2500, in _execute_task_with_callbacks
    result = self._execute_task(context, task_orig)
  File "/home/airflow/.local/lib/python3.8/site-packages/airflow/models/taskinstance.py", line 2517, in _execute_task
    return _execute_task(self, context, task_orig)
  File "/home/airflow/.local/lib/python3.8/site-packages/airflow/models/taskinstance.py", line 433, in _execute_task
    result = execute_callable(context=context, **execute_callable_kwargs)
  File "/home/airflow/.local/lib/python3.8/site-packages/airflow/operators/python.py", line 233, in execute
    return self.do_branch(context, super().execute(context))
  File "/home/airflow/.local/lib/python3.8/site-packages/airflow/operators/python.py", line 199, in execute
    return_value = self.execute_callable()
  File "/home/airflow/.local/lib/python3.8/site-packages/airflow/operators/python.py", line 216, in execute_callable
    return self.python_callable(*self.op_args, **self.op_kwargs)
  File "/opt/airflow/dags/CrawlCompanyInfo.py", line 55, in CheckTableExisting
    cursor = ConnectPostgres().cursor()
  File "/opt/airflow/dags/CrawlCompanyInfo.py", line 27, in ConnectPostgres
    params = ReadConfigFile(relative_path,section)
  File "/opt/airflow/dags/GetAuthInfoFuncton.py", line 25, in ReadConfigFile
    raise Exception('Section {0} not found in the {1} file'.format(section, text_file_path))
Exception: Section Postgresql not found in the /Users/anhho/Desktop/DataEngineer/CrawlStockData/CrawlFunction/Authorization.ini file

During handling of the above exception, another exception occurred:

Traceback (most recent call last):
  File "/home/airflow/.local/lib/python3.8/site-packages/airflow/models/taskinstance.py", line 1000, in _email_alert
    send_email(task.email, subject, html_content)
  File "/home/airflow/.local/lib/python3.8/site-packages/airflow/utils/email.py", line 80, in send_email
    return backend(
  File "/home/airflow/.local/lib/python3.8/site-packages/airflow/utils/email.py", line 154, in send_email_smtp
    send_mime_email(e_from=mail_from, e_to=recipients, mime_msg=msg, conn_id=conn_id, dryrun=dryrun)
  File "/home/airflow/.local/lib/python3.8/site-packages/airflow/utils/email.py", line 272, in send_mime_email
    smtp_conn = _get_smtp_connection(smtp_host, smtp_port, smtp_timeout, smtp_ssl)
  File "/home/airflow/.local/lib/python3.8/site-packages/airflow/utils/email.py", line 316, in _get_smtp_connection
    return smtplib.SMTP(host=host, port=port, timeout=timeout)
  File "/usr/local/lib/python3.8/smtplib.py", line 255, in __init__
    (code, msg) = self.connect(host, port)
  File "/usr/local/lib/python3.8/smtplib.py", line 339, in connect
    self.sock = self._get_socket(host, port, self.timeout)
  File "/usr/local/lib/python3.8/smtplib.py", line 310, in _get_socket
    return socket.create_connection((host, port), timeout,
  File "/usr/local/lib/python3.8/socket.py", line 808, in create_connection
    raise err
  File "/usr/local/lib/python3.8/socket.py", line 796, in create_connection
    sock.connect(sa)
OSError: [Errno 99] Cannot assign requested address

During handling of the above exception, another exception occurred:

Traceback (most recent call last):
  File "/home/airflow/.local/lib/python3.8/site-packages/airflow/models/taskinstance.py", line 824, in _handle_failure
    task_instance.email_alert(error, failure_context["task"])
  File "/home/airflow/.local/lib/python3.8/site-packages/airflow/models/taskinstance.py", line 2947, in email_alert
    _email_alert(task_instance=self, exception=exception, task=task)
  File "/home/airflow/.local/lib/python3.8/site-packages/airflow/models/taskinstance.py", line 1002, in _email_alert
    send_email(task.email, subject, html_content_err)
  File "/home/airflow/.local/lib/python3.8/site-packages/airflow/utils/email.py", line 80, in send_email
    return backend(
  File "/home/airflow/.local/lib/python3.8/site-packages/airflow/utils/email.py", line 154, in send_email_smtp
    send_mime_email(e_from=mail_from, e_to=recipients, mime_msg=msg, conn_id=conn_id, dryrun=dryrun)
  File "/home/airflow/.local/lib/python3.8/site-packages/airflow/utils/email.py", line 272, in send_mime_email
    smtp_conn = _get_smtp_connection(smtp_host, smtp_port, smtp_timeout, smtp_ssl)
  File "/home/airflow/.local/lib/python3.8/site-packages/airflow/utils/email.py", line 316, in _get_smtp_connection
    return smtplib.SMTP(host=host, port=port, timeout=timeout)
  File "/usr/local/lib/python3.8/smtplib.py", line 255, in __init__
    (code, msg) = self.connect(host, port)
  File "/usr/local/lib/python3.8/smtplib.py", line 339, in connect
    self.sock = self._get_socket(host, port, self.timeout)
  File "/usr/local/lib/python3.8/smtplib.py", line 310, in _get_socket
    return socket.create_connection((host, port), timeout,
  File "/usr/local/lib/python3.8/socket.py", line 808, in create_connection
    raise err
  File "/usr/local/lib/python3.8/socket.py", line 796, in create_connection
    sock.connect(sa)
OSError: [Errno 99] Cannot assign requested address
[2024-01-18T09:57:07.023+0000] {standard_task_runner.py:107} ERROR - Failed to execute job 18 for task CheckTableExisting (Section Postgresql not found in the /Users/anhho/Desktop/DataEngineer/CrawlStockData/CrawlFunction/Authorization.ini file; 82)
[2024-01-18T09:57:07.037+0000] {local_task_job_runner.py:234} INFO - Task exited with return code 1
[2024-01-18T09:57:07.064+0000] {taskinstance.py:3281} INFO - 0 downstream tasks scheduled from follow-on schedule check
[2024-01-18T10:00:56.715+0000] {taskinstance.py:1957} INFO - Dependencies all met for dep_context=non-requeueable deps ti=<TaskInstance: company_profile_pipeline.CheckTableExisting scheduled__2024-01-01T00:00:00+00:00 [queued]>
[2024-01-18T10:00:56.719+0000] {taskinstance.py:1957} INFO - Dependencies all met for dep_context=requeueable deps ti=<TaskInstance: company_profile_pipeline.CheckTableExisting scheduled__2024-01-01T00:00:00+00:00 [queued]>
[2024-01-18T10:00:56.719+0000] {taskinstance.py:2171} INFO - Starting attempt 1 of 1
[2024-01-18T10:00:56.738+0000] {taskinstance.py:2192} INFO - Executing <Task(BranchPythonOperator): CheckTableExisting> on 2024-01-01 00:00:00+00:00
[2024-01-18T10:00:56.741+0000] {standard_task_runner.py:60} INFO - Started process 174 to run task
[2024-01-18T10:00:56.744+0000] {standard_task_runner.py:87} INFO - Running: ['***', 'tasks', 'run', 'company_profile_pipeline', 'CheckTableExisting', 'scheduled__2024-01-01T00:00:00+00:00', '--job-id', '36', '--raw', '--subdir', 'DAGS_FOLDER/CrawlCompanyInfo.py', '--cfg-path', '/tmp/tmptvy52fkv']
[2024-01-18T10:00:56.745+0000] {standard_task_runner.py:88} INFO - Job 36: Subtask CheckTableExisting
[2024-01-18T10:00:56.772+0000] {task_command.py:423} INFO - Running <TaskInstance: company_profile_pipeline.CheckTableExisting scheduled__2024-01-01T00:00:00+00:00 [running]> on host a56b2d2a6d76
[2024-01-18T10:00:56.811+0000] {taskinstance.py:2481} INFO - Exporting env vars: AIRFLOW_CTX_DAG_EMAIL='anh.ho@tititada.com' AIRFLOW_CTX_DAG_OWNER='anh.ho' AIRFLOW_CTX_DAG_ID='company_profile_pipeline' AIRFLOW_CTX_TASK_ID='CheckTableExisting' AIRFLOW_CTX_EXECUTION_DATE='2024-01-01T00:00:00+00:00' AIRFLOW_CTX_TRY_NUMBER='1' AIRFLOW_CTX_DAG_RUN_ID='scheduled__2024-01-01T00:00:00+00:00'
[2024-01-18T10:00:56.812+0000] {taskinstance.py:2699} ERROR - Task failed with exception
Traceback (most recent call last):
  File "/home/airflow/.local/lib/python3.8/site-packages/airflow/models/taskinstance.py", line 433, in _execute_task
    result = execute_callable(context=context, **execute_callable_kwargs)
  File "/home/airflow/.local/lib/python3.8/site-packages/airflow/operators/python.py", line 233, in execute
    return self.do_branch(context, super().execute(context))
  File "/home/airflow/.local/lib/python3.8/site-packages/airflow/operators/python.py", line 199, in execute
    return_value = self.execute_callable()
  File "/home/airflow/.local/lib/python3.8/site-packages/airflow/operators/python.py", line 216, in execute_callable
    return self.python_callable(*self.op_args, **self.op_kwargs)
  File "/opt/airflow/dags/CrawlCompanyInfo.py", line 55, in CheckTableExisting
    cursor = ConnectPostgres().cursor()
  File "/opt/airflow/dags/CrawlCompanyInfo.py", line 27, in ConnectPostgres
    params = ReadConfigFile(relative_path,section)
  File "/opt/airflow/dags/GetAuthInfoFuncton.py", line 25, in ReadConfigFile
    raise Exception('Section {section} not found in the {text_file_path} file'.format(section=section, text_file_path=text_file_path))
Exception: Section Postgresql not found in the /Users/anhho/Desktop/DataEngineer/CrawlStockData/ApacheAirflow/Authorization.ini file
[2024-01-18T10:00:56.819+0000] {taskinstance.py:1138} INFO - Marking task as FAILED. dag_id=company_profile_pipeline, task_id=CheckTableExisting, execution_date=20240101T000000, start_date=20240118T100056, end_date=20240118T100056
[2024-01-18T10:00:56.827+0000] {warnings.py:109} WARNING - /home/***/.local/lib/python3.8/site-packages/***/utils/email.py:154: RemovedInAirflow3Warning: Fetching SMTP credentials from configuration variables will be deprecated in a future release. Please set credentials using a connection instead.
  send_mime_email(e_from=mail_from, e_to=recipients, mime_msg=msg, conn_id=conn_id, dryrun=dryrun)

[2024-01-18T10:00:56.828+0000] {configuration.py:1046} WARNING - section/key [smtp/smtp_user] not found in config
[2024-01-18T10:00:56.828+0000] {email.py:270} INFO - Email alerting: attempt 1
[2024-01-18T10:00:56.833+0000] {configuration.py:1046} WARNING - section/key [smtp/smtp_user] not found in config
[2024-01-18T10:00:56.834+0000] {email.py:270} INFO - Email alerting: attempt 1
[2024-01-18T10:00:56.835+0000] {taskinstance.py:826} ERROR - Failed to send email to: anh.ho@tititada.com
Traceback (most recent call last):
  File "/home/airflow/.local/lib/python3.8/site-packages/airflow/models/taskinstance.py", line 2335, in _run_raw_task
    self._execute_task_with_callbacks(context, test_mode, session=session)
  File "/home/airflow/.local/lib/python3.8/site-packages/airflow/models/taskinstance.py", line 2500, in _execute_task_with_callbacks
    result = self._execute_task(context, task_orig)
  File "/home/airflow/.local/lib/python3.8/site-packages/airflow/models/taskinstance.py", line 2517, in _execute_task
    return _execute_task(self, context, task_orig)
  File "/home/airflow/.local/lib/python3.8/site-packages/airflow/models/taskinstance.py", line 433, in _execute_task
    result = execute_callable(context=context, **execute_callable_kwargs)
  File "/home/airflow/.local/lib/python3.8/site-packages/airflow/operators/python.py", line 233, in execute
    return self.do_branch(context, super().execute(context))
  File "/home/airflow/.local/lib/python3.8/site-packages/airflow/operators/python.py", line 199, in execute
    return_value = self.execute_callable()
  File "/home/airflow/.local/lib/python3.8/site-packages/airflow/operators/python.py", line 216, in execute_callable
    return self.python_callable(*self.op_args, **self.op_kwargs)
  File "/opt/airflow/dags/CrawlCompanyInfo.py", line 55, in CheckTableExisting
    cursor = ConnectPostgres().cursor()
  File "/opt/airflow/dags/CrawlCompanyInfo.py", line 27, in ConnectPostgres
    params = ReadConfigFile(relative_path,section)
  File "/opt/airflow/dags/GetAuthInfoFuncton.py", line 25, in ReadConfigFile
    raise Exception('Section {section} not found in the {text_file_path} file'.format(section=section, text_file_path=text_file_path))
Exception: Section Postgresql not found in the /Users/anhho/Desktop/DataEngineer/CrawlStockData/ApacheAirflow/Authorization.ini file

During handling of the above exception, another exception occurred:

Traceback (most recent call last):
  File "/home/airflow/.local/lib/python3.8/site-packages/airflow/models/taskinstance.py", line 1000, in _email_alert
    send_email(task.email, subject, html_content)
  File "/home/airflow/.local/lib/python3.8/site-packages/airflow/utils/email.py", line 80, in send_email
    return backend(
  File "/home/airflow/.local/lib/python3.8/site-packages/airflow/utils/email.py", line 154, in send_email_smtp
    send_mime_email(e_from=mail_from, e_to=recipients, mime_msg=msg, conn_id=conn_id, dryrun=dryrun)
  File "/home/airflow/.local/lib/python3.8/site-packages/airflow/utils/email.py", line 272, in send_mime_email
    smtp_conn = _get_smtp_connection(smtp_host, smtp_port, smtp_timeout, smtp_ssl)
  File "/home/airflow/.local/lib/python3.8/site-packages/airflow/utils/email.py", line 316, in _get_smtp_connection
    return smtplib.SMTP(host=host, port=port, timeout=timeout)
  File "/usr/local/lib/python3.8/smtplib.py", line 255, in __init__
    (code, msg) = self.connect(host, port)
  File "/usr/local/lib/python3.8/smtplib.py", line 339, in connect
    self.sock = self._get_socket(host, port, self.timeout)
  File "/usr/local/lib/python3.8/smtplib.py", line 310, in _get_socket
    return socket.create_connection((host, port), timeout,
  File "/usr/local/lib/python3.8/socket.py", line 808, in create_connection
    raise err
  File "/usr/local/lib/python3.8/socket.py", line 796, in create_connection
    sock.connect(sa)
OSError: [Errno 99] Cannot assign requested address

During handling of the above exception, another exception occurred:

Traceback (most recent call last):
  File "/home/airflow/.local/lib/python3.8/site-packages/airflow/models/taskinstance.py", line 824, in _handle_failure
    task_instance.email_alert(error, failure_context["task"])
  File "/home/airflow/.local/lib/python3.8/site-packages/airflow/models/taskinstance.py", line 2947, in email_alert
    _email_alert(task_instance=self, exception=exception, task=task)
  File "/home/airflow/.local/lib/python3.8/site-packages/airflow/models/taskinstance.py", line 1002, in _email_alert
    send_email(task.email, subject, html_content_err)
  File "/home/airflow/.local/lib/python3.8/site-packages/airflow/utils/email.py", line 80, in send_email
    return backend(
  File "/home/airflow/.local/lib/python3.8/site-packages/airflow/utils/email.py", line 154, in send_email_smtp
    send_mime_email(e_from=mail_from, e_to=recipients, mime_msg=msg, conn_id=conn_id, dryrun=dryrun)
  File "/home/airflow/.local/lib/python3.8/site-packages/airflow/utils/email.py", line 272, in send_mime_email
    smtp_conn = _get_smtp_connection(smtp_host, smtp_port, smtp_timeout, smtp_ssl)
  File "/home/airflow/.local/lib/python3.8/site-packages/airflow/utils/email.py", line 316, in _get_smtp_connection
    return smtplib.SMTP(host=host, port=port, timeout=timeout)
  File "/usr/local/lib/python3.8/smtplib.py", line 255, in __init__
    (code, msg) = self.connect(host, port)
  File "/usr/local/lib/python3.8/smtplib.py", line 339, in connect
    self.sock = self._get_socket(host, port, self.timeout)
  File "/usr/local/lib/python3.8/smtplib.py", line 310, in _get_socket
    return socket.create_connection((host, port), timeout,
  File "/usr/local/lib/python3.8/socket.py", line 808, in create_connection
    raise err
  File "/usr/local/lib/python3.8/socket.py", line 796, in create_connection
    sock.connect(sa)
OSError: [Errno 99] Cannot assign requested address
[2024-01-18T10:00:56.844+0000] {standard_task_runner.py:107} ERROR - Failed to execute job 36 for task CheckTableExisting (Section Postgresql not found in the /Users/anhho/Desktop/DataEngineer/CrawlStockData/ApacheAirflow/Authorization.ini file; 174)
[2024-01-18T10:00:56.876+0000] {local_task_job_runner.py:234} INFO - Task exited with return code 1
[2024-01-18T10:00:56.898+0000] {taskinstance.py:3281} INFO - 0 downstream tasks scheduled from follow-on schedule check
[2024-01-19T02:23:43.889+0000] {taskinstance.py:1957} INFO - Dependencies all met for dep_context=non-requeueable deps ti=<TaskInstance: company_profile_pipeline.CheckTableExisting scheduled__2024-01-01T00:00:00+00:00 [queued]>
[2024-01-19T02:23:43.894+0000] {taskinstance.py:1957} INFO - Dependencies all met for dep_context=requeueable deps ti=<TaskInstance: company_profile_pipeline.CheckTableExisting scheduled__2024-01-01T00:00:00+00:00 [queued]>
[2024-01-19T02:23:43.894+0000] {taskinstance.py:2171} INFO - Starting attempt 1 of 1
[2024-01-19T02:23:43.901+0000] {taskinstance.py:2192} INFO - Executing <Task(BranchPythonOperator): CheckTableExisting> on 2024-01-01 00:00:00+00:00
[2024-01-19T02:23:43.905+0000] {standard_task_runner.py:60} INFO - Started process 110 to run task
[2024-01-19T02:23:43.909+0000] {standard_task_runner.py:87} INFO - Running: ['***', 'tasks', 'run', 'company_profile_pipeline', 'CheckTableExisting', 'scheduled__2024-01-01T00:00:00+00:00', '--job-id', '70', '--raw', '--subdir', 'DAGS_FOLDER/CrawlCompanyInfo.py', '--cfg-path', '/tmp/tmp6vapw5l0']
[2024-01-19T02:23:43.911+0000] {standard_task_runner.py:88} INFO - Job 70: Subtask CheckTableExisting
[2024-01-19T02:23:43.980+0000] {task_command.py:423} INFO - Running <TaskInstance: company_profile_pipeline.CheckTableExisting scheduled__2024-01-01T00:00:00+00:00 [running]> on host a56b2d2a6d76
[2024-01-19T02:23:44.035+0000] {taskinstance.py:2481} INFO - Exporting env vars: AIRFLOW_CTX_DAG_EMAIL='anh.ho@tititada.com' AIRFLOW_CTX_DAG_OWNER='anh.ho' AIRFLOW_CTX_DAG_ID='company_profile_pipeline' AIRFLOW_CTX_TASK_ID='CheckTableExisting' AIRFLOW_CTX_EXECUTION_DATE='2024-01-01T00:00:00+00:00' AIRFLOW_CTX_TRY_NUMBER='1' AIRFLOW_CTX_DAG_RUN_ID='scheduled__2024-01-01T00:00:00+00:00'
[2024-01-19T02:23:44.038+0000] {logging_mixin.py:188} INFO - Connecting to the PostgreSQL database...
[2024-01-19T02:25:52.692+0000] {taskinstance.py:2699} ERROR - Task failed with exception
Traceback (most recent call last):
  File "/home/airflow/.local/lib/python3.8/site-packages/airflow/models/taskinstance.py", line 433, in _execute_task
    result = execute_callable(context=context, **execute_callable_kwargs)
  File "/home/airflow/.local/lib/python3.8/site-packages/airflow/operators/python.py", line 233, in execute
    return self.do_branch(context, super().execute(context))
  File "/home/airflow/.local/lib/python3.8/site-packages/airflow/operators/python.py", line 199, in execute
    return_value = self.execute_callable()
  File "/home/airflow/.local/lib/python3.8/site-packages/airflow/operators/python.py", line 216, in execute_callable
    return self.python_callable(*self.op_args, **self.op_kwargs)
  File "/opt/airflow/dags/CrawlCompanyInfo.py", line 50, in CheckTableExisting
    cursor = ConnectPostgres().cursor()
  File "/opt/airflow/dags/CrawlCompanyInfo.py", line 41, in ConnectPostgres
    raise e
  File "/opt/airflow/dags/CrawlCompanyInfo.py", line 26, in ConnectPostgres
    conn = psycopg2.connect(**params)
  File "/home/airflow/.local/lib/python3.8/site-packages/psycopg2/__init__.py", line 122, in connect
    conn = _connect(dsn, connection_factory=connection_factory, **kwasync)
psycopg2.OperationalError: connection to server at "172.17.0.2", port 5432 failed: Connection timed out
	Is the server running on that host and accepting TCP/IP connections?

[2024-01-19T02:25:52.732+0000] {taskinstance.py:1138} INFO - Marking task as FAILED. dag_id=company_profile_pipeline, task_id=CheckTableExisting, execution_date=20240101T000000, start_date=20240119T022343, end_date=20240119T022552
[2024-01-19T02:25:52.757+0000] {warnings.py:109} WARNING - /home/***/.local/lib/python3.8/site-packages/***/utils/email.py:154: RemovedInAirflow3Warning: Fetching SMTP credentials from configuration variables will be deprecated in a future release. Please set credentials using a connection instead.
  send_mime_email(e_from=mail_from, e_to=recipients, mime_msg=msg, conn_id=conn_id, dryrun=dryrun)

[2024-01-19T02:25:52.759+0000] {configuration.py:1046} WARNING - section/key [smtp/smtp_user] not found in config
[2024-01-19T02:25:52.760+0000] {email.py:270} INFO - Email alerting: attempt 1
[2024-01-19T02:25:52.769+0000] {configuration.py:1046} WARNING - section/key [smtp/smtp_user] not found in config
[2024-01-19T02:25:52.770+0000] {email.py:270} INFO - Email alerting: attempt 1
[2024-01-19T02:25:52.771+0000] {taskinstance.py:826} ERROR - Failed to send email to: anh.ho@tititada.com
Traceback (most recent call last):
  File "/home/airflow/.local/lib/python3.8/site-packages/airflow/models/taskinstance.py", line 2335, in _run_raw_task
    self._execute_task_with_callbacks(context, test_mode, session=session)
  File "/home/airflow/.local/lib/python3.8/site-packages/airflow/models/taskinstance.py", line 2500, in _execute_task_with_callbacks
    result = self._execute_task(context, task_orig)
  File "/home/airflow/.local/lib/python3.8/site-packages/airflow/models/taskinstance.py", line 2517, in _execute_task
    return _execute_task(self, context, task_orig)
  File "/home/airflow/.local/lib/python3.8/site-packages/airflow/models/taskinstance.py", line 433, in _execute_task
    result = execute_callable(context=context, **execute_callable_kwargs)
  File "/home/airflow/.local/lib/python3.8/site-packages/airflow/operators/python.py", line 233, in execute
    return self.do_branch(context, super().execute(context))
  File "/home/airflow/.local/lib/python3.8/site-packages/airflow/operators/python.py", line 199, in execute
    return_value = self.execute_callable()
  File "/home/airflow/.local/lib/python3.8/site-packages/airflow/operators/python.py", line 216, in execute_callable
    return self.python_callable(*self.op_args, **self.op_kwargs)
  File "/opt/airflow/dags/CrawlCompanyInfo.py", line 50, in CheckTableExisting
    cursor = ConnectPostgres().cursor()
  File "/opt/airflow/dags/CrawlCompanyInfo.py", line 41, in ConnectPostgres
    raise e
  File "/opt/airflow/dags/CrawlCompanyInfo.py", line 26, in ConnectPostgres
    conn = psycopg2.connect(**params)
  File "/home/airflow/.local/lib/python3.8/site-packages/psycopg2/__init__.py", line 122, in connect
    conn = _connect(dsn, connection_factory=connection_factory, **kwasync)
psycopg2.OperationalError: connection to server at "172.17.0.2", port 5432 failed: Connection timed out
	Is the server running on that host and accepting TCP/IP connections?


During handling of the above exception, another exception occurred:

Traceback (most recent call last):
  File "/home/airflow/.local/lib/python3.8/site-packages/airflow/models/taskinstance.py", line 1000, in _email_alert
    send_email(task.email, subject, html_content)
  File "/home/airflow/.local/lib/python3.8/site-packages/airflow/utils/email.py", line 80, in send_email
    return backend(
  File "/home/airflow/.local/lib/python3.8/site-packages/airflow/utils/email.py", line 154, in send_email_smtp
    send_mime_email(e_from=mail_from, e_to=recipients, mime_msg=msg, conn_id=conn_id, dryrun=dryrun)
  File "/home/airflow/.local/lib/python3.8/site-packages/airflow/utils/email.py", line 272, in send_mime_email
    smtp_conn = _get_smtp_connection(smtp_host, smtp_port, smtp_timeout, smtp_ssl)
  File "/home/airflow/.local/lib/python3.8/site-packages/airflow/utils/email.py", line 316, in _get_smtp_connection
    return smtplib.SMTP(host=host, port=port, timeout=timeout)
  File "/usr/local/lib/python3.8/smtplib.py", line 255, in __init__
    (code, msg) = self.connect(host, port)
  File "/usr/local/lib/python3.8/smtplib.py", line 339, in connect
    self.sock = self._get_socket(host, port, self.timeout)
  File "/usr/local/lib/python3.8/smtplib.py", line 310, in _get_socket
    return socket.create_connection((host, port), timeout,
  File "/usr/local/lib/python3.8/socket.py", line 808, in create_connection
    raise err
  File "/usr/local/lib/python3.8/socket.py", line 796, in create_connection
    sock.connect(sa)
OSError: [Errno 99] Cannot assign requested address

During handling of the above exception, another exception occurred:

Traceback (most recent call last):
  File "/home/airflow/.local/lib/python3.8/site-packages/airflow/models/taskinstance.py", line 824, in _handle_failure
    task_instance.email_alert(error, failure_context["task"])
  File "/home/airflow/.local/lib/python3.8/site-packages/airflow/models/taskinstance.py", line 2947, in email_alert
    _email_alert(task_instance=self, exception=exception, task=task)
  File "/home/airflow/.local/lib/python3.8/site-packages/airflow/models/taskinstance.py", line 1002, in _email_alert
    send_email(task.email, subject, html_content_err)
  File "/home/airflow/.local/lib/python3.8/site-packages/airflow/utils/email.py", line 80, in send_email
    return backend(
  File "/home/airflow/.local/lib/python3.8/site-packages/airflow/utils/email.py", line 154, in send_email_smtp
    send_mime_email(e_from=mail_from, e_to=recipients, mime_msg=msg, conn_id=conn_id, dryrun=dryrun)
  File "/home/airflow/.local/lib/python3.8/site-packages/airflow/utils/email.py", line 272, in send_mime_email
    smtp_conn = _get_smtp_connection(smtp_host, smtp_port, smtp_timeout, smtp_ssl)
  File "/home/airflow/.local/lib/python3.8/site-packages/airflow/utils/email.py", line 316, in _get_smtp_connection
    return smtplib.SMTP(host=host, port=port, timeout=timeout)
  File "/usr/local/lib/python3.8/smtplib.py", line 255, in __init__
    (code, msg) = self.connect(host, port)
  File "/usr/local/lib/python3.8/smtplib.py", line 339, in connect
    self.sock = self._get_socket(host, port, self.timeout)
  File "/usr/local/lib/python3.8/smtplib.py", line 310, in _get_socket
    return socket.create_connection((host, port), timeout,
  File "/usr/local/lib/python3.8/socket.py", line 808, in create_connection
    raise err
  File "/usr/local/lib/python3.8/socket.py", line 796, in create_connection
    sock.connect(sa)
OSError: [Errno 99] Cannot assign requested address
[2024-01-19T02:25:52.808+0000] {standard_task_runner.py:107} ERROR - Failed to execute job 70 for task CheckTableExisting (connection to server at "172.17.0.2", port 5432 failed: Connection timed out
	Is the server running on that host and accepting TCP/IP connections?
; 110)
[2024-01-19T02:25:52.838+0000] {local_task_job_runner.py:234} INFO - Task exited with return code 1
[2024-01-19T02:25:52.867+0000] {taskinstance.py:3281} INFO - 0 downstream tasks scheduled from follow-on schedule check
[2024-01-19T02:30:17.853+0000] {taskinstance.py:1957} INFO - Dependencies all met for dep_context=non-requeueable deps ti=<TaskInstance: company_profile_pipeline.CheckTableExisting scheduled__2024-01-01T00:00:00+00:00 [queued]>
[2024-01-19T02:30:17.859+0000] {taskinstance.py:1957} INFO - Dependencies all met for dep_context=requeueable deps ti=<TaskInstance: company_profile_pipeline.CheckTableExisting scheduled__2024-01-01T00:00:00+00:00 [queued]>
[2024-01-19T02:30:17.860+0000] {taskinstance.py:2171} INFO - Starting attempt 1 of 1
[2024-01-19T02:30:17.869+0000] {taskinstance.py:2192} INFO - Executing <Task(BranchPythonOperator): CheckTableExisting> on 2024-01-01 00:00:00+00:00
[2024-01-19T02:30:17.873+0000] {standard_task_runner.py:60} INFO - Started process 253 to run task
[2024-01-19T02:30:17.875+0000] {standard_task_runner.py:87} INFO - Running: ['***', 'tasks', 'run', 'company_profile_pipeline', 'CheckTableExisting', 'scheduled__2024-01-01T00:00:00+00:00', '--job-id', '89', '--raw', '--subdir', 'DAGS_FOLDER/CrawlCompanyInfo.py', '--cfg-path', '/tmp/tmpxc4nk8vf']
[2024-01-19T02:30:17.876+0000] {standard_task_runner.py:88} INFO - Job 89: Subtask CheckTableExisting
[2024-01-19T02:30:17.902+0000] {task_command.py:423} INFO - Running <TaskInstance: company_profile_pipeline.CheckTableExisting scheduled__2024-01-01T00:00:00+00:00 [running]> on host a56b2d2a6d76
[2024-01-19T02:30:17.948+0000] {taskinstance.py:2481} INFO - Exporting env vars: AIRFLOW_CTX_DAG_EMAIL='anh.ho@tititada.com' AIRFLOW_CTX_DAG_OWNER='anh.ho' AIRFLOW_CTX_DAG_ID='company_profile_pipeline' AIRFLOW_CTX_TASK_ID='CheckTableExisting' AIRFLOW_CTX_EXECUTION_DATE='2024-01-01T00:00:00+00:00' AIRFLOW_CTX_TRY_NUMBER='1' AIRFLOW_CTX_DAG_RUN_ID='scheduled__2024-01-01T00:00:00+00:00'
[2024-01-19T02:30:17.949+0000] {logging_mixin.py:188} INFO - Connecting to the PostgreSQL database...
[2024-01-19T03:14:20.007+0000] {taskinstance.py:1957} INFO - Dependencies all met for dep_context=non-requeueable deps ti=<TaskInstance: company_profile_pipeline.CheckTableExisting scheduled__2024-01-01T00:00:00+00:00 [queued]>
[2024-01-19T03:14:20.014+0000] {taskinstance.py:1957} INFO - Dependencies all met for dep_context=requeueable deps ti=<TaskInstance: company_profile_pipeline.CheckTableExisting scheduled__2024-01-01T00:00:00+00:00 [queued]>
[2024-01-19T03:14:20.014+0000] {taskinstance.py:2171} INFO - Starting attempt 1 of 1
[2024-01-19T03:14:20.023+0000] {taskinstance.py:2192} INFO - Executing <Task(BranchPythonOperator): CheckTableExisting> on 2024-01-01 00:00:00+00:00
[2024-01-19T03:14:20.032+0000] {standard_task_runner.py:60} INFO - Started process 86 to run task
[2024-01-19T03:14:20.038+0000] {standard_task_runner.py:87} INFO - Running: ['***', 'tasks', 'run', 'company_profile_pipeline', 'CheckTableExisting', 'scheduled__2024-01-01T00:00:00+00:00', '--job-id', '113', '--raw', '--subdir', 'DAGS_FOLDER/CrawlCompanyInfo.py', '--cfg-path', '/tmp/tmpndvewcwa']
[2024-01-19T03:14:20.039+0000] {standard_task_runner.py:88} INFO - Job 113: Subtask CheckTableExisting
[2024-01-19T03:14:20.089+0000] {task_command.py:423} INFO - Running <TaskInstance: company_profile_pipeline.CheckTableExisting scheduled__2024-01-01T00:00:00+00:00 [running]> on host a56b2d2a6d76
[2024-01-19T03:14:20.152+0000] {taskinstance.py:2481} INFO - Exporting env vars: AIRFLOW_CTX_DAG_EMAIL='anh.ho@tititada.com' AIRFLOW_CTX_DAG_OWNER='anh.ho' AIRFLOW_CTX_DAG_ID='company_profile_pipeline' AIRFLOW_CTX_TASK_ID='CheckTableExisting' AIRFLOW_CTX_EXECUTION_DATE='2024-01-01T00:00:00+00:00' AIRFLOW_CTX_TRY_NUMBER='1' AIRFLOW_CTX_DAG_RUN_ID='scheduled__2024-01-01T00:00:00+00:00'
[2024-01-19T03:14:20.154+0000] {logging_mixin.py:188} INFO - Connecting to the PostgreSQL database...
[2024-01-19T03:14:20.156+0000] {taskinstance.py:2699} ERROR - Task failed with exception
Traceback (most recent call last):
  File "/home/airflow/.local/lib/python3.8/site-packages/airflow/models/taskinstance.py", line 433, in _execute_task
    result = execute_callable(context=context, **execute_callable_kwargs)
  File "/home/airflow/.local/lib/python3.8/site-packages/airflow/operators/python.py", line 233, in execute
    return self.do_branch(context, super().execute(context))
  File "/home/airflow/.local/lib/python3.8/site-packages/airflow/operators/python.py", line 199, in execute
    return_value = self.execute_callable()
  File "/home/airflow/.local/lib/python3.8/site-packages/airflow/operators/python.py", line 216, in execute_callable
    return self.python_callable(*self.op_args, **self.op_kwargs)
  File "/opt/airflow/dags/CrawlCompanyInfo.py", line 50, in CheckTableExisting
    cursor = ConnectPostgres().cursor()
  File "/opt/airflow/dags/CrawlCompanyInfo.py", line 41, in ConnectPostgres
    raise e
  File "/opt/airflow/dags/CrawlCompanyInfo.py", line 26, in ConnectPostgres
    conn = psycopg2.connect(**params)
  File "/home/airflow/.local/lib/python3.8/site-packages/psycopg2/__init__.py", line 122, in connect
    conn = _connect(dsn, connection_factory=connection_factory, **kwasync)
psycopg2.OperationalError: connection to server at "0.0.0.0", port 5432 failed: Connection refused
	Is the server running on that host and accepting TCP/IP connections?

[2024-01-19T03:14:20.175+0000] {taskinstance.py:1138} INFO - Marking task as FAILED. dag_id=company_profile_pipeline, task_id=CheckTableExisting, execution_date=20240101T000000, start_date=20240119T031420, end_date=20240119T031420
[2024-01-19T03:14:20.186+0000] {warnings.py:109} WARNING - /home/***/.local/lib/python3.8/site-packages/***/utils/email.py:154: RemovedInAirflow3Warning: Fetching SMTP credentials from configuration variables will be deprecated in a future release. Please set credentials using a connection instead.
  send_mime_email(e_from=mail_from, e_to=recipients, mime_msg=msg, conn_id=conn_id, dryrun=dryrun)

[2024-01-19T03:14:20.188+0000] {configuration.py:1046} WARNING - section/key [smtp/smtp_user] not found in config
[2024-01-19T03:14:20.192+0000] {email.py:270} INFO - Email alerting: attempt 1
[2024-01-19T03:14:20.201+0000] {configuration.py:1046} WARNING - section/key [smtp/smtp_user] not found in config
[2024-01-19T03:14:20.203+0000] {email.py:270} INFO - Email alerting: attempt 1
[2024-01-19T03:14:20.205+0000] {taskinstance.py:826} ERROR - Failed to send email to: anh.ho@tititada.com
Traceback (most recent call last):
  File "/home/airflow/.local/lib/python3.8/site-packages/airflow/models/taskinstance.py", line 2335, in _run_raw_task
    self._execute_task_with_callbacks(context, test_mode, session=session)
  File "/home/airflow/.local/lib/python3.8/site-packages/airflow/models/taskinstance.py", line 2500, in _execute_task_with_callbacks
    result = self._execute_task(context, task_orig)
  File "/home/airflow/.local/lib/python3.8/site-packages/airflow/models/taskinstance.py", line 2517, in _execute_task
    return _execute_task(self, context, task_orig)
  File "/home/airflow/.local/lib/python3.8/site-packages/airflow/models/taskinstance.py", line 433, in _execute_task
    result = execute_callable(context=context, **execute_callable_kwargs)
  File "/home/airflow/.local/lib/python3.8/site-packages/airflow/operators/python.py", line 233, in execute
    return self.do_branch(context, super().execute(context))
  File "/home/airflow/.local/lib/python3.8/site-packages/airflow/operators/python.py", line 199, in execute
    return_value = self.execute_callable()
  File "/home/airflow/.local/lib/python3.8/site-packages/airflow/operators/python.py", line 216, in execute_callable
    return self.python_callable(*self.op_args, **self.op_kwargs)
  File "/opt/airflow/dags/CrawlCompanyInfo.py", line 50, in CheckTableExisting
    cursor = ConnectPostgres().cursor()
  File "/opt/airflow/dags/CrawlCompanyInfo.py", line 41, in ConnectPostgres
    raise e
  File "/opt/airflow/dags/CrawlCompanyInfo.py", line 26, in ConnectPostgres
    conn = psycopg2.connect(**params)
  File "/home/airflow/.local/lib/python3.8/site-packages/psycopg2/__init__.py", line 122, in connect
    conn = _connect(dsn, connection_factory=connection_factory, **kwasync)
psycopg2.OperationalError: connection to server at "0.0.0.0", port 5432 failed: Connection refused
	Is the server running on that host and accepting TCP/IP connections?


During handling of the above exception, another exception occurred:

Traceback (most recent call last):
  File "/home/airflow/.local/lib/python3.8/site-packages/airflow/models/taskinstance.py", line 1000, in _email_alert
    send_email(task.email, subject, html_content)
  File "/home/airflow/.local/lib/python3.8/site-packages/airflow/utils/email.py", line 80, in send_email
    return backend(
  File "/home/airflow/.local/lib/python3.8/site-packages/airflow/utils/email.py", line 154, in send_email_smtp
    send_mime_email(e_from=mail_from, e_to=recipients, mime_msg=msg, conn_id=conn_id, dryrun=dryrun)
  File "/home/airflow/.local/lib/python3.8/site-packages/airflow/utils/email.py", line 272, in send_mime_email
    smtp_conn = _get_smtp_connection(smtp_host, smtp_port, smtp_timeout, smtp_ssl)
  File "/home/airflow/.local/lib/python3.8/site-packages/airflow/utils/email.py", line 316, in _get_smtp_connection
    return smtplib.SMTP(host=host, port=port, timeout=timeout)
  File "/usr/local/lib/python3.8/smtplib.py", line 255, in __init__
    (code, msg) = self.connect(host, port)
  File "/usr/local/lib/python3.8/smtplib.py", line 339, in connect
    self.sock = self._get_socket(host, port, self.timeout)
  File "/usr/local/lib/python3.8/smtplib.py", line 310, in _get_socket
    return socket.create_connection((host, port), timeout,
  File "/usr/local/lib/python3.8/socket.py", line 808, in create_connection
    raise err
  File "/usr/local/lib/python3.8/socket.py", line 796, in create_connection
    sock.connect(sa)
OSError: [Errno 99] Cannot assign requested address

During handling of the above exception, another exception occurred:

Traceback (most recent call last):
  File "/home/airflow/.local/lib/python3.8/site-packages/airflow/models/taskinstance.py", line 824, in _handle_failure
    task_instance.email_alert(error, failure_context["task"])
  File "/home/airflow/.local/lib/python3.8/site-packages/airflow/models/taskinstance.py", line 2947, in email_alert
    _email_alert(task_instance=self, exception=exception, task=task)
  File "/home/airflow/.local/lib/python3.8/site-packages/airflow/models/taskinstance.py", line 1002, in _email_alert
    send_email(task.email, subject, html_content_err)
  File "/home/airflow/.local/lib/python3.8/site-packages/airflow/utils/email.py", line 80, in send_email
    return backend(
  File "/home/airflow/.local/lib/python3.8/site-packages/airflow/utils/email.py", line 154, in send_email_smtp
    send_mime_email(e_from=mail_from, e_to=recipients, mime_msg=msg, conn_id=conn_id, dryrun=dryrun)
  File "/home/airflow/.local/lib/python3.8/site-packages/airflow/utils/email.py", line 272, in send_mime_email
    smtp_conn = _get_smtp_connection(smtp_host, smtp_port, smtp_timeout, smtp_ssl)
  File "/home/airflow/.local/lib/python3.8/site-packages/airflow/utils/email.py", line 316, in _get_smtp_connection
    return smtplib.SMTP(host=host, port=port, timeout=timeout)
  File "/usr/local/lib/python3.8/smtplib.py", line 255, in __init__
    (code, msg) = self.connect(host, port)
  File "/usr/local/lib/python3.8/smtplib.py", line 339, in connect
    self.sock = self._get_socket(host, port, self.timeout)
  File "/usr/local/lib/python3.8/smtplib.py", line 310, in _get_socket
    return socket.create_connection((host, port), timeout,
  File "/usr/local/lib/python3.8/socket.py", line 808, in create_connection
    raise err
  File "/usr/local/lib/python3.8/socket.py", line 796, in create_connection
    sock.connect(sa)
OSError: [Errno 99] Cannot assign requested address
[2024-01-19T03:14:20.219+0000] {standard_task_runner.py:107} ERROR - Failed to execute job 113 for task CheckTableExisting (connection to server at "0.0.0.0", port 5432 failed: Connection refused
	Is the server running on that host and accepting TCP/IP connections?
; 86)
[2024-01-19T03:14:20.256+0000] {local_task_job_runner.py:234} INFO - Task exited with return code 1
[2024-01-19T03:14:20.283+0000] {taskinstance.py:3281} INFO - 0 downstream tasks scheduled from follow-on schedule check
[2024-01-19T03:16:00.990+0000] {taskinstance.py:1957} INFO - Dependencies all met for dep_context=non-requeueable deps ti=<TaskInstance: company_profile_pipeline.CheckTableExisting scheduled__2024-01-01T00:00:00+00:00 [queued]>
[2024-01-19T03:16:00.995+0000] {taskinstance.py:1957} INFO - Dependencies all met for dep_context=requeueable deps ti=<TaskInstance: company_profile_pipeline.CheckTableExisting scheduled__2024-01-01T00:00:00+00:00 [queued]>
[2024-01-19T03:16:00.995+0000] {taskinstance.py:2171} INFO - Starting attempt 1 of 1
[2024-01-19T03:16:01.002+0000] {taskinstance.py:2192} INFO - Executing <Task(BranchPythonOperator): CheckTableExisting> on 2024-01-01 00:00:00+00:00
[2024-01-19T03:16:01.010+0000] {standard_task_runner.py:60} INFO - Started process 217 to run task
[2024-01-19T03:16:01.015+0000] {standard_task_runner.py:87} INFO - Running: ['***', 'tasks', 'run', 'company_profile_pipeline', 'CheckTableExisting', 'scheduled__2024-01-01T00:00:00+00:00', '--job-id', '168', '--raw', '--subdir', 'DAGS_FOLDER/CrawlCompanyInfo.py', '--cfg-path', '/tmp/tmpok7xo32r']
[2024-01-19T03:16:01.017+0000] {standard_task_runner.py:88} INFO - Job 168: Subtask CheckTableExisting
[2024-01-19T03:16:01.061+0000] {task_command.py:423} INFO - Running <TaskInstance: company_profile_pipeline.CheckTableExisting scheduled__2024-01-01T00:00:00+00:00 [running]> on host a56b2d2a6d76
[2024-01-19T03:16:01.112+0000] {taskinstance.py:2481} INFO - Exporting env vars: AIRFLOW_CTX_DAG_EMAIL='anh.ho@tititada.com' AIRFLOW_CTX_DAG_OWNER='anh.ho' AIRFLOW_CTX_DAG_ID='company_profile_pipeline' AIRFLOW_CTX_TASK_ID='CheckTableExisting' AIRFLOW_CTX_EXECUTION_DATE='2024-01-01T00:00:00+00:00' AIRFLOW_CTX_TRY_NUMBER='1' AIRFLOW_CTX_DAG_RUN_ID='scheduled__2024-01-01T00:00:00+00:00'
[2024-01-19T03:16:01.113+0000] {logging_mixin.py:188} INFO - Connecting to the PostgreSQL database...
[2024-01-19T03:16:01.114+0000] {taskinstance.py:2699} ERROR - Task failed with exception
Traceback (most recent call last):
  File "/home/airflow/.local/lib/python3.8/site-packages/airflow/models/taskinstance.py", line 433, in _execute_task
    result = execute_callable(context=context, **execute_callable_kwargs)
  File "/home/airflow/.local/lib/python3.8/site-packages/airflow/operators/python.py", line 233, in execute
    return self.do_branch(context, super().execute(context))
  File "/home/airflow/.local/lib/python3.8/site-packages/airflow/operators/python.py", line 199, in execute
    return_value = self.execute_callable()
  File "/home/airflow/.local/lib/python3.8/site-packages/airflow/operators/python.py", line 216, in execute_callable
    return self.python_callable(*self.op_args, **self.op_kwargs)
  File "/opt/airflow/dags/CrawlCompanyInfo.py", line 50, in CheckTableExisting
    cursor = ConnectPostgres().cursor()
  File "/opt/airflow/dags/CrawlCompanyInfo.py", line 41, in ConnectPostgres
    raise e
  File "/opt/airflow/dags/CrawlCompanyInfo.py", line 26, in ConnectPostgres
    conn = psycopg2.connect(**params)
  File "/home/airflow/.local/lib/python3.8/site-packages/psycopg2/__init__.py", line 122, in connect
    conn = _connect(dsn, connection_factory=connection_factory, **kwasync)
psycopg2.OperationalError: connection to server at "0.0.0.0", port 5432 failed: Connection refused
	Is the server running on that host and accepting TCP/IP connections?

[2024-01-19T03:16:01.127+0000] {taskinstance.py:1138} INFO - Marking task as FAILED. dag_id=company_profile_pipeline, task_id=CheckTableExisting, execution_date=20240101T000000, start_date=20240119T031600, end_date=20240119T031601
[2024-01-19T03:16:01.138+0000] {warnings.py:109} WARNING - /home/***/.local/lib/python3.8/site-packages/***/utils/email.py:154: RemovedInAirflow3Warning: Fetching SMTP credentials from configuration variables will be deprecated in a future release. Please set credentials using a connection instead.
  send_mime_email(e_from=mail_from, e_to=recipients, mime_msg=msg, conn_id=conn_id, dryrun=dryrun)

[2024-01-19T03:16:01.138+0000] {configuration.py:1046} WARNING - section/key [smtp/smtp_user] not found in config
[2024-01-19T03:16:01.139+0000] {email.py:270} INFO - Email alerting: attempt 1
[2024-01-19T03:16:01.147+0000] {configuration.py:1046} WARNING - section/key [smtp/smtp_user] not found in config
[2024-01-19T03:16:01.149+0000] {email.py:270} INFO - Email alerting: attempt 1
[2024-01-19T03:16:01.150+0000] {taskinstance.py:826} ERROR - Failed to send email to: anh.ho@tititada.com
Traceback (most recent call last):
  File "/home/airflow/.local/lib/python3.8/site-packages/airflow/models/taskinstance.py", line 2335, in _run_raw_task
    self._execute_task_with_callbacks(context, test_mode, session=session)
  File "/home/airflow/.local/lib/python3.8/site-packages/airflow/models/taskinstance.py", line 2500, in _execute_task_with_callbacks
    result = self._execute_task(context, task_orig)
  File "/home/airflow/.local/lib/python3.8/site-packages/airflow/models/taskinstance.py", line 2517, in _execute_task
    return _execute_task(self, context, task_orig)
  File "/home/airflow/.local/lib/python3.8/site-packages/airflow/models/taskinstance.py", line 433, in _execute_task
    result = execute_callable(context=context, **execute_callable_kwargs)
  File "/home/airflow/.local/lib/python3.8/site-packages/airflow/operators/python.py", line 233, in execute
    return self.do_branch(context, super().execute(context))
  File "/home/airflow/.local/lib/python3.8/site-packages/airflow/operators/python.py", line 199, in execute
    return_value = self.execute_callable()
  File "/home/airflow/.local/lib/python3.8/site-packages/airflow/operators/python.py", line 216, in execute_callable
    return self.python_callable(*self.op_args, **self.op_kwargs)
  File "/opt/airflow/dags/CrawlCompanyInfo.py", line 50, in CheckTableExisting
    cursor = ConnectPostgres().cursor()
  File "/opt/airflow/dags/CrawlCompanyInfo.py", line 41, in ConnectPostgres
    raise e
  File "/opt/airflow/dags/CrawlCompanyInfo.py", line 26, in ConnectPostgres
    conn = psycopg2.connect(**params)
  File "/home/airflow/.local/lib/python3.8/site-packages/psycopg2/__init__.py", line 122, in connect
    conn = _connect(dsn, connection_factory=connection_factory, **kwasync)
psycopg2.OperationalError: connection to server at "0.0.0.0", port 5432 failed: Connection refused
	Is the server running on that host and accepting TCP/IP connections?


During handling of the above exception, another exception occurred:

Traceback (most recent call last):
  File "/home/airflow/.local/lib/python3.8/site-packages/airflow/models/taskinstance.py", line 1000, in _email_alert
    send_email(task.email, subject, html_content)
  File "/home/airflow/.local/lib/python3.8/site-packages/airflow/utils/email.py", line 80, in send_email
    return backend(
  File "/home/airflow/.local/lib/python3.8/site-packages/airflow/utils/email.py", line 154, in send_email_smtp
    send_mime_email(e_from=mail_from, e_to=recipients, mime_msg=msg, conn_id=conn_id, dryrun=dryrun)
  File "/home/airflow/.local/lib/python3.8/site-packages/airflow/utils/email.py", line 272, in send_mime_email
    smtp_conn = _get_smtp_connection(smtp_host, smtp_port, smtp_timeout, smtp_ssl)
  File "/home/airflow/.local/lib/python3.8/site-packages/airflow/utils/email.py", line 316, in _get_smtp_connection
    return smtplib.SMTP(host=host, port=port, timeout=timeout)
  File "/usr/local/lib/python3.8/smtplib.py", line 255, in __init__
    (code, msg) = self.connect(host, port)
  File "/usr/local/lib/python3.8/smtplib.py", line 339, in connect
    self.sock = self._get_socket(host, port, self.timeout)
  File "/usr/local/lib/python3.8/smtplib.py", line 310, in _get_socket
    return socket.create_connection((host, port), timeout,
  File "/usr/local/lib/python3.8/socket.py", line 808, in create_connection
    raise err
  File "/usr/local/lib/python3.8/socket.py", line 796, in create_connection
    sock.connect(sa)
OSError: [Errno 99] Cannot assign requested address

During handling of the above exception, another exception occurred:

Traceback (most recent call last):
  File "/home/airflow/.local/lib/python3.8/site-packages/airflow/models/taskinstance.py", line 824, in _handle_failure
    task_instance.email_alert(error, failure_context["task"])
  File "/home/airflow/.local/lib/python3.8/site-packages/airflow/models/taskinstance.py", line 2947, in email_alert
    _email_alert(task_instance=self, exception=exception, task=task)
  File "/home/airflow/.local/lib/python3.8/site-packages/airflow/models/taskinstance.py", line 1002, in _email_alert
    send_email(task.email, subject, html_content_err)
  File "/home/airflow/.local/lib/python3.8/site-packages/airflow/utils/email.py", line 80, in send_email
    return backend(
  File "/home/airflow/.local/lib/python3.8/site-packages/airflow/utils/email.py", line 154, in send_email_smtp
    send_mime_email(e_from=mail_from, e_to=recipients, mime_msg=msg, conn_id=conn_id, dryrun=dryrun)
  File "/home/airflow/.local/lib/python3.8/site-packages/airflow/utils/email.py", line 272, in send_mime_email
    smtp_conn = _get_smtp_connection(smtp_host, smtp_port, smtp_timeout, smtp_ssl)
  File "/home/airflow/.local/lib/python3.8/site-packages/airflow/utils/email.py", line 316, in _get_smtp_connection
    return smtplib.SMTP(host=host, port=port, timeout=timeout)
  File "/usr/local/lib/python3.8/smtplib.py", line 255, in __init__
    (code, msg) = self.connect(host, port)
  File "/usr/local/lib/python3.8/smtplib.py", line 339, in connect
    self.sock = self._get_socket(host, port, self.timeout)
  File "/usr/local/lib/python3.8/smtplib.py", line 310, in _get_socket
    return socket.create_connection((host, port), timeout,
  File "/usr/local/lib/python3.8/socket.py", line 808, in create_connection
    raise err
  File "/usr/local/lib/python3.8/socket.py", line 796, in create_connection
    sock.connect(sa)
OSError: [Errno 99] Cannot assign requested address
[2024-01-19T03:16:01.159+0000] {standard_task_runner.py:107} ERROR - Failed to execute job 168 for task CheckTableExisting (connection to server at "0.0.0.0", port 5432 failed: Connection refused
	Is the server running on that host and accepting TCP/IP connections?
; 217)
[2024-01-19T03:16:01.189+0000] {local_task_job_runner.py:234} INFO - Task exited with return code 1
[2024-01-19T03:16:01.206+0000] {taskinstance.py:3281} INFO - 0 downstream tasks scheduled from follow-on schedule check
[2024-01-19T04:05:33.178+0000] {taskinstance.py:1957} INFO - Dependencies all met for dep_context=non-requeueable deps ti=<TaskInstance: company_profile_pipeline.CheckTableExisting scheduled__2024-01-01T00:00:00+00:00 [queued]>
[2024-01-19T04:05:33.182+0000] {taskinstance.py:1957} INFO - Dependencies all met for dep_context=requeueable deps ti=<TaskInstance: company_profile_pipeline.CheckTableExisting scheduled__2024-01-01T00:00:00+00:00 [queued]>
[2024-01-19T04:05:33.182+0000] {taskinstance.py:2171} INFO - Starting attempt 1 of 1
[2024-01-19T04:05:33.195+0000] {taskinstance.py:2192} INFO - Executing <Task(BranchPythonOperator): CheckTableExisting> on 2024-01-01 00:00:00+00:00
[2024-01-19T04:05:33.199+0000] {standard_task_runner.py:60} INFO - Started process 89 to run task
[2024-01-19T04:05:33.203+0000] {standard_task_runner.py:87} INFO - Running: ['***', 'tasks', 'run', 'company_profile_pipeline', 'CheckTableExisting', 'scheduled__2024-01-01T00:00:00+00:00', '--job-id', '202', '--raw', '--subdir', 'DAGS_FOLDER/CrawlCompanyInfo.py', '--cfg-path', '/tmp/tmpukmhk4or']
[2024-01-19T04:05:33.204+0000] {standard_task_runner.py:88} INFO - Job 202: Subtask CheckTableExisting
[2024-01-19T04:05:33.236+0000] {task_command.py:423} INFO - Running <TaskInstance: company_profile_pipeline.CheckTableExisting scheduled__2024-01-01T00:00:00+00:00 [running]> on host f27b64f975c2
[2024-01-19T04:05:33.283+0000] {taskinstance.py:2481} INFO - Exporting env vars: AIRFLOW_CTX_DAG_EMAIL='anh.ho@tititada.com' AIRFLOW_CTX_DAG_OWNER='anh.ho' AIRFLOW_CTX_DAG_ID='company_profile_pipeline' AIRFLOW_CTX_TASK_ID='CheckTableExisting' AIRFLOW_CTX_EXECUTION_DATE='2024-01-01T00:00:00+00:00' AIRFLOW_CTX_TRY_NUMBER='1' AIRFLOW_CTX_DAG_RUN_ID='scheduled__2024-01-01T00:00:00+00:00'
[2024-01-19T04:05:33.284+0000] {logging_mixin.py:188} INFO - Connecting to the PostgreSQL database...
[2024-01-19T04:05:33.287+0000] {logging_mixin.py:188} INFO - PostgreSQL database version:
[2024-01-19T04:05:33.288+0000] {logging_mixin.py:188} INFO - Successfully connect to Postgresql
[2024-01-19T04:05:33.289+0000] {logging_mixin.py:188} INFO - ('PostgreSQL 13.13 (Debian 13.13-1.pgdg120+1) on aarch64-unknown-linux-gnu, compiled by gcc (Debian 12.2.0-14) 12.2.0, 64-bit',)
[2024-01-19T04:05:33.289+0000] {logging_mixin.py:188} INFO - Checking existing table...
[2024-01-19T04:05:33.291+0000] {python.py:201} INFO - Done. Returned value was: InsertDataFunction
[2024-01-19T04:05:33.291+0000] {branch.py:35} INFO - Branch into InsertDataFunction
[2024-01-19T04:05:33.292+0000] {skipmixin.py:178} INFO - Following branch InsertDataFunction
[2024-01-19T04:05:33.301+0000] {taskinstance.py:2699} ERROR - Task failed with exception
Traceback (most recent call last):
  File "/home/airflow/.local/lib/python3.8/site-packages/airflow/models/taskinstance.py", line 433, in _execute_task
    result = execute_callable(context=context, **execute_callable_kwargs)
  File "/home/airflow/.local/lib/python3.8/site-packages/airflow/operators/python.py", line 233, in execute
    return self.do_branch(context, super().execute(context))
  File "/home/airflow/.local/lib/python3.8/site-packages/airflow/operators/branch.py", line 36, in do_branch
    self.skip_all_except(context["ti"], branches_to_execute)
  File "/home/airflow/.local/lib/python3.8/site-packages/airflow/models/skipmixin.py", line 213, in skip_all_except
    raise AirflowException(
airflow.exceptions.AirflowException: 'branch_task_ids' must contain only valid task_ids. Invalid tasks found: {'InsertDataFunction'}.
[2024-01-19T04:05:33.305+0000] {taskinstance.py:1138} INFO - Marking task as FAILED. dag_id=company_profile_pipeline, task_id=CheckTableExisting, execution_date=20240101T000000, start_date=20240119T040533, end_date=20240119T040533
[2024-01-19T04:05:33.317+0000] {warnings.py:109} WARNING - /home/***/.local/lib/python3.8/site-packages/***/utils/email.py:154: RemovedInAirflow3Warning: Fetching SMTP credentials from configuration variables will be deprecated in a future release. Please set credentials using a connection instead.
  send_mime_email(e_from=mail_from, e_to=recipients, mime_msg=msg, conn_id=conn_id, dryrun=dryrun)

[2024-01-19T04:05:33.319+0000] {configuration.py:1046} WARNING - section/key [smtp/smtp_user] not found in config
[2024-01-19T04:05:33.319+0000] {email.py:270} INFO - Email alerting: attempt 1
[2024-01-19T04:05:33.324+0000] {configuration.py:1046} WARNING - section/key [smtp/smtp_user] not found in config
[2024-01-19T04:05:33.324+0000] {email.py:270} INFO - Email alerting: attempt 1
[2024-01-19T04:05:33.325+0000] {taskinstance.py:826} ERROR - Failed to send email to: anh.ho@tititada.com
Traceback (most recent call last):
  File "/home/airflow/.local/lib/python3.8/site-packages/airflow/models/taskinstance.py", line 2335, in _run_raw_task
    self._execute_task_with_callbacks(context, test_mode, session=session)
  File "/home/airflow/.local/lib/python3.8/site-packages/airflow/models/taskinstance.py", line 2500, in _execute_task_with_callbacks
    result = self._execute_task(context, task_orig)
  File "/home/airflow/.local/lib/python3.8/site-packages/airflow/models/taskinstance.py", line 2517, in _execute_task
    return _execute_task(self, context, task_orig)
  File "/home/airflow/.local/lib/python3.8/site-packages/airflow/models/taskinstance.py", line 433, in _execute_task
    result = execute_callable(context=context, **execute_callable_kwargs)
  File "/home/airflow/.local/lib/python3.8/site-packages/airflow/operators/python.py", line 233, in execute
    return self.do_branch(context, super().execute(context))
  File "/home/airflow/.local/lib/python3.8/site-packages/airflow/operators/branch.py", line 36, in do_branch
    self.skip_all_except(context["ti"], branches_to_execute)
  File "/home/airflow/.local/lib/python3.8/site-packages/airflow/models/skipmixin.py", line 213, in skip_all_except
    raise AirflowException(
airflow.exceptions.AirflowException: 'branch_task_ids' must contain only valid task_ids. Invalid tasks found: {'InsertDataFunction'}.

During handling of the above exception, another exception occurred:

Traceback (most recent call last):
  File "/home/airflow/.local/lib/python3.8/site-packages/airflow/models/taskinstance.py", line 1000, in _email_alert
    send_email(task.email, subject, html_content)
  File "/home/airflow/.local/lib/python3.8/site-packages/airflow/utils/email.py", line 80, in send_email
    return backend(
  File "/home/airflow/.local/lib/python3.8/site-packages/airflow/utils/email.py", line 154, in send_email_smtp
    send_mime_email(e_from=mail_from, e_to=recipients, mime_msg=msg, conn_id=conn_id, dryrun=dryrun)
  File "/home/airflow/.local/lib/python3.8/site-packages/airflow/utils/email.py", line 272, in send_mime_email
    smtp_conn = _get_smtp_connection(smtp_host, smtp_port, smtp_timeout, smtp_ssl)
  File "/home/airflow/.local/lib/python3.8/site-packages/airflow/utils/email.py", line 316, in _get_smtp_connection
    return smtplib.SMTP(host=host, port=port, timeout=timeout)
  File "/usr/local/lib/python3.8/smtplib.py", line 255, in __init__
    (code, msg) = self.connect(host, port)
  File "/usr/local/lib/python3.8/smtplib.py", line 339, in connect
    self.sock = self._get_socket(host, port, self.timeout)
  File "/usr/local/lib/python3.8/smtplib.py", line 310, in _get_socket
    return socket.create_connection((host, port), timeout,
  File "/usr/local/lib/python3.8/socket.py", line 808, in create_connection
    raise err
  File "/usr/local/lib/python3.8/socket.py", line 796, in create_connection
    sock.connect(sa)
OSError: [Errno 99] Cannot assign requested address

During handling of the above exception, another exception occurred:

Traceback (most recent call last):
  File "/home/airflow/.local/lib/python3.8/site-packages/airflow/models/taskinstance.py", line 824, in _handle_failure
    task_instance.email_alert(error, failure_context["task"])
  File "/home/airflow/.local/lib/python3.8/site-packages/airflow/models/taskinstance.py", line 2947, in email_alert
    _email_alert(task_instance=self, exception=exception, task=task)
  File "/home/airflow/.local/lib/python3.8/site-packages/airflow/models/taskinstance.py", line 1002, in _email_alert
    send_email(task.email, subject, html_content_err)
  File "/home/airflow/.local/lib/python3.8/site-packages/airflow/utils/email.py", line 80, in send_email
    return backend(
  File "/home/airflow/.local/lib/python3.8/site-packages/airflow/utils/email.py", line 154, in send_email_smtp
    send_mime_email(e_from=mail_from, e_to=recipients, mime_msg=msg, conn_id=conn_id, dryrun=dryrun)
  File "/home/airflow/.local/lib/python3.8/site-packages/airflow/utils/email.py", line 272, in send_mime_email
    smtp_conn = _get_smtp_connection(smtp_host, smtp_port, smtp_timeout, smtp_ssl)
  File "/home/airflow/.local/lib/python3.8/site-packages/airflow/utils/email.py", line 316, in _get_smtp_connection
    return smtplib.SMTP(host=host, port=port, timeout=timeout)
  File "/usr/local/lib/python3.8/smtplib.py", line 255, in __init__
    (code, msg) = self.connect(host, port)
  File "/usr/local/lib/python3.8/smtplib.py", line 339, in connect
    self.sock = self._get_socket(host, port, self.timeout)
  File "/usr/local/lib/python3.8/smtplib.py", line 310, in _get_socket
    return socket.create_connection((host, port), timeout,
  File "/usr/local/lib/python3.8/socket.py", line 808, in create_connection
    raise err
  File "/usr/local/lib/python3.8/socket.py", line 796, in create_connection
    sock.connect(sa)
OSError: [Errno 99] Cannot assign requested address
[2024-01-19T04:05:33.333+0000] {standard_task_runner.py:107} ERROR - Failed to execute job 202 for task CheckTableExisting ('branch_task_ids' must contain only valid task_ids. Invalid tasks found: {'InsertDataFunction'}.; 89)
[2024-01-19T04:05:33.375+0000] {local_task_job_runner.py:234} INFO - Task exited with return code 1
[2024-01-19T04:05:33.388+0000] {taskinstance.py:3281} INFO - 0 downstream tasks scheduled from follow-on schedule check
