[2024-01-18T09:57:11.862+0000] {taskinstance.py:1957} INFO - Dependencies all met for dep_context=non-requeueable deps ti=<TaskInstance: company_profile_pipeline.CheckTableExisting scheduled__2024-01-11T00:00:00+00:00 [queued]>
[2024-01-18T09:57:11.868+0000] {taskinstance.py:1957} INFO - Dependencies all met for dep_context=requeueable deps ti=<TaskInstance: company_profile_pipeline.CheckTableExisting scheduled__2024-01-11T00:00:00+00:00 [queued]>
[2024-01-18T09:57:11.869+0000] {taskinstance.py:2171} INFO - Starting attempt 1 of 1
[2024-01-18T09:57:11.876+0000] {taskinstance.py:2192} INFO - Executing <Task(BranchPythonOperator): CheckTableExisting> on 2024-01-11 00:00:00+00:00
[2024-01-18T09:57:11.881+0000] {standard_task_runner.py:60} INFO - Started process 102 to run task
[2024-01-18T09:57:11.884+0000] {standard_task_runner.py:87} INFO - Running: ['***', 'tasks', 'run', 'company_profile_pipeline', 'CheckTableExisting', 'scheduled__2024-01-11T00:00:00+00:00', '--job-id', '28', '--raw', '--subdir', 'DAGS_FOLDER/CrawlCompanyInfo.py', '--cfg-path', '/tmp/tmpw5vkscnu']
[2024-01-18T09:57:11.885+0000] {standard_task_runner.py:88} INFO - Job 28: Subtask CheckTableExisting
[2024-01-18T09:57:11.918+0000] {task_command.py:423} INFO - Running <TaskInstance: company_profile_pipeline.CheckTableExisting scheduled__2024-01-11T00:00:00+00:00 [running]> on host a56b2d2a6d76
[2024-01-18T09:57:11.966+0000] {taskinstance.py:2481} INFO - Exporting env vars: AIRFLOW_CTX_DAG_EMAIL='anh.ho@tititada.com' AIRFLOW_CTX_DAG_OWNER='anh.ho' AIRFLOW_CTX_DAG_ID='company_profile_pipeline' AIRFLOW_CTX_TASK_ID='CheckTableExisting' AIRFLOW_CTX_EXECUTION_DATE='2024-01-11T00:00:00+00:00' AIRFLOW_CTX_TRY_NUMBER='1' AIRFLOW_CTX_DAG_RUN_ID='scheduled__2024-01-11T00:00:00+00:00'
[2024-01-18T09:57:11.968+0000] {taskinstance.py:2699} ERROR - Task failed with exception
Traceback (most recent call last):
  File "/home/airflow/.local/lib/python3.8/site-packages/airflow/models/taskinstance.py", line 433, in _execute_task
    result = execute_callable(context=context, **execute_callable_kwargs)
  File "/home/airflow/.local/lib/python3.8/site-packages/airflow/operators/python.py", line 233, in execute
    return self.do_branch(context, super().execute(context))
  File "/home/airflow/.local/lib/python3.8/site-packages/airflow/operators/python.py", line 199, in execute
    return_value = self.execute_callable()
  File "/home/airflow/.local/lib/python3.8/site-packages/airflow/operators/python.py", line 216, in execute_callable
    return self.python_callable(*self.op_args, **self.op_kwargs)
  File "/opt/airflow/dags/CrawlCompanyInfo.py", line 55, in CheckTableExisting
    cursor = ConnectPostgres().cursor()
  File "/opt/airflow/dags/CrawlCompanyInfo.py", line 27, in ConnectPostgres
    params = ReadConfigFile(relative_path,section)
  File "/opt/airflow/dags/GetAuthInfoFuncton.py", line 25, in ReadConfigFile
    raise Exception('Section {0} not found in the {1} file'.format(section, text_file_path))
Exception: Section Postgresql not found in the /Users/anhho/Desktop/DataEngineer/CrawlStockData/CrawlFunction/Authorization.ini file
[2024-01-18T09:57:11.975+0000] {taskinstance.py:1138} INFO - Marking task as FAILED. dag_id=company_profile_pipeline, task_id=CheckTableExisting, execution_date=20240111T000000, start_date=20240118T095711, end_date=20240118T095711
[2024-01-18T09:57:11.982+0000] {warnings.py:109} WARNING - /home/***/.local/lib/python3.8/site-packages/***/utils/email.py:154: RemovedInAirflow3Warning: Fetching SMTP credentials from configuration variables will be deprecated in a future release. Please set credentials using a connection instead.
  send_mime_email(e_from=mail_from, e_to=recipients, mime_msg=msg, conn_id=conn_id, dryrun=dryrun)

[2024-01-18T09:57:11.983+0000] {configuration.py:1046} WARNING - section/key [smtp/smtp_user] not found in config
[2024-01-18T09:57:11.983+0000] {email.py:270} INFO - Email alerting: attempt 1
[2024-01-18T09:57:11.988+0000] {configuration.py:1046} WARNING - section/key [smtp/smtp_user] not found in config
[2024-01-18T09:57:11.989+0000] {email.py:270} INFO - Email alerting: attempt 1
[2024-01-18T09:57:11.989+0000] {taskinstance.py:826} ERROR - Failed to send email to: anh.ho@tititada.com
Traceback (most recent call last):
  File "/home/airflow/.local/lib/python3.8/site-packages/airflow/models/taskinstance.py", line 2335, in _run_raw_task
    self._execute_task_with_callbacks(context, test_mode, session=session)
  File "/home/airflow/.local/lib/python3.8/site-packages/airflow/models/taskinstance.py", line 2500, in _execute_task_with_callbacks
    result = self._execute_task(context, task_orig)
  File "/home/airflow/.local/lib/python3.8/site-packages/airflow/models/taskinstance.py", line 2517, in _execute_task
    return _execute_task(self, context, task_orig)
  File "/home/airflow/.local/lib/python3.8/site-packages/airflow/models/taskinstance.py", line 433, in _execute_task
    result = execute_callable(context=context, **execute_callable_kwargs)
  File "/home/airflow/.local/lib/python3.8/site-packages/airflow/operators/python.py", line 233, in execute
    return self.do_branch(context, super().execute(context))
  File "/home/airflow/.local/lib/python3.8/site-packages/airflow/operators/python.py", line 199, in execute
    return_value = self.execute_callable()
  File "/home/airflow/.local/lib/python3.8/site-packages/airflow/operators/python.py", line 216, in execute_callable
    return self.python_callable(*self.op_args, **self.op_kwargs)
  File "/opt/airflow/dags/CrawlCompanyInfo.py", line 55, in CheckTableExisting
    cursor = ConnectPostgres().cursor()
  File "/opt/airflow/dags/CrawlCompanyInfo.py", line 27, in ConnectPostgres
    params = ReadConfigFile(relative_path,section)
  File "/opt/airflow/dags/GetAuthInfoFuncton.py", line 25, in ReadConfigFile
    raise Exception('Section {0} not found in the {1} file'.format(section, text_file_path))
Exception: Section Postgresql not found in the /Users/anhho/Desktop/DataEngineer/CrawlStockData/CrawlFunction/Authorization.ini file

During handling of the above exception, another exception occurred:

Traceback (most recent call last):
  File "/home/airflow/.local/lib/python3.8/site-packages/airflow/models/taskinstance.py", line 1000, in _email_alert
    send_email(task.email, subject, html_content)
  File "/home/airflow/.local/lib/python3.8/site-packages/airflow/utils/email.py", line 80, in send_email
    return backend(
  File "/home/airflow/.local/lib/python3.8/site-packages/airflow/utils/email.py", line 154, in send_email_smtp
    send_mime_email(e_from=mail_from, e_to=recipients, mime_msg=msg, conn_id=conn_id, dryrun=dryrun)
  File "/home/airflow/.local/lib/python3.8/site-packages/airflow/utils/email.py", line 272, in send_mime_email
    smtp_conn = _get_smtp_connection(smtp_host, smtp_port, smtp_timeout, smtp_ssl)
  File "/home/airflow/.local/lib/python3.8/site-packages/airflow/utils/email.py", line 316, in _get_smtp_connection
    return smtplib.SMTP(host=host, port=port, timeout=timeout)
  File "/usr/local/lib/python3.8/smtplib.py", line 255, in __init__
    (code, msg) = self.connect(host, port)
  File "/usr/local/lib/python3.8/smtplib.py", line 339, in connect
    self.sock = self._get_socket(host, port, self.timeout)
  File "/usr/local/lib/python3.8/smtplib.py", line 310, in _get_socket
    return socket.create_connection((host, port), timeout,
  File "/usr/local/lib/python3.8/socket.py", line 808, in create_connection
    raise err
  File "/usr/local/lib/python3.8/socket.py", line 796, in create_connection
    sock.connect(sa)
OSError: [Errno 99] Cannot assign requested address

During handling of the above exception, another exception occurred:

Traceback (most recent call last):
  File "/home/airflow/.local/lib/python3.8/site-packages/airflow/models/taskinstance.py", line 824, in _handle_failure
    task_instance.email_alert(error, failure_context["task"])
  File "/home/airflow/.local/lib/python3.8/site-packages/airflow/models/taskinstance.py", line 2947, in email_alert
    _email_alert(task_instance=self, exception=exception, task=task)
  File "/home/airflow/.local/lib/python3.8/site-packages/airflow/models/taskinstance.py", line 1002, in _email_alert
    send_email(task.email, subject, html_content_err)
  File "/home/airflow/.local/lib/python3.8/site-packages/airflow/utils/email.py", line 80, in send_email
    return backend(
  File "/home/airflow/.local/lib/python3.8/site-packages/airflow/utils/email.py", line 154, in send_email_smtp
    send_mime_email(e_from=mail_from, e_to=recipients, mime_msg=msg, conn_id=conn_id, dryrun=dryrun)
  File "/home/airflow/.local/lib/python3.8/site-packages/airflow/utils/email.py", line 272, in send_mime_email
    smtp_conn = _get_smtp_connection(smtp_host, smtp_port, smtp_timeout, smtp_ssl)
  File "/home/airflow/.local/lib/python3.8/site-packages/airflow/utils/email.py", line 316, in _get_smtp_connection
    return smtplib.SMTP(host=host, port=port, timeout=timeout)
  File "/usr/local/lib/python3.8/smtplib.py", line 255, in __init__
    (code, msg) = self.connect(host, port)
  File "/usr/local/lib/python3.8/smtplib.py", line 339, in connect
    self.sock = self._get_socket(host, port, self.timeout)
  File "/usr/local/lib/python3.8/smtplib.py", line 310, in _get_socket
    return socket.create_connection((host, port), timeout,
  File "/usr/local/lib/python3.8/socket.py", line 808, in create_connection
    raise err
  File "/usr/local/lib/python3.8/socket.py", line 796, in create_connection
    sock.connect(sa)
OSError: [Errno 99] Cannot assign requested address
[2024-01-18T09:57:11.997+0000] {standard_task_runner.py:107} ERROR - Failed to execute job 28 for task CheckTableExisting (Section Postgresql not found in the /Users/anhho/Desktop/DataEngineer/CrawlStockData/CrawlFunction/Authorization.ini file; 102)
[2024-01-18T09:57:12.016+0000] {local_task_job_runner.py:234} INFO - Task exited with return code 1
[2024-01-18T09:57:12.035+0000] {taskinstance.py:3281} INFO - 0 downstream tasks scheduled from follow-on schedule check
[2024-01-18T10:00:59.427+0000] {taskinstance.py:1957} INFO - Dependencies all met for dep_context=non-requeueable deps ti=<TaskInstance: company_profile_pipeline.CheckTableExisting scheduled__2024-01-11T00:00:00+00:00 [queued]>
[2024-01-18T10:00:59.432+0000] {taskinstance.py:1957} INFO - Dependencies all met for dep_context=requeueable deps ti=<TaskInstance: company_profile_pipeline.CheckTableExisting scheduled__2024-01-11T00:00:00+00:00 [queued]>
[2024-01-18T10:00:59.432+0000] {taskinstance.py:2171} INFO - Starting attempt 1 of 1
[2024-01-18T10:00:59.438+0000] {taskinstance.py:2192} INFO - Executing <Task(BranchPythonOperator): CheckTableExisting> on 2024-01-11 00:00:00+00:00
[2024-01-18T10:00:59.441+0000] {standard_task_runner.py:60} INFO - Started process 193 to run task
[2024-01-18T10:00:59.443+0000] {standard_task_runner.py:87} INFO - Running: ['***', 'tasks', 'run', 'company_profile_pipeline', 'CheckTableExisting', 'scheduled__2024-01-11T00:00:00+00:00', '--job-id', '46', '--raw', '--subdir', 'DAGS_FOLDER/CrawlCompanyInfo.py', '--cfg-path', '/tmp/tmpz62ud58p']
[2024-01-18T10:00:59.444+0000] {standard_task_runner.py:88} INFO - Job 46: Subtask CheckTableExisting
[2024-01-18T10:00:59.477+0000] {task_command.py:423} INFO - Running <TaskInstance: company_profile_pipeline.CheckTableExisting scheduled__2024-01-11T00:00:00+00:00 [running]> on host a56b2d2a6d76
[2024-01-18T10:00:59.524+0000] {taskinstance.py:2481} INFO - Exporting env vars: AIRFLOW_CTX_DAG_EMAIL='anh.ho@tititada.com' AIRFLOW_CTX_DAG_OWNER='anh.ho' AIRFLOW_CTX_DAG_ID='company_profile_pipeline' AIRFLOW_CTX_TASK_ID='CheckTableExisting' AIRFLOW_CTX_EXECUTION_DATE='2024-01-11T00:00:00+00:00' AIRFLOW_CTX_TRY_NUMBER='1' AIRFLOW_CTX_DAG_RUN_ID='scheduled__2024-01-11T00:00:00+00:00'
[2024-01-18T10:00:59.526+0000] {taskinstance.py:2699} ERROR - Task failed with exception
Traceback (most recent call last):
  File "/home/airflow/.local/lib/python3.8/site-packages/airflow/models/taskinstance.py", line 433, in _execute_task
    result = execute_callable(context=context, **execute_callable_kwargs)
  File "/home/airflow/.local/lib/python3.8/site-packages/airflow/operators/python.py", line 233, in execute
    return self.do_branch(context, super().execute(context))
  File "/home/airflow/.local/lib/python3.8/site-packages/airflow/operators/python.py", line 199, in execute
    return_value = self.execute_callable()
  File "/home/airflow/.local/lib/python3.8/site-packages/airflow/operators/python.py", line 216, in execute_callable
    return self.python_callable(*self.op_args, **self.op_kwargs)
  File "/opt/airflow/dags/CrawlCompanyInfo.py", line 55, in CheckTableExisting
    cursor = ConnectPostgres().cursor()
  File "/opt/airflow/dags/CrawlCompanyInfo.py", line 27, in ConnectPostgres
    params = ReadConfigFile(relative_path,section)
  File "/opt/airflow/dags/GetAuthInfoFuncton.py", line 25, in ReadConfigFile
    raise Exception('Section {section} not found in the {text_file_path} file'.format(section=section, text_file_path=text_file_path))
Exception: Section Postgresql not found in the /Users/anhho/Desktop/DataEngineer/CrawlStockData/ApacheAirflow/Authorization.ini file
[2024-01-18T10:00:59.532+0000] {taskinstance.py:1138} INFO - Marking task as FAILED. dag_id=company_profile_pipeline, task_id=CheckTableExisting, execution_date=20240111T000000, start_date=20240118T100059, end_date=20240118T100059
[2024-01-18T10:00:59.540+0000] {warnings.py:109} WARNING - /home/***/.local/lib/python3.8/site-packages/***/utils/email.py:154: RemovedInAirflow3Warning: Fetching SMTP credentials from configuration variables will be deprecated in a future release. Please set credentials using a connection instead.
  send_mime_email(e_from=mail_from, e_to=recipients, mime_msg=msg, conn_id=conn_id, dryrun=dryrun)

[2024-01-18T10:00:59.541+0000] {configuration.py:1046} WARNING - section/key [smtp/smtp_user] not found in config
[2024-01-18T10:00:59.541+0000] {email.py:270} INFO - Email alerting: attempt 1
[2024-01-18T10:00:59.554+0000] {configuration.py:1046} WARNING - section/key [smtp/smtp_user] not found in config
[2024-01-18T10:00:59.555+0000] {email.py:270} INFO - Email alerting: attempt 1
[2024-01-18T10:00:59.556+0000] {taskinstance.py:826} ERROR - Failed to send email to: anh.ho@tititada.com
Traceback (most recent call last):
  File "/home/airflow/.local/lib/python3.8/site-packages/airflow/models/taskinstance.py", line 2335, in _run_raw_task
    self._execute_task_with_callbacks(context, test_mode, session=session)
  File "/home/airflow/.local/lib/python3.8/site-packages/airflow/models/taskinstance.py", line 2500, in _execute_task_with_callbacks
    result = self._execute_task(context, task_orig)
  File "/home/airflow/.local/lib/python3.8/site-packages/airflow/models/taskinstance.py", line 2517, in _execute_task
    return _execute_task(self, context, task_orig)
  File "/home/airflow/.local/lib/python3.8/site-packages/airflow/models/taskinstance.py", line 433, in _execute_task
    result = execute_callable(context=context, **execute_callable_kwargs)
  File "/home/airflow/.local/lib/python3.8/site-packages/airflow/operators/python.py", line 233, in execute
    return self.do_branch(context, super().execute(context))
  File "/home/airflow/.local/lib/python3.8/site-packages/airflow/operators/python.py", line 199, in execute
    return_value = self.execute_callable()
  File "/home/airflow/.local/lib/python3.8/site-packages/airflow/operators/python.py", line 216, in execute_callable
    return self.python_callable(*self.op_args, **self.op_kwargs)
  File "/opt/airflow/dags/CrawlCompanyInfo.py", line 55, in CheckTableExisting
    cursor = ConnectPostgres().cursor()
  File "/opt/airflow/dags/CrawlCompanyInfo.py", line 27, in ConnectPostgres
    params = ReadConfigFile(relative_path,section)
  File "/opt/airflow/dags/GetAuthInfoFuncton.py", line 25, in ReadConfigFile
    raise Exception('Section {section} not found in the {text_file_path} file'.format(section=section, text_file_path=text_file_path))
Exception: Section Postgresql not found in the /Users/anhho/Desktop/DataEngineer/CrawlStockData/ApacheAirflow/Authorization.ini file

During handling of the above exception, another exception occurred:

Traceback (most recent call last):
  File "/home/airflow/.local/lib/python3.8/site-packages/airflow/models/taskinstance.py", line 1000, in _email_alert
    send_email(task.email, subject, html_content)
  File "/home/airflow/.local/lib/python3.8/site-packages/airflow/utils/email.py", line 80, in send_email
    return backend(
  File "/home/airflow/.local/lib/python3.8/site-packages/airflow/utils/email.py", line 154, in send_email_smtp
    send_mime_email(e_from=mail_from, e_to=recipients, mime_msg=msg, conn_id=conn_id, dryrun=dryrun)
  File "/home/airflow/.local/lib/python3.8/site-packages/airflow/utils/email.py", line 272, in send_mime_email
    smtp_conn = _get_smtp_connection(smtp_host, smtp_port, smtp_timeout, smtp_ssl)
  File "/home/airflow/.local/lib/python3.8/site-packages/airflow/utils/email.py", line 316, in _get_smtp_connection
    return smtplib.SMTP(host=host, port=port, timeout=timeout)
  File "/usr/local/lib/python3.8/smtplib.py", line 255, in __init__
    (code, msg) = self.connect(host, port)
  File "/usr/local/lib/python3.8/smtplib.py", line 339, in connect
    self.sock = self._get_socket(host, port, self.timeout)
  File "/usr/local/lib/python3.8/smtplib.py", line 310, in _get_socket
    return socket.create_connection((host, port), timeout,
  File "/usr/local/lib/python3.8/socket.py", line 808, in create_connection
    raise err
  File "/usr/local/lib/python3.8/socket.py", line 796, in create_connection
    sock.connect(sa)
OSError: [Errno 99] Cannot assign requested address

During handling of the above exception, another exception occurred:

Traceback (most recent call last):
  File "/home/airflow/.local/lib/python3.8/site-packages/airflow/models/taskinstance.py", line 824, in _handle_failure
    task_instance.email_alert(error, failure_context["task"])
  File "/home/airflow/.local/lib/python3.8/site-packages/airflow/models/taskinstance.py", line 2947, in email_alert
    _email_alert(task_instance=self, exception=exception, task=task)
  File "/home/airflow/.local/lib/python3.8/site-packages/airflow/models/taskinstance.py", line 1002, in _email_alert
    send_email(task.email, subject, html_content_err)
  File "/home/airflow/.local/lib/python3.8/site-packages/airflow/utils/email.py", line 80, in send_email
    return backend(
  File "/home/airflow/.local/lib/python3.8/site-packages/airflow/utils/email.py", line 154, in send_email_smtp
    send_mime_email(e_from=mail_from, e_to=recipients, mime_msg=msg, conn_id=conn_id, dryrun=dryrun)
  File "/home/airflow/.local/lib/python3.8/site-packages/airflow/utils/email.py", line 272, in send_mime_email
    smtp_conn = _get_smtp_connection(smtp_host, smtp_port, smtp_timeout, smtp_ssl)
  File "/home/airflow/.local/lib/python3.8/site-packages/airflow/utils/email.py", line 316, in _get_smtp_connection
    return smtplib.SMTP(host=host, port=port, timeout=timeout)
  File "/usr/local/lib/python3.8/smtplib.py", line 255, in __init__
    (code, msg) = self.connect(host, port)
  File "/usr/local/lib/python3.8/smtplib.py", line 339, in connect
    self.sock = self._get_socket(host, port, self.timeout)
  File "/usr/local/lib/python3.8/smtplib.py", line 310, in _get_socket
    return socket.create_connection((host, port), timeout,
  File "/usr/local/lib/python3.8/socket.py", line 808, in create_connection
    raise err
  File "/usr/local/lib/python3.8/socket.py", line 796, in create_connection
    sock.connect(sa)
OSError: [Errno 99] Cannot assign requested address
[2024-01-18T10:00:59.566+0000] {standard_task_runner.py:107} ERROR - Failed to execute job 46 for task CheckTableExisting (Section Postgresql not found in the /Users/anhho/Desktop/DataEngineer/CrawlStockData/ApacheAirflow/Authorization.ini file; 193)
[2024-01-18T10:00:59.579+0000] {local_task_job_runner.py:234} INFO - Task exited with return code 1
[2024-01-18T10:00:59.604+0000] {taskinstance.py:3281} INFO - 0 downstream tasks scheduled from follow-on schedule check
[2024-01-19T02:23:45.068+0000] {taskinstance.py:1957} INFO - Dependencies all met for dep_context=non-requeueable deps ti=<TaskInstance: company_profile_pipeline.CheckTableExisting scheduled__2024-01-11T00:00:00+00:00 [queued]>
[2024-01-19T02:23:45.072+0000] {taskinstance.py:1957} INFO - Dependencies all met for dep_context=requeueable deps ti=<TaskInstance: company_profile_pipeline.CheckTableExisting scheduled__2024-01-11T00:00:00+00:00 [queued]>
[2024-01-19T02:23:45.073+0000] {taskinstance.py:2171} INFO - Starting attempt 1 of 1
[2024-01-19T02:23:45.123+0000] {taskinstance.py:2192} INFO - Executing <Task(BranchPythonOperator): CheckTableExisting> on 2024-01-11 00:00:00+00:00
[2024-01-19T02:23:45.128+0000] {standard_task_runner.py:60} INFO - Started process 130 to run task
[2024-01-19T02:23:45.132+0000] {standard_task_runner.py:87} INFO - Running: ['***', 'tasks', 'run', 'company_profile_pipeline', 'CheckTableExisting', 'scheduled__2024-01-11T00:00:00+00:00', '--job-id', '80', '--raw', '--subdir', 'DAGS_FOLDER/CrawlCompanyInfo.py', '--cfg-path', '/tmp/tmpnodqf2fg']
[2024-01-19T02:23:45.134+0000] {standard_task_runner.py:88} INFO - Job 80: Subtask CheckTableExisting
[2024-01-19T02:23:45.180+0000] {task_command.py:423} INFO - Running <TaskInstance: company_profile_pipeline.CheckTableExisting scheduled__2024-01-11T00:00:00+00:00 [running]> on host a56b2d2a6d76
[2024-01-19T02:23:45.250+0000] {taskinstance.py:2481} INFO - Exporting env vars: AIRFLOW_CTX_DAG_EMAIL='anh.ho@tititada.com' AIRFLOW_CTX_DAG_OWNER='anh.ho' AIRFLOW_CTX_DAG_ID='company_profile_pipeline' AIRFLOW_CTX_TASK_ID='CheckTableExisting' AIRFLOW_CTX_EXECUTION_DATE='2024-01-11T00:00:00+00:00' AIRFLOW_CTX_TRY_NUMBER='1' AIRFLOW_CTX_DAG_RUN_ID='scheduled__2024-01-11T00:00:00+00:00'
[2024-01-19T02:23:45.251+0000] {logging_mixin.py:188} INFO - Connecting to the PostgreSQL database...
[2024-01-19T02:25:56.791+0000] {taskinstance.py:2699} ERROR - Task failed with exception
Traceback (most recent call last):
  File "/home/airflow/.local/lib/python3.8/site-packages/airflow/models/taskinstance.py", line 433, in _execute_task
    result = execute_callable(context=context, **execute_callable_kwargs)
  File "/home/airflow/.local/lib/python3.8/site-packages/airflow/operators/python.py", line 233, in execute
    return self.do_branch(context, super().execute(context))
  File "/home/airflow/.local/lib/python3.8/site-packages/airflow/operators/python.py", line 199, in execute
    return_value = self.execute_callable()
  File "/home/airflow/.local/lib/python3.8/site-packages/airflow/operators/python.py", line 216, in execute_callable
    return self.python_callable(*self.op_args, **self.op_kwargs)
  File "/opt/airflow/dags/CrawlCompanyInfo.py", line 50, in CheckTableExisting
    cursor = ConnectPostgres().cursor()
  File "/opt/airflow/dags/CrawlCompanyInfo.py", line 41, in ConnectPostgres
    raise e
  File "/opt/airflow/dags/CrawlCompanyInfo.py", line 26, in ConnectPostgres
    conn = psycopg2.connect(**params)
  File "/home/airflow/.local/lib/python3.8/site-packages/psycopg2/__init__.py", line 122, in connect
    conn = _connect(dsn, connection_factory=connection_factory, **kwasync)
psycopg2.OperationalError: connection to server at "172.17.0.2", port 5432 failed: Connection timed out
	Is the server running on that host and accepting TCP/IP connections?

[2024-01-19T02:25:56.846+0000] {taskinstance.py:1138} INFO - Marking task as FAILED. dag_id=company_profile_pipeline, task_id=CheckTableExisting, execution_date=20240111T000000, start_date=20240119T022345, end_date=20240119T022556
[2024-01-19T02:25:56.887+0000] {warnings.py:109} WARNING - /home/***/.local/lib/python3.8/site-packages/***/utils/email.py:154: RemovedInAirflow3Warning: Fetching SMTP credentials from configuration variables will be deprecated in a future release. Please set credentials using a connection instead.
  send_mime_email(e_from=mail_from, e_to=recipients, mime_msg=msg, conn_id=conn_id, dryrun=dryrun)

[2024-01-19T02:25:56.889+0000] {configuration.py:1046} WARNING - section/key [smtp/smtp_user] not found in config
[2024-01-19T02:25:56.890+0000] {email.py:270} INFO - Email alerting: attempt 1
[2024-01-19T02:25:56.899+0000] {configuration.py:1046} WARNING - section/key [smtp/smtp_user] not found in config
[2024-01-19T02:25:56.901+0000] {email.py:270} INFO - Email alerting: attempt 1
[2024-01-19T02:25:56.902+0000] {taskinstance.py:826} ERROR - Failed to send email to: anh.ho@tititada.com
Traceback (most recent call last):
  File "/home/airflow/.local/lib/python3.8/site-packages/airflow/models/taskinstance.py", line 2335, in _run_raw_task
    self._execute_task_with_callbacks(context, test_mode, session=session)
  File "/home/airflow/.local/lib/python3.8/site-packages/airflow/models/taskinstance.py", line 2500, in _execute_task_with_callbacks
    result = self._execute_task(context, task_orig)
  File "/home/airflow/.local/lib/python3.8/site-packages/airflow/models/taskinstance.py", line 2517, in _execute_task
    return _execute_task(self, context, task_orig)
  File "/home/airflow/.local/lib/python3.8/site-packages/airflow/models/taskinstance.py", line 433, in _execute_task
    result = execute_callable(context=context, **execute_callable_kwargs)
  File "/home/airflow/.local/lib/python3.8/site-packages/airflow/operators/python.py", line 233, in execute
    return self.do_branch(context, super().execute(context))
  File "/home/airflow/.local/lib/python3.8/site-packages/airflow/operators/python.py", line 199, in execute
    return_value = self.execute_callable()
  File "/home/airflow/.local/lib/python3.8/site-packages/airflow/operators/python.py", line 216, in execute_callable
    return self.python_callable(*self.op_args, **self.op_kwargs)
  File "/opt/airflow/dags/CrawlCompanyInfo.py", line 50, in CheckTableExisting
    cursor = ConnectPostgres().cursor()
  File "/opt/airflow/dags/CrawlCompanyInfo.py", line 41, in ConnectPostgres
    raise e
  File "/opt/airflow/dags/CrawlCompanyInfo.py", line 26, in ConnectPostgres
    conn = psycopg2.connect(**params)
  File "/home/airflow/.local/lib/python3.8/site-packages/psycopg2/__init__.py", line 122, in connect
    conn = _connect(dsn, connection_factory=connection_factory, **kwasync)
psycopg2.OperationalError: connection to server at "172.17.0.2", port 5432 failed: Connection timed out
	Is the server running on that host and accepting TCP/IP connections?


During handling of the above exception, another exception occurred:

Traceback (most recent call last):
  File "/home/airflow/.local/lib/python3.8/site-packages/airflow/models/taskinstance.py", line 1000, in _email_alert
    send_email(task.email, subject, html_content)
  File "/home/airflow/.local/lib/python3.8/site-packages/airflow/utils/email.py", line 80, in send_email
    return backend(
  File "/home/airflow/.local/lib/python3.8/site-packages/airflow/utils/email.py", line 154, in send_email_smtp
    send_mime_email(e_from=mail_from, e_to=recipients, mime_msg=msg, conn_id=conn_id, dryrun=dryrun)
  File "/home/airflow/.local/lib/python3.8/site-packages/airflow/utils/email.py", line 272, in send_mime_email
    smtp_conn = _get_smtp_connection(smtp_host, smtp_port, smtp_timeout, smtp_ssl)
  File "/home/airflow/.local/lib/python3.8/site-packages/airflow/utils/email.py", line 316, in _get_smtp_connection
    return smtplib.SMTP(host=host, port=port, timeout=timeout)
  File "/usr/local/lib/python3.8/smtplib.py", line 255, in __init__
    (code, msg) = self.connect(host, port)
  File "/usr/local/lib/python3.8/smtplib.py", line 339, in connect
    self.sock = self._get_socket(host, port, self.timeout)
  File "/usr/local/lib/python3.8/smtplib.py", line 310, in _get_socket
    return socket.create_connection((host, port), timeout,
  File "/usr/local/lib/python3.8/socket.py", line 808, in create_connection
    raise err
  File "/usr/local/lib/python3.8/socket.py", line 796, in create_connection
    sock.connect(sa)
OSError: [Errno 99] Cannot assign requested address

During handling of the above exception, another exception occurred:

Traceback (most recent call last):
  File "/home/airflow/.local/lib/python3.8/site-packages/airflow/models/taskinstance.py", line 824, in _handle_failure
    task_instance.email_alert(error, failure_context["task"])
  File "/home/airflow/.local/lib/python3.8/site-packages/airflow/models/taskinstance.py", line 2947, in email_alert
    _email_alert(task_instance=self, exception=exception, task=task)
  File "/home/airflow/.local/lib/python3.8/site-packages/airflow/models/taskinstance.py", line 1002, in _email_alert
    send_email(task.email, subject, html_content_err)
  File "/home/airflow/.local/lib/python3.8/site-packages/airflow/utils/email.py", line 80, in send_email
    return backend(
  File "/home/airflow/.local/lib/python3.8/site-packages/airflow/utils/email.py", line 154, in send_email_smtp
    send_mime_email(e_from=mail_from, e_to=recipients, mime_msg=msg, conn_id=conn_id, dryrun=dryrun)
  File "/home/airflow/.local/lib/python3.8/site-packages/airflow/utils/email.py", line 272, in send_mime_email
    smtp_conn = _get_smtp_connection(smtp_host, smtp_port, smtp_timeout, smtp_ssl)
  File "/home/airflow/.local/lib/python3.8/site-packages/airflow/utils/email.py", line 316, in _get_smtp_connection
    return smtplib.SMTP(host=host, port=port, timeout=timeout)
  File "/usr/local/lib/python3.8/smtplib.py", line 255, in __init__
    (code, msg) = self.connect(host, port)
  File "/usr/local/lib/python3.8/smtplib.py", line 339, in connect
    self.sock = self._get_socket(host, port, self.timeout)
  File "/usr/local/lib/python3.8/smtplib.py", line 310, in _get_socket
    return socket.create_connection((host, port), timeout,
  File "/usr/local/lib/python3.8/socket.py", line 808, in create_connection
    raise err
  File "/usr/local/lib/python3.8/socket.py", line 796, in create_connection
    sock.connect(sa)
OSError: [Errno 99] Cannot assign requested address
[2024-01-19T02:25:56.922+0000] {standard_task_runner.py:107} ERROR - Failed to execute job 80 for task CheckTableExisting (connection to server at "172.17.0.2", port 5432 failed: Connection timed out
	Is the server running on that host and accepting TCP/IP connections?
; 130)
[2024-01-19T02:25:56.965+0000] {local_task_job_runner.py:234} INFO - Task exited with return code 1
[2024-01-19T02:25:57.025+0000] {taskinstance.py:3281} INFO - 0 downstream tasks scheduled from follow-on schedule check
[2024-01-19T02:30:18.943+0000] {taskinstance.py:1957} INFO - Dependencies all met for dep_context=non-requeueable deps ti=<TaskInstance: company_profile_pipeline.CheckTableExisting scheduled__2024-01-11T00:00:00+00:00 [queued]>
[2024-01-19T02:30:18.948+0000] {taskinstance.py:1957} INFO - Dependencies all met for dep_context=requeueable deps ti=<TaskInstance: company_profile_pipeline.CheckTableExisting scheduled__2024-01-11T00:00:00+00:00 [queued]>
[2024-01-19T02:30:18.949+0000] {taskinstance.py:2171} INFO - Starting attempt 1 of 1
[2024-01-19T02:30:18.961+0000] {taskinstance.py:2192} INFO - Executing <Task(BranchPythonOperator): CheckTableExisting> on 2024-01-11 00:00:00+00:00
[2024-01-19T02:30:18.968+0000] {standard_task_runner.py:60} INFO - Started process 272 to run task
[2024-01-19T02:30:18.982+0000] {standard_task_runner.py:87} INFO - Running: ['***', 'tasks', 'run', 'company_profile_pipeline', 'CheckTableExisting', 'scheduled__2024-01-11T00:00:00+00:00', '--job-id', '99', '--raw', '--subdir', 'DAGS_FOLDER/CrawlCompanyInfo.py', '--cfg-path', '/tmp/tmpferbb14e']
[2024-01-19T02:30:18.985+0000] {standard_task_runner.py:88} INFO - Job 99: Subtask CheckTableExisting
[2024-01-19T02:30:19.036+0000] {task_command.py:423} INFO - Running <TaskInstance: company_profile_pipeline.CheckTableExisting scheduled__2024-01-11T00:00:00+00:00 [running]> on host a56b2d2a6d76
[2024-01-19T02:30:19.114+0000] {taskinstance.py:2481} INFO - Exporting env vars: AIRFLOW_CTX_DAG_EMAIL='anh.ho@tititada.com' AIRFLOW_CTX_DAG_OWNER='anh.ho' AIRFLOW_CTX_DAG_ID='company_profile_pipeline' AIRFLOW_CTX_TASK_ID='CheckTableExisting' AIRFLOW_CTX_EXECUTION_DATE='2024-01-11T00:00:00+00:00' AIRFLOW_CTX_TRY_NUMBER='1' AIRFLOW_CTX_DAG_RUN_ID='scheduled__2024-01-11T00:00:00+00:00'
[2024-01-19T02:30:19.117+0000] {logging_mixin.py:188} INFO - Connecting to the PostgreSQL database...
[2024-01-19T03:14:25.724+0000] {taskinstance.py:1957} INFO - Dependencies all met for dep_context=non-requeueable deps ti=<TaskInstance: company_profile_pipeline.CheckTableExisting scheduled__2024-01-11T00:00:00+00:00 [queued]>
[2024-01-19T03:14:25.730+0000] {taskinstance.py:1957} INFO - Dependencies all met for dep_context=requeueable deps ti=<TaskInstance: company_profile_pipeline.CheckTableExisting scheduled__2024-01-11T00:00:00+00:00 [queued]>
[2024-01-19T03:14:25.731+0000] {taskinstance.py:2171} INFO - Starting attempt 1 of 1
[2024-01-19T03:14:25.737+0000] {taskinstance.py:2192} INFO - Executing <Task(BranchPythonOperator): CheckTableExisting> on 2024-01-11 00:00:00+00:00
[2024-01-19T03:14:25.741+0000] {standard_task_runner.py:60} INFO - Started process 147 to run task
[2024-01-19T03:14:25.745+0000] {standard_task_runner.py:87} INFO - Running: ['***', 'tasks', 'run', 'company_profile_pipeline', 'CheckTableExisting', 'scheduled__2024-01-11T00:00:00+00:00', '--job-id', '143', '--raw', '--subdir', 'DAGS_FOLDER/CrawlCompanyInfo.py', '--cfg-path', '/tmp/tmp6674a1jl']
[2024-01-19T03:14:25.746+0000] {standard_task_runner.py:88} INFO - Job 143: Subtask CheckTableExisting
[2024-01-19T03:14:25.779+0000] {task_command.py:423} INFO - Running <TaskInstance: company_profile_pipeline.CheckTableExisting scheduled__2024-01-11T00:00:00+00:00 [running]> on host a56b2d2a6d76
[2024-01-19T03:14:25.836+0000] {taskinstance.py:2481} INFO - Exporting env vars: AIRFLOW_CTX_DAG_EMAIL='anh.ho@tititada.com' AIRFLOW_CTX_DAG_OWNER='anh.ho' AIRFLOW_CTX_DAG_ID='company_profile_pipeline' AIRFLOW_CTX_TASK_ID='CheckTableExisting' AIRFLOW_CTX_EXECUTION_DATE='2024-01-11T00:00:00+00:00' AIRFLOW_CTX_TRY_NUMBER='1' AIRFLOW_CTX_DAG_RUN_ID='scheduled__2024-01-11T00:00:00+00:00'
[2024-01-19T03:14:25.839+0000] {logging_mixin.py:188} INFO - Connecting to the PostgreSQL database...
[2024-01-19T03:14:25.841+0000] {taskinstance.py:2699} ERROR - Task failed with exception
Traceback (most recent call last):
  File "/home/airflow/.local/lib/python3.8/site-packages/airflow/models/taskinstance.py", line 433, in _execute_task
    result = execute_callable(context=context, **execute_callable_kwargs)
  File "/home/airflow/.local/lib/python3.8/site-packages/airflow/operators/python.py", line 233, in execute
    return self.do_branch(context, super().execute(context))
  File "/home/airflow/.local/lib/python3.8/site-packages/airflow/operators/python.py", line 199, in execute
    return_value = self.execute_callable()
  File "/home/airflow/.local/lib/python3.8/site-packages/airflow/operators/python.py", line 216, in execute_callable
    return self.python_callable(*self.op_args, **self.op_kwargs)
  File "/opt/airflow/dags/CrawlCompanyInfo.py", line 50, in CheckTableExisting
    cursor = ConnectPostgres().cursor()
  File "/opt/airflow/dags/CrawlCompanyInfo.py", line 41, in ConnectPostgres
    raise e
  File "/opt/airflow/dags/CrawlCompanyInfo.py", line 26, in ConnectPostgres
    conn = psycopg2.connect(**params)
  File "/home/airflow/.local/lib/python3.8/site-packages/psycopg2/__init__.py", line 122, in connect
    conn = _connect(dsn, connection_factory=connection_factory, **kwasync)
psycopg2.OperationalError: connection to server at "0.0.0.0", port 5432 failed: Connection refused
	Is the server running on that host and accepting TCP/IP connections?

[2024-01-19T03:14:25.851+0000] {taskinstance.py:1138} INFO - Marking task as FAILED. dag_id=company_profile_pipeline, task_id=CheckTableExisting, execution_date=20240111T000000, start_date=20240119T031425, end_date=20240119T031425
[2024-01-19T03:14:25.859+0000] {warnings.py:109} WARNING - /home/***/.local/lib/python3.8/site-packages/***/utils/email.py:154: RemovedInAirflow3Warning: Fetching SMTP credentials from configuration variables will be deprecated in a future release. Please set credentials using a connection instead.
  send_mime_email(e_from=mail_from, e_to=recipients, mime_msg=msg, conn_id=conn_id, dryrun=dryrun)

[2024-01-19T03:14:25.863+0000] {configuration.py:1046} WARNING - section/key [smtp/smtp_user] not found in config
[2024-01-19T03:14:25.868+0000] {email.py:270} INFO - Email alerting: attempt 1
[2024-01-19T03:14:25.874+0000] {configuration.py:1046} WARNING - section/key [smtp/smtp_user] not found in config
[2024-01-19T03:14:25.874+0000] {email.py:270} INFO - Email alerting: attempt 1
[2024-01-19T03:14:25.875+0000] {taskinstance.py:826} ERROR - Failed to send email to: anh.ho@tititada.com
Traceback (most recent call last):
  File "/home/airflow/.local/lib/python3.8/site-packages/airflow/models/taskinstance.py", line 2335, in _run_raw_task
    self._execute_task_with_callbacks(context, test_mode, session=session)
  File "/home/airflow/.local/lib/python3.8/site-packages/airflow/models/taskinstance.py", line 2500, in _execute_task_with_callbacks
    result = self._execute_task(context, task_orig)
  File "/home/airflow/.local/lib/python3.8/site-packages/airflow/models/taskinstance.py", line 2517, in _execute_task
    return _execute_task(self, context, task_orig)
  File "/home/airflow/.local/lib/python3.8/site-packages/airflow/models/taskinstance.py", line 433, in _execute_task
    result = execute_callable(context=context, **execute_callable_kwargs)
  File "/home/airflow/.local/lib/python3.8/site-packages/airflow/operators/python.py", line 233, in execute
    return self.do_branch(context, super().execute(context))
  File "/home/airflow/.local/lib/python3.8/site-packages/airflow/operators/python.py", line 199, in execute
    return_value = self.execute_callable()
  File "/home/airflow/.local/lib/python3.8/site-packages/airflow/operators/python.py", line 216, in execute_callable
    return self.python_callable(*self.op_args, **self.op_kwargs)
  File "/opt/airflow/dags/CrawlCompanyInfo.py", line 50, in CheckTableExisting
    cursor = ConnectPostgres().cursor()
  File "/opt/airflow/dags/CrawlCompanyInfo.py", line 41, in ConnectPostgres
    raise e
  File "/opt/airflow/dags/CrawlCompanyInfo.py", line 26, in ConnectPostgres
    conn = psycopg2.connect(**params)
  File "/home/airflow/.local/lib/python3.8/site-packages/psycopg2/__init__.py", line 122, in connect
    conn = _connect(dsn, connection_factory=connection_factory, **kwasync)
psycopg2.OperationalError: connection to server at "0.0.0.0", port 5432 failed: Connection refused
	Is the server running on that host and accepting TCP/IP connections?


During handling of the above exception, another exception occurred:

Traceback (most recent call last):
  File "/home/airflow/.local/lib/python3.8/site-packages/airflow/models/taskinstance.py", line 1000, in _email_alert
    send_email(task.email, subject, html_content)
  File "/home/airflow/.local/lib/python3.8/site-packages/airflow/utils/email.py", line 80, in send_email
    return backend(
  File "/home/airflow/.local/lib/python3.8/site-packages/airflow/utils/email.py", line 154, in send_email_smtp
    send_mime_email(e_from=mail_from, e_to=recipients, mime_msg=msg, conn_id=conn_id, dryrun=dryrun)
  File "/home/airflow/.local/lib/python3.8/site-packages/airflow/utils/email.py", line 272, in send_mime_email
    smtp_conn = _get_smtp_connection(smtp_host, smtp_port, smtp_timeout, smtp_ssl)
  File "/home/airflow/.local/lib/python3.8/site-packages/airflow/utils/email.py", line 316, in _get_smtp_connection
    return smtplib.SMTP(host=host, port=port, timeout=timeout)
  File "/usr/local/lib/python3.8/smtplib.py", line 255, in __init__
    (code, msg) = self.connect(host, port)
  File "/usr/local/lib/python3.8/smtplib.py", line 339, in connect
    self.sock = self._get_socket(host, port, self.timeout)
  File "/usr/local/lib/python3.8/smtplib.py", line 310, in _get_socket
    return socket.create_connection((host, port), timeout,
  File "/usr/local/lib/python3.8/socket.py", line 808, in create_connection
    raise err
  File "/usr/local/lib/python3.8/socket.py", line 796, in create_connection
    sock.connect(sa)
OSError: [Errno 99] Cannot assign requested address

During handling of the above exception, another exception occurred:

Traceback (most recent call last):
  File "/home/airflow/.local/lib/python3.8/site-packages/airflow/models/taskinstance.py", line 824, in _handle_failure
    task_instance.email_alert(error, failure_context["task"])
  File "/home/airflow/.local/lib/python3.8/site-packages/airflow/models/taskinstance.py", line 2947, in email_alert
    _email_alert(task_instance=self, exception=exception, task=task)
  File "/home/airflow/.local/lib/python3.8/site-packages/airflow/models/taskinstance.py", line 1002, in _email_alert
    send_email(task.email, subject, html_content_err)
  File "/home/airflow/.local/lib/python3.8/site-packages/airflow/utils/email.py", line 80, in send_email
    return backend(
  File "/home/airflow/.local/lib/python3.8/site-packages/airflow/utils/email.py", line 154, in send_email_smtp
    send_mime_email(e_from=mail_from, e_to=recipients, mime_msg=msg, conn_id=conn_id, dryrun=dryrun)
  File "/home/airflow/.local/lib/python3.8/site-packages/airflow/utils/email.py", line 272, in send_mime_email
    smtp_conn = _get_smtp_connection(smtp_host, smtp_port, smtp_timeout, smtp_ssl)
  File "/home/airflow/.local/lib/python3.8/site-packages/airflow/utils/email.py", line 316, in _get_smtp_connection
    return smtplib.SMTP(host=host, port=port, timeout=timeout)
  File "/usr/local/lib/python3.8/smtplib.py", line 255, in __init__
    (code, msg) = self.connect(host, port)
  File "/usr/local/lib/python3.8/smtplib.py", line 339, in connect
    self.sock = self._get_socket(host, port, self.timeout)
  File "/usr/local/lib/python3.8/smtplib.py", line 310, in _get_socket
    return socket.create_connection((host, port), timeout,
  File "/usr/local/lib/python3.8/socket.py", line 808, in create_connection
    raise err
  File "/usr/local/lib/python3.8/socket.py", line 796, in create_connection
    sock.connect(sa)
OSError: [Errno 99] Cannot assign requested address
[2024-01-19T03:14:25.888+0000] {standard_task_runner.py:107} ERROR - Failed to execute job 143 for task CheckTableExisting (connection to server at "0.0.0.0", port 5432 failed: Connection refused
	Is the server running on that host and accepting TCP/IP connections?
; 147)
[2024-01-19T03:14:25.916+0000] {local_task_job_runner.py:234} INFO - Task exited with return code 1
[2024-01-19T03:14:25.938+0000] {taskinstance.py:3281} INFO - 0 downstream tasks scheduled from follow-on schedule check
[2024-01-19T03:16:04.140+0000] {taskinstance.py:1957} INFO - Dependencies all met for dep_context=non-requeueable deps ti=<TaskInstance: company_profile_pipeline.CheckTableExisting scheduled__2024-01-11T00:00:00+00:00 [queued]>
[2024-01-19T03:16:04.145+0000] {taskinstance.py:1957} INFO - Dependencies all met for dep_context=requeueable deps ti=<TaskInstance: company_profile_pipeline.CheckTableExisting scheduled__2024-01-11T00:00:00+00:00 [queued]>
[2024-01-19T03:16:04.145+0000] {taskinstance.py:2171} INFO - Starting attempt 1 of 1
[2024-01-19T03:16:04.154+0000] {taskinstance.py:2192} INFO - Executing <Task(BranchPythonOperator): CheckTableExisting> on 2024-01-11 00:00:00+00:00
[2024-01-19T03:16:04.158+0000] {standard_task_runner.py:60} INFO - Started process 237 to run task
[2024-01-19T03:16:04.163+0000] {standard_task_runner.py:87} INFO - Running: ['***', 'tasks', 'run', 'company_profile_pipeline', 'CheckTableExisting', 'scheduled__2024-01-11T00:00:00+00:00', '--job-id', '178', '--raw', '--subdir', 'DAGS_FOLDER/CrawlCompanyInfo.py', '--cfg-path', '/tmp/tmp1m_sfbtb']
[2024-01-19T03:16:04.164+0000] {standard_task_runner.py:88} INFO - Job 178: Subtask CheckTableExisting
[2024-01-19T03:16:04.195+0000] {task_command.py:423} INFO - Running <TaskInstance: company_profile_pipeline.CheckTableExisting scheduled__2024-01-11T00:00:00+00:00 [running]> on host a56b2d2a6d76
[2024-01-19T03:16:04.234+0000] {taskinstance.py:2481} INFO - Exporting env vars: AIRFLOW_CTX_DAG_EMAIL='anh.ho@tititada.com' AIRFLOW_CTX_DAG_OWNER='anh.ho' AIRFLOW_CTX_DAG_ID='company_profile_pipeline' AIRFLOW_CTX_TASK_ID='CheckTableExisting' AIRFLOW_CTX_EXECUTION_DATE='2024-01-11T00:00:00+00:00' AIRFLOW_CTX_TRY_NUMBER='1' AIRFLOW_CTX_DAG_RUN_ID='scheduled__2024-01-11T00:00:00+00:00'
[2024-01-19T03:16:04.235+0000] {logging_mixin.py:188} INFO - Connecting to the PostgreSQL database...
[2024-01-19T03:16:04.235+0000] {taskinstance.py:2699} ERROR - Task failed with exception
Traceback (most recent call last):
  File "/home/airflow/.local/lib/python3.8/site-packages/airflow/models/taskinstance.py", line 433, in _execute_task
    result = execute_callable(context=context, **execute_callable_kwargs)
  File "/home/airflow/.local/lib/python3.8/site-packages/airflow/operators/python.py", line 233, in execute
    return self.do_branch(context, super().execute(context))
  File "/home/airflow/.local/lib/python3.8/site-packages/airflow/operators/python.py", line 199, in execute
    return_value = self.execute_callable()
  File "/home/airflow/.local/lib/python3.8/site-packages/airflow/operators/python.py", line 216, in execute_callable
    return self.python_callable(*self.op_args, **self.op_kwargs)
  File "/opt/airflow/dags/CrawlCompanyInfo.py", line 50, in CheckTableExisting
    cursor = ConnectPostgres().cursor()
  File "/opt/airflow/dags/CrawlCompanyInfo.py", line 41, in ConnectPostgres
    raise e
  File "/opt/airflow/dags/CrawlCompanyInfo.py", line 26, in ConnectPostgres
    conn = psycopg2.connect(**params)
  File "/home/airflow/.local/lib/python3.8/site-packages/psycopg2/__init__.py", line 122, in connect
    conn = _connect(dsn, connection_factory=connection_factory, **kwasync)
psycopg2.OperationalError: connection to server at "0.0.0.0", port 5432 failed: Connection refused
	Is the server running on that host and accepting TCP/IP connections?

[2024-01-19T03:16:04.241+0000] {taskinstance.py:1138} INFO - Marking task as FAILED. dag_id=company_profile_pipeline, task_id=CheckTableExisting, execution_date=20240111T000000, start_date=20240119T031604, end_date=20240119T031604
[2024-01-19T03:16:04.249+0000] {warnings.py:109} WARNING - /home/***/.local/lib/python3.8/site-packages/***/utils/email.py:154: RemovedInAirflow3Warning: Fetching SMTP credentials from configuration variables will be deprecated in a future release. Please set credentials using a connection instead.
  send_mime_email(e_from=mail_from, e_to=recipients, mime_msg=msg, conn_id=conn_id, dryrun=dryrun)

[2024-01-19T03:16:04.250+0000] {configuration.py:1046} WARNING - section/key [smtp/smtp_user] not found in config
[2024-01-19T03:16:04.251+0000] {email.py:270} INFO - Email alerting: attempt 1
[2024-01-19T03:16:04.258+0000] {configuration.py:1046} WARNING - section/key [smtp/smtp_user] not found in config
[2024-01-19T03:16:04.260+0000] {email.py:270} INFO - Email alerting: attempt 1
[2024-01-19T03:16:04.261+0000] {taskinstance.py:826} ERROR - Failed to send email to: anh.ho@tititada.com
Traceback (most recent call last):
  File "/home/airflow/.local/lib/python3.8/site-packages/airflow/models/taskinstance.py", line 2335, in _run_raw_task
    self._execute_task_with_callbacks(context, test_mode, session=session)
  File "/home/airflow/.local/lib/python3.8/site-packages/airflow/models/taskinstance.py", line 2500, in _execute_task_with_callbacks
    result = self._execute_task(context, task_orig)
  File "/home/airflow/.local/lib/python3.8/site-packages/airflow/models/taskinstance.py", line 2517, in _execute_task
    return _execute_task(self, context, task_orig)
  File "/home/airflow/.local/lib/python3.8/site-packages/airflow/models/taskinstance.py", line 433, in _execute_task
    result = execute_callable(context=context, **execute_callable_kwargs)
  File "/home/airflow/.local/lib/python3.8/site-packages/airflow/operators/python.py", line 233, in execute
    return self.do_branch(context, super().execute(context))
  File "/home/airflow/.local/lib/python3.8/site-packages/airflow/operators/python.py", line 199, in execute
    return_value = self.execute_callable()
  File "/home/airflow/.local/lib/python3.8/site-packages/airflow/operators/python.py", line 216, in execute_callable
    return self.python_callable(*self.op_args, **self.op_kwargs)
  File "/opt/airflow/dags/CrawlCompanyInfo.py", line 50, in CheckTableExisting
    cursor = ConnectPostgres().cursor()
  File "/opt/airflow/dags/CrawlCompanyInfo.py", line 41, in ConnectPostgres
    raise e
  File "/opt/airflow/dags/CrawlCompanyInfo.py", line 26, in ConnectPostgres
    conn = psycopg2.connect(**params)
  File "/home/airflow/.local/lib/python3.8/site-packages/psycopg2/__init__.py", line 122, in connect
    conn = _connect(dsn, connection_factory=connection_factory, **kwasync)
psycopg2.OperationalError: connection to server at "0.0.0.0", port 5432 failed: Connection refused
	Is the server running on that host and accepting TCP/IP connections?


During handling of the above exception, another exception occurred:

Traceback (most recent call last):
  File "/home/airflow/.local/lib/python3.8/site-packages/airflow/models/taskinstance.py", line 1000, in _email_alert
    send_email(task.email, subject, html_content)
  File "/home/airflow/.local/lib/python3.8/site-packages/airflow/utils/email.py", line 80, in send_email
    return backend(
  File "/home/airflow/.local/lib/python3.8/site-packages/airflow/utils/email.py", line 154, in send_email_smtp
    send_mime_email(e_from=mail_from, e_to=recipients, mime_msg=msg, conn_id=conn_id, dryrun=dryrun)
  File "/home/airflow/.local/lib/python3.8/site-packages/airflow/utils/email.py", line 272, in send_mime_email
    smtp_conn = _get_smtp_connection(smtp_host, smtp_port, smtp_timeout, smtp_ssl)
  File "/home/airflow/.local/lib/python3.8/site-packages/airflow/utils/email.py", line 316, in _get_smtp_connection
    return smtplib.SMTP(host=host, port=port, timeout=timeout)
  File "/usr/local/lib/python3.8/smtplib.py", line 255, in __init__
    (code, msg) = self.connect(host, port)
  File "/usr/local/lib/python3.8/smtplib.py", line 339, in connect
    self.sock = self._get_socket(host, port, self.timeout)
  File "/usr/local/lib/python3.8/smtplib.py", line 310, in _get_socket
    return socket.create_connection((host, port), timeout,
  File "/usr/local/lib/python3.8/socket.py", line 808, in create_connection
    raise err
  File "/usr/local/lib/python3.8/socket.py", line 796, in create_connection
    sock.connect(sa)
OSError: [Errno 99] Cannot assign requested address

During handling of the above exception, another exception occurred:

Traceback (most recent call last):
  File "/home/airflow/.local/lib/python3.8/site-packages/airflow/models/taskinstance.py", line 824, in _handle_failure
    task_instance.email_alert(error, failure_context["task"])
  File "/home/airflow/.local/lib/python3.8/site-packages/airflow/models/taskinstance.py", line 2947, in email_alert
    _email_alert(task_instance=self, exception=exception, task=task)
  File "/home/airflow/.local/lib/python3.8/site-packages/airflow/models/taskinstance.py", line 1002, in _email_alert
    send_email(task.email, subject, html_content_err)
  File "/home/airflow/.local/lib/python3.8/site-packages/airflow/utils/email.py", line 80, in send_email
    return backend(
  File "/home/airflow/.local/lib/python3.8/site-packages/airflow/utils/email.py", line 154, in send_email_smtp
    send_mime_email(e_from=mail_from, e_to=recipients, mime_msg=msg, conn_id=conn_id, dryrun=dryrun)
  File "/home/airflow/.local/lib/python3.8/site-packages/airflow/utils/email.py", line 272, in send_mime_email
    smtp_conn = _get_smtp_connection(smtp_host, smtp_port, smtp_timeout, smtp_ssl)
  File "/home/airflow/.local/lib/python3.8/site-packages/airflow/utils/email.py", line 316, in _get_smtp_connection
    return smtplib.SMTP(host=host, port=port, timeout=timeout)
  File "/usr/local/lib/python3.8/smtplib.py", line 255, in __init__
    (code, msg) = self.connect(host, port)
  File "/usr/local/lib/python3.8/smtplib.py", line 339, in connect
    self.sock = self._get_socket(host, port, self.timeout)
  File "/usr/local/lib/python3.8/smtplib.py", line 310, in _get_socket
    return socket.create_connection((host, port), timeout,
  File "/usr/local/lib/python3.8/socket.py", line 808, in create_connection
    raise err
  File "/usr/local/lib/python3.8/socket.py", line 796, in create_connection
    sock.connect(sa)
OSError: [Errno 99] Cannot assign requested address
[2024-01-19T03:16:04.275+0000] {standard_task_runner.py:107} ERROR - Failed to execute job 178 for task CheckTableExisting (connection to server at "0.0.0.0", port 5432 failed: Connection refused
	Is the server running on that host and accepting TCP/IP connections?
; 237)
[2024-01-19T03:16:04.297+0000] {local_task_job_runner.py:234} INFO - Task exited with return code 1
[2024-01-19T03:16:04.329+0000] {taskinstance.py:3281} INFO - 0 downstream tasks scheduled from follow-on schedule check
[2024-01-19T04:05:38.323+0000] {taskinstance.py:1957} INFO - Dependencies all met for dep_context=non-requeueable deps ti=<TaskInstance: company_profile_pipeline.CheckTableExisting scheduled__2024-01-11T00:00:00+00:00 [queued]>
[2024-01-19T04:05:38.329+0000] {taskinstance.py:1957} INFO - Dependencies all met for dep_context=requeueable deps ti=<TaskInstance: company_profile_pipeline.CheckTableExisting scheduled__2024-01-11T00:00:00+00:00 [queued]>
[2024-01-19T04:05:38.329+0000] {taskinstance.py:2171} INFO - Starting attempt 1 of 1
[2024-01-19T04:05:38.337+0000] {taskinstance.py:2192} INFO - Executing <Task(BranchPythonOperator): CheckTableExisting> on 2024-01-11 00:00:00+00:00
[2024-01-19T04:05:38.341+0000] {standard_task_runner.py:60} INFO - Started process 110 to run task
[2024-01-19T04:05:38.344+0000] {standard_task_runner.py:87} INFO - Running: ['***', 'tasks', 'run', 'company_profile_pipeline', 'CheckTableExisting', 'scheduled__2024-01-11T00:00:00+00:00', '--job-id', '212', '--raw', '--subdir', 'DAGS_FOLDER/CrawlCompanyInfo.py', '--cfg-path', '/tmp/tmpep9u902j']
[2024-01-19T04:05:38.345+0000] {standard_task_runner.py:88} INFO - Job 212: Subtask CheckTableExisting
[2024-01-19T04:05:38.381+0000] {task_command.py:423} INFO - Running <TaskInstance: company_profile_pipeline.CheckTableExisting scheduled__2024-01-11T00:00:00+00:00 [running]> on host f27b64f975c2
[2024-01-19T04:05:38.421+0000] {taskinstance.py:2481} INFO - Exporting env vars: AIRFLOW_CTX_DAG_EMAIL='anh.ho@tititada.com' AIRFLOW_CTX_DAG_OWNER='anh.ho' AIRFLOW_CTX_DAG_ID='company_profile_pipeline' AIRFLOW_CTX_TASK_ID='CheckTableExisting' AIRFLOW_CTX_EXECUTION_DATE='2024-01-11T00:00:00+00:00' AIRFLOW_CTX_TRY_NUMBER='1' AIRFLOW_CTX_DAG_RUN_ID='scheduled__2024-01-11T00:00:00+00:00'
[2024-01-19T04:05:38.422+0000] {logging_mixin.py:188} INFO - Connecting to the PostgreSQL database...
[2024-01-19T04:05:38.424+0000] {logging_mixin.py:188} INFO - PostgreSQL database version:
[2024-01-19T04:05:38.425+0000] {logging_mixin.py:188} INFO - Successfully connect to Postgresql
[2024-01-19T04:05:38.425+0000] {logging_mixin.py:188} INFO - ('PostgreSQL 13.13 (Debian 13.13-1.pgdg120+1) on aarch64-unknown-linux-gnu, compiled by gcc (Debian 12.2.0-14) 12.2.0, 64-bit',)
[2024-01-19T04:05:38.426+0000] {logging_mixin.py:188} INFO - Checking existing table...
[2024-01-19T04:05:38.427+0000] {python.py:201} INFO - Done. Returned value was: InsertDataFunction
[2024-01-19T04:05:38.427+0000] {branch.py:35} INFO - Branch into InsertDataFunction
[2024-01-19T04:05:38.428+0000] {skipmixin.py:178} INFO - Following branch InsertDataFunction
[2024-01-19T04:05:38.433+0000] {taskinstance.py:2699} ERROR - Task failed with exception
Traceback (most recent call last):
  File "/home/airflow/.local/lib/python3.8/site-packages/airflow/models/taskinstance.py", line 433, in _execute_task
    result = execute_callable(context=context, **execute_callable_kwargs)
  File "/home/airflow/.local/lib/python3.8/site-packages/airflow/operators/python.py", line 233, in execute
    return self.do_branch(context, super().execute(context))
  File "/home/airflow/.local/lib/python3.8/site-packages/airflow/operators/branch.py", line 36, in do_branch
    self.skip_all_except(context["ti"], branches_to_execute)
  File "/home/airflow/.local/lib/python3.8/site-packages/airflow/models/skipmixin.py", line 213, in skip_all_except
    raise AirflowException(
airflow.exceptions.AirflowException: 'branch_task_ids' must contain only valid task_ids. Invalid tasks found: {'InsertDataFunction'}.
[2024-01-19T04:05:38.435+0000] {taskinstance.py:1138} INFO - Marking task as FAILED. dag_id=company_profile_pipeline, task_id=CheckTableExisting, execution_date=20240111T000000, start_date=20240119T040538, end_date=20240119T040538
[2024-01-19T04:05:38.442+0000] {warnings.py:109} WARNING - /home/***/.local/lib/python3.8/site-packages/***/utils/email.py:154: RemovedInAirflow3Warning: Fetching SMTP credentials from configuration variables will be deprecated in a future release. Please set credentials using a connection instead.
  send_mime_email(e_from=mail_from, e_to=recipients, mime_msg=msg, conn_id=conn_id, dryrun=dryrun)

[2024-01-19T04:05:38.444+0000] {configuration.py:1046} WARNING - section/key [smtp/smtp_user] not found in config
[2024-01-19T04:05:38.444+0000] {email.py:270} INFO - Email alerting: attempt 1
[2024-01-19T04:05:38.449+0000] {configuration.py:1046} WARNING - section/key [smtp/smtp_user] not found in config
[2024-01-19T04:05:38.450+0000] {email.py:270} INFO - Email alerting: attempt 1
[2024-01-19T04:05:38.450+0000] {taskinstance.py:826} ERROR - Failed to send email to: anh.ho@tititada.com
Traceback (most recent call last):
  File "/home/airflow/.local/lib/python3.8/site-packages/airflow/models/taskinstance.py", line 2335, in _run_raw_task
    self._execute_task_with_callbacks(context, test_mode, session=session)
  File "/home/airflow/.local/lib/python3.8/site-packages/airflow/models/taskinstance.py", line 2500, in _execute_task_with_callbacks
    result = self._execute_task(context, task_orig)
  File "/home/airflow/.local/lib/python3.8/site-packages/airflow/models/taskinstance.py", line 2517, in _execute_task
    return _execute_task(self, context, task_orig)
  File "/home/airflow/.local/lib/python3.8/site-packages/airflow/models/taskinstance.py", line 433, in _execute_task
    result = execute_callable(context=context, **execute_callable_kwargs)
  File "/home/airflow/.local/lib/python3.8/site-packages/airflow/operators/python.py", line 233, in execute
    return self.do_branch(context, super().execute(context))
  File "/home/airflow/.local/lib/python3.8/site-packages/airflow/operators/branch.py", line 36, in do_branch
    self.skip_all_except(context["ti"], branches_to_execute)
  File "/home/airflow/.local/lib/python3.8/site-packages/airflow/models/skipmixin.py", line 213, in skip_all_except
    raise AirflowException(
airflow.exceptions.AirflowException: 'branch_task_ids' must contain only valid task_ids. Invalid tasks found: {'InsertDataFunction'}.

During handling of the above exception, another exception occurred:

Traceback (most recent call last):
  File "/home/airflow/.local/lib/python3.8/site-packages/airflow/models/taskinstance.py", line 1000, in _email_alert
    send_email(task.email, subject, html_content)
  File "/home/airflow/.local/lib/python3.8/site-packages/airflow/utils/email.py", line 80, in send_email
    return backend(
  File "/home/airflow/.local/lib/python3.8/site-packages/airflow/utils/email.py", line 154, in send_email_smtp
    send_mime_email(e_from=mail_from, e_to=recipients, mime_msg=msg, conn_id=conn_id, dryrun=dryrun)
  File "/home/airflow/.local/lib/python3.8/site-packages/airflow/utils/email.py", line 272, in send_mime_email
    smtp_conn = _get_smtp_connection(smtp_host, smtp_port, smtp_timeout, smtp_ssl)
  File "/home/airflow/.local/lib/python3.8/site-packages/airflow/utils/email.py", line 316, in _get_smtp_connection
    return smtplib.SMTP(host=host, port=port, timeout=timeout)
  File "/usr/local/lib/python3.8/smtplib.py", line 255, in __init__
    (code, msg) = self.connect(host, port)
  File "/usr/local/lib/python3.8/smtplib.py", line 339, in connect
    self.sock = self._get_socket(host, port, self.timeout)
  File "/usr/local/lib/python3.8/smtplib.py", line 310, in _get_socket
    return socket.create_connection((host, port), timeout,
  File "/usr/local/lib/python3.8/socket.py", line 808, in create_connection
    raise err
  File "/usr/local/lib/python3.8/socket.py", line 796, in create_connection
    sock.connect(sa)
OSError: [Errno 99] Cannot assign requested address

During handling of the above exception, another exception occurred:

Traceback (most recent call last):
  File "/home/airflow/.local/lib/python3.8/site-packages/airflow/models/taskinstance.py", line 824, in _handle_failure
    task_instance.email_alert(error, failure_context["task"])
  File "/home/airflow/.local/lib/python3.8/site-packages/airflow/models/taskinstance.py", line 2947, in email_alert
    _email_alert(task_instance=self, exception=exception, task=task)
  File "/home/airflow/.local/lib/python3.8/site-packages/airflow/models/taskinstance.py", line 1002, in _email_alert
    send_email(task.email, subject, html_content_err)
  File "/home/airflow/.local/lib/python3.8/site-packages/airflow/utils/email.py", line 80, in send_email
    return backend(
  File "/home/airflow/.local/lib/python3.8/site-packages/airflow/utils/email.py", line 154, in send_email_smtp
    send_mime_email(e_from=mail_from, e_to=recipients, mime_msg=msg, conn_id=conn_id, dryrun=dryrun)
  File "/home/airflow/.local/lib/python3.8/site-packages/airflow/utils/email.py", line 272, in send_mime_email
    smtp_conn = _get_smtp_connection(smtp_host, smtp_port, smtp_timeout, smtp_ssl)
  File "/home/airflow/.local/lib/python3.8/site-packages/airflow/utils/email.py", line 316, in _get_smtp_connection
    return smtplib.SMTP(host=host, port=port, timeout=timeout)
  File "/usr/local/lib/python3.8/smtplib.py", line 255, in __init__
    (code, msg) = self.connect(host, port)
  File "/usr/local/lib/python3.8/smtplib.py", line 339, in connect
    self.sock = self._get_socket(host, port, self.timeout)
  File "/usr/local/lib/python3.8/smtplib.py", line 310, in _get_socket
    return socket.create_connection((host, port), timeout,
  File "/usr/local/lib/python3.8/socket.py", line 808, in create_connection
    raise err
  File "/usr/local/lib/python3.8/socket.py", line 796, in create_connection
    sock.connect(sa)
OSError: [Errno 99] Cannot assign requested address
[2024-01-19T04:05:38.460+0000] {standard_task_runner.py:107} ERROR - Failed to execute job 212 for task CheckTableExisting ('branch_task_ids' must contain only valid task_ids. Invalid tasks found: {'InsertDataFunction'}.; 110)
[2024-01-19T04:05:38.476+0000] {local_task_job_runner.py:234} INFO - Task exited with return code 1
[2024-01-19T04:05:38.500+0000] {taskinstance.py:3281} INFO - 0 downstream tasks scheduled from follow-on schedule check
[2024-01-19T04:39:28.409+0000] {taskinstance.py:1957} INFO - Dependencies all met for dep_context=non-requeueable deps ti=<TaskInstance: company_profile_pipeline.CheckTableExisting scheduled__2024-01-11T00:00:00+00:00 [queued]>
[2024-01-19T04:39:28.414+0000] {taskinstance.py:1957} INFO - Dependencies all met for dep_context=requeueable deps ti=<TaskInstance: company_profile_pipeline.CheckTableExisting scheduled__2024-01-11T00:00:00+00:00 [queued]>
[2024-01-19T04:39:28.414+0000] {taskinstance.py:2171} INFO - Starting attempt 1 of 1
[2024-01-19T04:39:28.440+0000] {taskinstance.py:2192} INFO - Executing <Task(BranchPythonOperator): CheckTableExisting> on 2024-01-11 00:00:00+00:00
[2024-01-19T04:39:28.444+0000] {standard_task_runner.py:60} INFO - Started process 234 to run task
[2024-01-19T04:39:28.446+0000] {standard_task_runner.py:87} INFO - Running: ['***', 'tasks', 'run', 'company_profile_pipeline', 'CheckTableExisting', 'scheduled__2024-01-11T00:00:00+00:00', '--job-id', '20', '--raw', '--subdir', 'DAGS_FOLDER/CrawlCompanyInfo.py', '--cfg-path', '/tmp/tmpel3wn4fz']
[2024-01-19T04:39:28.447+0000] {standard_task_runner.py:88} INFO - Job 20: Subtask CheckTableExisting
[2024-01-19T04:39:28.479+0000] {task_command.py:423} INFO - Running <TaskInstance: company_profile_pipeline.CheckTableExisting scheduled__2024-01-11T00:00:00+00:00 [running]> on host ae6c997f1cf2
[2024-01-19T04:39:28.523+0000] {taskinstance.py:2481} INFO - Exporting env vars: AIRFLOW_CTX_DAG_EMAIL='anh.ho@tititada.com' AIRFLOW_CTX_DAG_OWNER='anh.ho' AIRFLOW_CTX_DAG_ID='company_profile_pipeline' AIRFLOW_CTX_TASK_ID='CheckTableExisting' AIRFLOW_CTX_EXECUTION_DATE='2024-01-11T00:00:00+00:00' AIRFLOW_CTX_TRY_NUMBER='1' AIRFLOW_CTX_DAG_RUN_ID='scheduled__2024-01-11T00:00:00+00:00'
[2024-01-19T04:39:28.524+0000] {logging_mixin.py:188} INFO - Connecting to the PostgreSQL database...
[2024-01-19T04:39:28.526+0000] {logging_mixin.py:188} INFO - PostgreSQL database version:
[2024-01-19T04:39:28.528+0000] {logging_mixin.py:188} INFO - Successfully connect to Postgresql
[2024-01-19T04:39:28.528+0000] {logging_mixin.py:188} INFO - ('PostgreSQL 13.13 (Debian 13.13-1.pgdg120+1) on aarch64-unknown-linux-gnu, compiled by gcc (Debian 12.2.0-14) 12.2.0, 64-bit',)
[2024-01-19T04:39:28.529+0000] {logging_mixin.py:188} INFO - Checking existing table...
[2024-01-19T04:39:28.530+0000] {python.py:201} INFO - Done. Returned value was: InsertDataFunction
[2024-01-19T04:39:28.531+0000] {branch.py:35} INFO - Branch into InsertDataFunction
[2024-01-19T04:39:28.531+0000] {skipmixin.py:178} INFO - Following branch InsertDataFunction
[2024-01-19T04:39:28.538+0000] {taskinstance.py:2699} ERROR - Task failed with exception
Traceback (most recent call last):
  File "/home/airflow/.local/lib/python3.8/site-packages/airflow/models/taskinstance.py", line 433, in _execute_task
    result = execute_callable(context=context, **execute_callable_kwargs)
  File "/home/airflow/.local/lib/python3.8/site-packages/airflow/operators/python.py", line 233, in execute
    return self.do_branch(context, super().execute(context))
  File "/home/airflow/.local/lib/python3.8/site-packages/airflow/operators/branch.py", line 36, in do_branch
    self.skip_all_except(context["ti"], branches_to_execute)
  File "/home/airflow/.local/lib/python3.8/site-packages/airflow/models/skipmixin.py", line 213, in skip_all_except
    raise AirflowException(
airflow.exceptions.AirflowException: 'branch_task_ids' must contain only valid task_ids. Invalid tasks found: {'InsertDataFunction'}.
[2024-01-19T04:39:28.540+0000] {taskinstance.py:1138} INFO - Marking task as FAILED. dag_id=company_profile_pipeline, task_id=CheckTableExisting, execution_date=20240111T000000, start_date=20240119T043928, end_date=20240119T043928
[2024-01-19T04:39:28.558+0000] {warnings.py:109} WARNING - /home/***/.local/lib/python3.8/site-packages/***/utils/email.py:154: RemovedInAirflow3Warning: Fetching SMTP credentials from configuration variables will be deprecated in a future release. Please set credentials using a connection instead.
  send_mime_email(e_from=mail_from, e_to=recipients, mime_msg=msg, conn_id=conn_id, dryrun=dryrun)

[2024-01-19T04:39:28.559+0000] {configuration.py:1046} WARNING - section/key [smtp/smtp_user] not found in config
[2024-01-19T04:39:28.559+0000] {email.py:270} INFO - Email alerting: attempt 1
[2024-01-19T04:39:28.564+0000] {configuration.py:1046} WARNING - section/key [smtp/smtp_user] not found in config
[2024-01-19T04:39:28.564+0000] {email.py:270} INFO - Email alerting: attempt 1
[2024-01-19T04:39:28.565+0000] {taskinstance.py:826} ERROR - Failed to send email to: anh.ho@tititada.com
Traceback (most recent call last):
  File "/home/airflow/.local/lib/python3.8/site-packages/airflow/models/taskinstance.py", line 2335, in _run_raw_task
    self._execute_task_with_callbacks(context, test_mode, session=session)
  File "/home/airflow/.local/lib/python3.8/site-packages/airflow/models/taskinstance.py", line 2500, in _execute_task_with_callbacks
    result = self._execute_task(context, task_orig)
  File "/home/airflow/.local/lib/python3.8/site-packages/airflow/models/taskinstance.py", line 2517, in _execute_task
    return _execute_task(self, context, task_orig)
  File "/home/airflow/.local/lib/python3.8/site-packages/airflow/models/taskinstance.py", line 433, in _execute_task
    result = execute_callable(context=context, **execute_callable_kwargs)
  File "/home/airflow/.local/lib/python3.8/site-packages/airflow/operators/python.py", line 233, in execute
    return self.do_branch(context, super().execute(context))
  File "/home/airflow/.local/lib/python3.8/site-packages/airflow/operators/branch.py", line 36, in do_branch
    self.skip_all_except(context["ti"], branches_to_execute)
  File "/home/airflow/.local/lib/python3.8/site-packages/airflow/models/skipmixin.py", line 213, in skip_all_except
    raise AirflowException(
airflow.exceptions.AirflowException: 'branch_task_ids' must contain only valid task_ids. Invalid tasks found: {'InsertDataFunction'}.

During handling of the above exception, another exception occurred:

Traceback (most recent call last):
  File "/home/airflow/.local/lib/python3.8/site-packages/airflow/models/taskinstance.py", line 1000, in _email_alert
    send_email(task.email, subject, html_content)
  File "/home/airflow/.local/lib/python3.8/site-packages/airflow/utils/email.py", line 80, in send_email
    return backend(
  File "/home/airflow/.local/lib/python3.8/site-packages/airflow/utils/email.py", line 154, in send_email_smtp
    send_mime_email(e_from=mail_from, e_to=recipients, mime_msg=msg, conn_id=conn_id, dryrun=dryrun)
  File "/home/airflow/.local/lib/python3.8/site-packages/airflow/utils/email.py", line 272, in send_mime_email
    smtp_conn = _get_smtp_connection(smtp_host, smtp_port, smtp_timeout, smtp_ssl)
  File "/home/airflow/.local/lib/python3.8/site-packages/airflow/utils/email.py", line 316, in _get_smtp_connection
    return smtplib.SMTP(host=host, port=port, timeout=timeout)
  File "/usr/local/lib/python3.8/smtplib.py", line 255, in __init__
    (code, msg) = self.connect(host, port)
  File "/usr/local/lib/python3.8/smtplib.py", line 339, in connect
    self.sock = self._get_socket(host, port, self.timeout)
  File "/usr/local/lib/python3.8/smtplib.py", line 310, in _get_socket
    return socket.create_connection((host, port), timeout,
  File "/usr/local/lib/python3.8/socket.py", line 808, in create_connection
    raise err
  File "/usr/local/lib/python3.8/socket.py", line 796, in create_connection
    sock.connect(sa)
OSError: [Errno 99] Cannot assign requested address

During handling of the above exception, another exception occurred:

Traceback (most recent call last):
  File "/home/airflow/.local/lib/python3.8/site-packages/airflow/models/taskinstance.py", line 824, in _handle_failure
    task_instance.email_alert(error, failure_context["task"])
  File "/home/airflow/.local/lib/python3.8/site-packages/airflow/models/taskinstance.py", line 2947, in email_alert
    _email_alert(task_instance=self, exception=exception, task=task)
  File "/home/airflow/.local/lib/python3.8/site-packages/airflow/models/taskinstance.py", line 1002, in _email_alert
    send_email(task.email, subject, html_content_err)
  File "/home/airflow/.local/lib/python3.8/site-packages/airflow/utils/email.py", line 80, in send_email
    return backend(
  File "/home/airflow/.local/lib/python3.8/site-packages/airflow/utils/email.py", line 154, in send_email_smtp
    send_mime_email(e_from=mail_from, e_to=recipients, mime_msg=msg, conn_id=conn_id, dryrun=dryrun)
  File "/home/airflow/.local/lib/python3.8/site-packages/airflow/utils/email.py", line 272, in send_mime_email
    smtp_conn = _get_smtp_connection(smtp_host, smtp_port, smtp_timeout, smtp_ssl)
  File "/home/airflow/.local/lib/python3.8/site-packages/airflow/utils/email.py", line 316, in _get_smtp_connection
    return smtplib.SMTP(host=host, port=port, timeout=timeout)
  File "/usr/local/lib/python3.8/smtplib.py", line 255, in __init__
    (code, msg) = self.connect(host, port)
  File "/usr/local/lib/python3.8/smtplib.py", line 339, in connect
    self.sock = self._get_socket(host, port, self.timeout)
  File "/usr/local/lib/python3.8/smtplib.py", line 310, in _get_socket
    return socket.create_connection((host, port), timeout,
  File "/usr/local/lib/python3.8/socket.py", line 808, in create_connection
    raise err
  File "/usr/local/lib/python3.8/socket.py", line 796, in create_connection
    sock.connect(sa)
OSError: [Errno 99] Cannot assign requested address
[2024-01-19T04:39:28.573+0000] {standard_task_runner.py:107} ERROR - Failed to execute job 20 for task CheckTableExisting ('branch_task_ids' must contain only valid task_ids. Invalid tasks found: {'InsertDataFunction'}.; 234)
[2024-01-19T04:39:28.580+0000] {local_task_job_runner.py:234} INFO - Task exited with return code 1
[2024-01-19T04:39:28.631+0000] {taskinstance.py:3281} INFO - 0 downstream tasks scheduled from follow-on schedule check
[2024-01-19T08:13:32.746+0000] {taskinstance.py:1957} INFO - Dependencies all met for dep_context=non-requeueable deps ti=<TaskInstance: company_profile_pipeline.CheckTableExisting scheduled__2024-01-11T00:00:00+00:00 [queued]>
[2024-01-19T08:13:32.755+0000] {taskinstance.py:1957} INFO - Dependencies all met for dep_context=requeueable deps ti=<TaskInstance: company_profile_pipeline.CheckTableExisting scheduled__2024-01-11T00:00:00+00:00 [queued]>
[2024-01-19T08:13:32.755+0000] {taskinstance.py:2171} INFO - Starting attempt 1 of 1
[2024-01-19T08:13:32.763+0000] {taskinstance.py:2192} INFO - Executing <Task(BranchPythonOperator): CheckTableExisting> on 2024-01-11 00:00:00+00:00
[2024-01-19T08:13:32.768+0000] {standard_task_runner.py:60} INFO - Started process 647 to run task
[2024-01-19T08:13:32.772+0000] {standard_task_runner.py:87} INFO - Running: ['***', 'tasks', 'run', 'company_profile_pipeline', 'CheckTableExisting', 'scheduled__2024-01-11T00:00:00+00:00', '--job-id', '44', '--raw', '--subdir', 'DAGS_FOLDER/CrawlCompanyInfo.py', '--cfg-path', '/tmp/tmpgw2_ni5m']
[2024-01-19T08:13:32.776+0000] {standard_task_runner.py:88} INFO - Job 44: Subtask CheckTableExisting
[2024-01-19T08:13:32.818+0000] {task_command.py:423} INFO - Running <TaskInstance: company_profile_pipeline.CheckTableExisting scheduled__2024-01-11T00:00:00+00:00 [running]> on host 945ee41ba0c4
[2024-01-19T08:13:32.886+0000] {taskinstance.py:2481} INFO - Exporting env vars: AIRFLOW_CTX_DAG_EMAIL='anh.ho@tititada.com' AIRFLOW_CTX_DAG_OWNER='anh.ho' AIRFLOW_CTX_DAG_ID='company_profile_pipeline' AIRFLOW_CTX_TASK_ID='CheckTableExisting' AIRFLOW_CTX_EXECUTION_DATE='2024-01-11T00:00:00+00:00' AIRFLOW_CTX_TRY_NUMBER='1' AIRFLOW_CTX_DAG_RUN_ID='scheduled__2024-01-11T00:00:00+00:00'
[2024-01-19T08:13:32.887+0000] {logging_mixin.py:188} INFO - Connecting to the PostgreSQL database...
[2024-01-19T08:13:32.891+0000] {logging_mixin.py:188} INFO - PostgreSQL database version:
[2024-01-19T08:13:32.892+0000] {logging_mixin.py:188} INFO - Successfully connect to Postgresql
[2024-01-19T08:13:32.892+0000] {logging_mixin.py:188} INFO - ('PostgreSQL 13.13 (Debian 13.13-1.pgdg120+1) on aarch64-unknown-linux-gnu, compiled by gcc (Debian 12.2.0-14) 12.2.0, 64-bit',)
[2024-01-19T08:13:32.893+0000] {logging_mixin.py:188} INFO - Checking existing table...
[2024-01-19T08:13:32.896+0000] {python.py:201} INFO - Done. Returned value was: ExistingCompanyProfile
[2024-01-19T08:13:32.897+0000] {branch.py:35} INFO - Branch into ExistingCompanyProfile
[2024-01-19T08:13:32.899+0000] {skipmixin.py:178} INFO - Following branch ExistingCompanyProfile
[2024-01-19T08:13:32.912+0000] {skipmixin.py:244} INFO - Skipping tasks [('CreateCompanyProfileTable', -1)]
[2024-01-19T08:13:32.942+0000] {taskinstance.py:1138} INFO - Marking task as SUCCESS. dag_id=company_profile_pipeline, task_id=CheckTableExisting, execution_date=20240111T000000, start_date=20240119T081332, end_date=20240119T081332
[2024-01-19T08:13:32.995+0000] {local_task_job_runner.py:234} INFO - Task exited with return code 0
[2024-01-19T08:13:33.026+0000] {taskinstance.py:3281} INFO - 1 downstream tasks scheduled from follow-on schedule check
[2024-01-19T12:12:17.180+0000] {taskinstance.py:1957} INFO - Dependencies all met for dep_context=non-requeueable deps ti=<TaskInstance: company_profile_pipeline.CheckTableExisting scheduled__2024-01-11T00:00:00+00:00 [queued]>
[2024-01-19T12:12:17.185+0000] {taskinstance.py:1957} INFO - Dependencies all met for dep_context=requeueable deps ti=<TaskInstance: company_profile_pipeline.CheckTableExisting scheduled__2024-01-11T00:00:00+00:00 [queued]>
[2024-01-19T12:12:17.185+0000] {taskinstance.py:2171} INFO - Starting attempt 1 of 1
[2024-01-19T12:12:17.191+0000] {taskinstance.py:2192} INFO - Executing <Task(BranchPythonOperator): CheckTableExisting> on 2024-01-11 00:00:00+00:00
[2024-01-19T12:12:17.197+0000] {standard_task_runner.py:60} INFO - Started process 84 to run task
[2024-01-19T12:12:17.201+0000] {standard_task_runner.py:87} INFO - Running: ['***', 'tasks', 'run', 'company_profile_pipeline', 'CheckTableExisting', 'scheduled__2024-01-11T00:00:00+00:00', '--job-id', '16', '--raw', '--subdir', 'DAGS_FOLDER/CrawlCompanyInfo.py', '--cfg-path', '/tmp/tmp3jpkzy3q']
[2024-01-19T12:12:17.202+0000] {standard_task_runner.py:88} INFO - Job 16: Subtask CheckTableExisting
[2024-01-19T12:12:17.233+0000] {task_command.py:423} INFO - Running <TaskInstance: company_profile_pipeline.CheckTableExisting scheduled__2024-01-11T00:00:00+00:00 [running]> on host 438eff074d5a
[2024-01-19T12:12:17.270+0000] {taskinstance.py:2481} INFO - Exporting env vars: AIRFLOW_CTX_DAG_EMAIL='anh.ho@tititada.com' AIRFLOW_CTX_DAG_OWNER='anh.ho' AIRFLOW_CTX_DAG_ID='company_profile_pipeline' AIRFLOW_CTX_TASK_ID='CheckTableExisting' AIRFLOW_CTX_EXECUTION_DATE='2024-01-11T00:00:00+00:00' AIRFLOW_CTX_TRY_NUMBER='1' AIRFLOW_CTX_DAG_RUN_ID='scheduled__2024-01-11T00:00:00+00:00'
[2024-01-19T12:12:17.271+0000] {logging_mixin.py:188} INFO - Connecting to the PostgreSQL database...
[2024-01-19T12:12:17.273+0000] {taskinstance.py:2699} ERROR - Task failed with exception
Traceback (most recent call last):
  File "/home/airflow/.local/lib/python3.8/site-packages/airflow/models/taskinstance.py", line 433, in _execute_task
    result = execute_callable(context=context, **execute_callable_kwargs)
  File "/home/airflow/.local/lib/python3.8/site-packages/airflow/operators/python.py", line 233, in execute
    return self.do_branch(context, super().execute(context))
  File "/home/airflow/.local/lib/python3.8/site-packages/airflow/operators/python.py", line 199, in execute
    return_value = self.execute_callable()
  File "/home/airflow/.local/lib/python3.8/site-packages/airflow/operators/python.py", line 216, in execute_callable
    return self.python_callable(*self.op_args, **self.op_kwargs)
  File "/opt/airflow/dags/CrawlCompanyInfo.py", line 50, in CheckTableExisting
    cursor = ConnectPostgres().cursor()
  File "/opt/airflow/dags/CrawlCompanyInfo.py", line 41, in ConnectPostgres
    raise e
  File "/opt/airflow/dags/CrawlCompanyInfo.py", line 26, in ConnectPostgres
    conn = psycopg2.connect(**params)
  File "/home/airflow/.local/lib/python3.8/site-packages/psycopg2/__init__.py", line 122, in connect
    conn = _connect(dsn, connection_factory=connection_factory, **kwasync)
psycopg2.OperationalError: connection to server at "postgres" (172.20.0.2), port 5432 failed: FATAL:  database "StockProject" does not exist

[2024-01-19T12:12:17.278+0000] {taskinstance.py:1138} INFO - Marking task as FAILED. dag_id=company_profile_pipeline, task_id=CheckTableExisting, execution_date=20240111T000000, start_date=20240119T121217, end_date=20240119T121217
[2024-01-19T12:12:17.285+0000] {warnings.py:109} WARNING - /home/***/.local/lib/python3.8/site-packages/***/utils/email.py:154: RemovedInAirflow3Warning: Fetching SMTP credentials from configuration variables will be deprecated in a future release. Please set credentials using a connection instead.
  send_mime_email(e_from=mail_from, e_to=recipients, mime_msg=msg, conn_id=conn_id, dryrun=dryrun)

[2024-01-19T12:12:17.285+0000] {configuration.py:1046} WARNING - section/key [smtp/smtp_user] not found in config
[2024-01-19T12:12:17.285+0000] {email.py:270} INFO - Email alerting: attempt 1
[2024-01-19T12:12:17.289+0000] {configuration.py:1046} WARNING - section/key [smtp/smtp_user] not found in config
[2024-01-19T12:12:17.290+0000] {email.py:270} INFO - Email alerting: attempt 1
[2024-01-19T12:12:17.290+0000] {taskinstance.py:826} ERROR - Failed to send email to: anh.ho@tititada.com
Traceback (most recent call last):
  File "/home/airflow/.local/lib/python3.8/site-packages/airflow/models/taskinstance.py", line 2335, in _run_raw_task
    self._execute_task_with_callbacks(context, test_mode, session=session)
  File "/home/airflow/.local/lib/python3.8/site-packages/airflow/models/taskinstance.py", line 2500, in _execute_task_with_callbacks
    result = self._execute_task(context, task_orig)
  File "/home/airflow/.local/lib/python3.8/site-packages/airflow/models/taskinstance.py", line 2517, in _execute_task
    return _execute_task(self, context, task_orig)
  File "/home/airflow/.local/lib/python3.8/site-packages/airflow/models/taskinstance.py", line 433, in _execute_task
    result = execute_callable(context=context, **execute_callable_kwargs)
  File "/home/airflow/.local/lib/python3.8/site-packages/airflow/operators/python.py", line 233, in execute
    return self.do_branch(context, super().execute(context))
  File "/home/airflow/.local/lib/python3.8/site-packages/airflow/operators/python.py", line 199, in execute
    return_value = self.execute_callable()
  File "/home/airflow/.local/lib/python3.8/site-packages/airflow/operators/python.py", line 216, in execute_callable
    return self.python_callable(*self.op_args, **self.op_kwargs)
  File "/opt/airflow/dags/CrawlCompanyInfo.py", line 50, in CheckTableExisting
    cursor = ConnectPostgres().cursor()
  File "/opt/airflow/dags/CrawlCompanyInfo.py", line 41, in ConnectPostgres
    raise e
  File "/opt/airflow/dags/CrawlCompanyInfo.py", line 26, in ConnectPostgres
    conn = psycopg2.connect(**params)
  File "/home/airflow/.local/lib/python3.8/site-packages/psycopg2/__init__.py", line 122, in connect
    conn = _connect(dsn, connection_factory=connection_factory, **kwasync)
psycopg2.OperationalError: connection to server at "postgres" (172.20.0.2), port 5432 failed: FATAL:  database "StockProject" does not exist


During handling of the above exception, another exception occurred:

Traceback (most recent call last):
  File "/home/airflow/.local/lib/python3.8/site-packages/airflow/models/taskinstance.py", line 1000, in _email_alert
    send_email(task.email, subject, html_content)
  File "/home/airflow/.local/lib/python3.8/site-packages/airflow/utils/email.py", line 80, in send_email
    return backend(
  File "/home/airflow/.local/lib/python3.8/site-packages/airflow/utils/email.py", line 154, in send_email_smtp
    send_mime_email(e_from=mail_from, e_to=recipients, mime_msg=msg, conn_id=conn_id, dryrun=dryrun)
  File "/home/airflow/.local/lib/python3.8/site-packages/airflow/utils/email.py", line 272, in send_mime_email
    smtp_conn = _get_smtp_connection(smtp_host, smtp_port, smtp_timeout, smtp_ssl)
  File "/home/airflow/.local/lib/python3.8/site-packages/airflow/utils/email.py", line 316, in _get_smtp_connection
    return smtplib.SMTP(host=host, port=port, timeout=timeout)
  File "/usr/local/lib/python3.8/smtplib.py", line 255, in __init__
    (code, msg) = self.connect(host, port)
  File "/usr/local/lib/python3.8/smtplib.py", line 339, in connect
    self.sock = self._get_socket(host, port, self.timeout)
  File "/usr/local/lib/python3.8/smtplib.py", line 310, in _get_socket
    return socket.create_connection((host, port), timeout,
  File "/usr/local/lib/python3.8/socket.py", line 808, in create_connection
    raise err
  File "/usr/local/lib/python3.8/socket.py", line 796, in create_connection
    sock.connect(sa)
OSError: [Errno 99] Cannot assign requested address

During handling of the above exception, another exception occurred:

Traceback (most recent call last):
  File "/home/airflow/.local/lib/python3.8/site-packages/airflow/models/taskinstance.py", line 824, in _handle_failure
    task_instance.email_alert(error, failure_context["task"])
  File "/home/airflow/.local/lib/python3.8/site-packages/airflow/models/taskinstance.py", line 2947, in email_alert
    _email_alert(task_instance=self, exception=exception, task=task)
  File "/home/airflow/.local/lib/python3.8/site-packages/airflow/models/taskinstance.py", line 1002, in _email_alert
    send_email(task.email, subject, html_content_err)
  File "/home/airflow/.local/lib/python3.8/site-packages/airflow/utils/email.py", line 80, in send_email
    return backend(
  File "/home/airflow/.local/lib/python3.8/site-packages/airflow/utils/email.py", line 154, in send_email_smtp
    send_mime_email(e_from=mail_from, e_to=recipients, mime_msg=msg, conn_id=conn_id, dryrun=dryrun)
  File "/home/airflow/.local/lib/python3.8/site-packages/airflow/utils/email.py", line 272, in send_mime_email
    smtp_conn = _get_smtp_connection(smtp_host, smtp_port, smtp_timeout, smtp_ssl)
  File "/home/airflow/.local/lib/python3.8/site-packages/airflow/utils/email.py", line 316, in _get_smtp_connection
    return smtplib.SMTP(host=host, port=port, timeout=timeout)
  File "/usr/local/lib/python3.8/smtplib.py", line 255, in __init__
    (code, msg) = self.connect(host, port)
  File "/usr/local/lib/python3.8/smtplib.py", line 339, in connect
    self.sock = self._get_socket(host, port, self.timeout)
  File "/usr/local/lib/python3.8/smtplib.py", line 310, in _get_socket
    return socket.create_connection((host, port), timeout,
  File "/usr/local/lib/python3.8/socket.py", line 808, in create_connection
    raise err
  File "/usr/local/lib/python3.8/socket.py", line 796, in create_connection
    sock.connect(sa)
OSError: [Errno 99] Cannot assign requested address
[2024-01-19T12:12:17.298+0000] {standard_task_runner.py:107} ERROR - Failed to execute job 16 for task CheckTableExisting (connection to server at "postgres" (172.20.0.2), port 5432 failed: FATAL:  database "StockProject" does not exist
; 84)
[2024-01-19T12:12:17.333+0000] {local_task_job_runner.py:234} INFO - Task exited with return code 1
[2024-01-19T12:12:17.381+0000] {taskinstance.py:3281} INFO - 0 downstream tasks scheduled from follow-on schedule check
