[2024-01-18T09:57:15.646+0000] {taskinstance.py:1957} INFO - Dependencies all met for dep_context=non-requeueable deps ti=<TaskInstance: company_profile_pipeline.CheckTableExisting scheduled__2024-01-16T00:00:00+00:00 [queued]>
[2024-01-18T09:57:15.650+0000] {taskinstance.py:1957} INFO - Dependencies all met for dep_context=requeueable deps ti=<TaskInstance: company_profile_pipeline.CheckTableExisting scheduled__2024-01-16T00:00:00+00:00 [queued]>
[2024-01-18T09:57:15.651+0000] {taskinstance.py:2171} INFO - Starting attempt 1 of 1
[2024-01-18T09:57:15.657+0000] {taskinstance.py:2192} INFO - Executing <Task(BranchPythonOperator): CheckTableExisting> on 2024-01-16 00:00:00+00:00
[2024-01-18T09:57:15.660+0000] {standard_task_runner.py:60} INFO - Started process 111 to run task
[2024-01-18T09:57:15.662+0000] {standard_task_runner.py:87} INFO - Running: ['***', 'tasks', 'run', 'company_profile_pipeline', 'CheckTableExisting', 'scheduled__2024-01-16T00:00:00+00:00', '--job-id', '33', '--raw', '--subdir', 'DAGS_FOLDER/CrawlCompanyInfo.py', '--cfg-path', '/tmp/tmpcxsvtj2j']
[2024-01-18T09:57:15.663+0000] {standard_task_runner.py:88} INFO - Job 33: Subtask CheckTableExisting
[2024-01-18T09:57:15.693+0000] {task_command.py:423} INFO - Running <TaskInstance: company_profile_pipeline.CheckTableExisting scheduled__2024-01-16T00:00:00+00:00 [running]> on host a56b2d2a6d76
[2024-01-18T09:57:15.726+0000] {taskinstance.py:2481} INFO - Exporting env vars: AIRFLOW_CTX_DAG_EMAIL='anh.ho@tititada.com' AIRFLOW_CTX_DAG_OWNER='anh.ho' AIRFLOW_CTX_DAG_ID='company_profile_pipeline' AIRFLOW_CTX_TASK_ID='CheckTableExisting' AIRFLOW_CTX_EXECUTION_DATE='2024-01-16T00:00:00+00:00' AIRFLOW_CTX_TRY_NUMBER='1' AIRFLOW_CTX_DAG_RUN_ID='scheduled__2024-01-16T00:00:00+00:00'
[2024-01-18T09:57:15.727+0000] {taskinstance.py:2699} ERROR - Task failed with exception
Traceback (most recent call last):
  File "/home/airflow/.local/lib/python3.8/site-packages/airflow/models/taskinstance.py", line 433, in _execute_task
    result = execute_callable(context=context, **execute_callable_kwargs)
  File "/home/airflow/.local/lib/python3.8/site-packages/airflow/operators/python.py", line 233, in execute
    return self.do_branch(context, super().execute(context))
  File "/home/airflow/.local/lib/python3.8/site-packages/airflow/operators/python.py", line 199, in execute
    return_value = self.execute_callable()
  File "/home/airflow/.local/lib/python3.8/site-packages/airflow/operators/python.py", line 216, in execute_callable
    return self.python_callable(*self.op_args, **self.op_kwargs)
  File "/opt/airflow/dags/CrawlCompanyInfo.py", line 55, in CheckTableExisting
    cursor = ConnectPostgres().cursor()
  File "/opt/airflow/dags/CrawlCompanyInfo.py", line 27, in ConnectPostgres
    params = ReadConfigFile(relative_path,section)
  File "/opt/airflow/dags/GetAuthInfoFuncton.py", line 25, in ReadConfigFile
    raise Exception('Section {0} not found in the {1} file'.format(section, text_file_path))
Exception: Section Postgresql not found in the /Users/anhho/Desktop/DataEngineer/CrawlStockData/CrawlFunction/Authorization.ini file
[2024-01-18T09:57:15.731+0000] {taskinstance.py:1138} INFO - Marking task as FAILED. dag_id=company_profile_pipeline, task_id=CheckTableExisting, execution_date=20240116T000000, start_date=20240118T095715, end_date=20240118T095715
[2024-01-18T09:57:15.738+0000] {warnings.py:109} WARNING - /home/***/.local/lib/python3.8/site-packages/***/utils/email.py:154: RemovedInAirflow3Warning: Fetching SMTP credentials from configuration variables will be deprecated in a future release. Please set credentials using a connection instead.
  send_mime_email(e_from=mail_from, e_to=recipients, mime_msg=msg, conn_id=conn_id, dryrun=dryrun)

[2024-01-18T09:57:15.738+0000] {configuration.py:1046} WARNING - section/key [smtp/smtp_user] not found in config
[2024-01-18T09:57:15.738+0000] {email.py:270} INFO - Email alerting: attempt 1
[2024-01-18T09:57:15.742+0000] {configuration.py:1046} WARNING - section/key [smtp/smtp_user] not found in config
[2024-01-18T09:57:15.742+0000] {email.py:270} INFO - Email alerting: attempt 1
[2024-01-18T09:57:15.743+0000] {taskinstance.py:826} ERROR - Failed to send email to: anh.ho@tititada.com
Traceback (most recent call last):
  File "/home/airflow/.local/lib/python3.8/site-packages/airflow/models/taskinstance.py", line 2335, in _run_raw_task
    self._execute_task_with_callbacks(context, test_mode, session=session)
  File "/home/airflow/.local/lib/python3.8/site-packages/airflow/models/taskinstance.py", line 2500, in _execute_task_with_callbacks
    result = self._execute_task(context, task_orig)
  File "/home/airflow/.local/lib/python3.8/site-packages/airflow/models/taskinstance.py", line 2517, in _execute_task
    return _execute_task(self, context, task_orig)
  File "/home/airflow/.local/lib/python3.8/site-packages/airflow/models/taskinstance.py", line 433, in _execute_task
    result = execute_callable(context=context, **execute_callable_kwargs)
  File "/home/airflow/.local/lib/python3.8/site-packages/airflow/operators/python.py", line 233, in execute
    return self.do_branch(context, super().execute(context))
  File "/home/airflow/.local/lib/python3.8/site-packages/airflow/operators/python.py", line 199, in execute
    return_value = self.execute_callable()
  File "/home/airflow/.local/lib/python3.8/site-packages/airflow/operators/python.py", line 216, in execute_callable
    return self.python_callable(*self.op_args, **self.op_kwargs)
  File "/opt/airflow/dags/CrawlCompanyInfo.py", line 55, in CheckTableExisting
    cursor = ConnectPostgres().cursor()
  File "/opt/airflow/dags/CrawlCompanyInfo.py", line 27, in ConnectPostgres
    params = ReadConfigFile(relative_path,section)
  File "/opt/airflow/dags/GetAuthInfoFuncton.py", line 25, in ReadConfigFile
    raise Exception('Section {0} not found in the {1} file'.format(section, text_file_path))
Exception: Section Postgresql not found in the /Users/anhho/Desktop/DataEngineer/CrawlStockData/CrawlFunction/Authorization.ini file

During handling of the above exception, another exception occurred:

Traceback (most recent call last):
  File "/home/airflow/.local/lib/python3.8/site-packages/airflow/models/taskinstance.py", line 1000, in _email_alert
    send_email(task.email, subject, html_content)
  File "/home/airflow/.local/lib/python3.8/site-packages/airflow/utils/email.py", line 80, in send_email
    return backend(
  File "/home/airflow/.local/lib/python3.8/site-packages/airflow/utils/email.py", line 154, in send_email_smtp
    send_mime_email(e_from=mail_from, e_to=recipients, mime_msg=msg, conn_id=conn_id, dryrun=dryrun)
  File "/home/airflow/.local/lib/python3.8/site-packages/airflow/utils/email.py", line 272, in send_mime_email
    smtp_conn = _get_smtp_connection(smtp_host, smtp_port, smtp_timeout, smtp_ssl)
  File "/home/airflow/.local/lib/python3.8/site-packages/airflow/utils/email.py", line 316, in _get_smtp_connection
    return smtplib.SMTP(host=host, port=port, timeout=timeout)
  File "/usr/local/lib/python3.8/smtplib.py", line 255, in __init__
    (code, msg) = self.connect(host, port)
  File "/usr/local/lib/python3.8/smtplib.py", line 339, in connect
    self.sock = self._get_socket(host, port, self.timeout)
  File "/usr/local/lib/python3.8/smtplib.py", line 310, in _get_socket
    return socket.create_connection((host, port), timeout,
  File "/usr/local/lib/python3.8/socket.py", line 808, in create_connection
    raise err
  File "/usr/local/lib/python3.8/socket.py", line 796, in create_connection
    sock.connect(sa)
OSError: [Errno 99] Cannot assign requested address

During handling of the above exception, another exception occurred:

Traceback (most recent call last):
  File "/home/airflow/.local/lib/python3.8/site-packages/airflow/models/taskinstance.py", line 824, in _handle_failure
    task_instance.email_alert(error, failure_context["task"])
  File "/home/airflow/.local/lib/python3.8/site-packages/airflow/models/taskinstance.py", line 2947, in email_alert
    _email_alert(task_instance=self, exception=exception, task=task)
  File "/home/airflow/.local/lib/python3.8/site-packages/airflow/models/taskinstance.py", line 1002, in _email_alert
    send_email(task.email, subject, html_content_err)
  File "/home/airflow/.local/lib/python3.8/site-packages/airflow/utils/email.py", line 80, in send_email
    return backend(
  File "/home/airflow/.local/lib/python3.8/site-packages/airflow/utils/email.py", line 154, in send_email_smtp
    send_mime_email(e_from=mail_from, e_to=recipients, mime_msg=msg, conn_id=conn_id, dryrun=dryrun)
  File "/home/airflow/.local/lib/python3.8/site-packages/airflow/utils/email.py", line 272, in send_mime_email
    smtp_conn = _get_smtp_connection(smtp_host, smtp_port, smtp_timeout, smtp_ssl)
  File "/home/airflow/.local/lib/python3.8/site-packages/airflow/utils/email.py", line 316, in _get_smtp_connection
    return smtplib.SMTP(host=host, port=port, timeout=timeout)
  File "/usr/local/lib/python3.8/smtplib.py", line 255, in __init__
    (code, msg) = self.connect(host, port)
  File "/usr/local/lib/python3.8/smtplib.py", line 339, in connect
    self.sock = self._get_socket(host, port, self.timeout)
  File "/usr/local/lib/python3.8/smtplib.py", line 310, in _get_socket
    return socket.create_connection((host, port), timeout,
  File "/usr/local/lib/python3.8/socket.py", line 808, in create_connection
    raise err
  File "/usr/local/lib/python3.8/socket.py", line 796, in create_connection
    sock.connect(sa)
OSError: [Errno 99] Cannot assign requested address
[2024-01-18T09:57:15.749+0000] {standard_task_runner.py:107} ERROR - Failed to execute job 33 for task CheckTableExisting (Section Postgresql not found in the /Users/anhho/Desktop/DataEngineer/CrawlStockData/CrawlFunction/Authorization.ini file; 111)
[2024-01-18T09:57:15.754+0000] {local_task_job_runner.py:234} INFO - Task exited with return code 1
[2024-01-18T09:57:15.770+0000] {taskinstance.py:3281} INFO - 0 downstream tasks scheduled from follow-on schedule check
[2024-01-18T10:01:03.074+0000] {taskinstance.py:1957} INFO - Dependencies all met for dep_context=non-requeueable deps ti=<TaskInstance: company_profile_pipeline.CheckTableExisting scheduled__2024-01-16T00:00:00+00:00 [queued]>
[2024-01-18T10:01:03.080+0000] {taskinstance.py:1957} INFO - Dependencies all met for dep_context=requeueable deps ti=<TaskInstance: company_profile_pipeline.CheckTableExisting scheduled__2024-01-16T00:00:00+00:00 [queued]>
[2024-01-18T10:01:03.080+0000] {taskinstance.py:2171} INFO - Starting attempt 1 of 1
[2024-01-18T10:01:03.088+0000] {taskinstance.py:2192} INFO - Executing <Task(BranchPythonOperator): CheckTableExisting> on 2024-01-16 00:00:00+00:00
[2024-01-18T10:01:03.092+0000] {standard_task_runner.py:60} INFO - Started process 210 to run task
[2024-01-18T10:01:03.096+0000] {standard_task_runner.py:87} INFO - Running: ['***', 'tasks', 'run', 'company_profile_pipeline', 'CheckTableExisting', 'scheduled__2024-01-16T00:00:00+00:00', '--job-id', '51', '--raw', '--subdir', 'DAGS_FOLDER/CrawlCompanyInfo.py', '--cfg-path', '/tmp/tmpzr9f33rn']
[2024-01-18T10:01:03.097+0000] {standard_task_runner.py:88} INFO - Job 51: Subtask CheckTableExisting
[2024-01-18T10:01:03.134+0000] {task_command.py:423} INFO - Running <TaskInstance: company_profile_pipeline.CheckTableExisting scheduled__2024-01-16T00:00:00+00:00 [running]> on host a56b2d2a6d76
[2024-01-18T10:01:03.173+0000] {taskinstance.py:2481} INFO - Exporting env vars: AIRFLOW_CTX_DAG_EMAIL='anh.ho@tititada.com' AIRFLOW_CTX_DAG_OWNER='anh.ho' AIRFLOW_CTX_DAG_ID='company_profile_pipeline' AIRFLOW_CTX_TASK_ID='CheckTableExisting' AIRFLOW_CTX_EXECUTION_DATE='2024-01-16T00:00:00+00:00' AIRFLOW_CTX_TRY_NUMBER='1' AIRFLOW_CTX_DAG_RUN_ID='scheduled__2024-01-16T00:00:00+00:00'
[2024-01-18T10:01:03.174+0000] {taskinstance.py:2699} ERROR - Task failed with exception
Traceback (most recent call last):
  File "/home/airflow/.local/lib/python3.8/site-packages/airflow/models/taskinstance.py", line 433, in _execute_task
    result = execute_callable(context=context, **execute_callable_kwargs)
  File "/home/airflow/.local/lib/python3.8/site-packages/airflow/operators/python.py", line 233, in execute
    return self.do_branch(context, super().execute(context))
  File "/home/airflow/.local/lib/python3.8/site-packages/airflow/operators/python.py", line 199, in execute
    return_value = self.execute_callable()
  File "/home/airflow/.local/lib/python3.8/site-packages/airflow/operators/python.py", line 216, in execute_callable
    return self.python_callable(*self.op_args, **self.op_kwargs)
  File "/opt/airflow/dags/CrawlCompanyInfo.py", line 55, in CheckTableExisting
    cursor = ConnectPostgres().cursor()
  File "/opt/airflow/dags/CrawlCompanyInfo.py", line 27, in ConnectPostgres
    params = ReadConfigFile(relative_path,section)
  File "/opt/airflow/dags/GetAuthInfoFuncton.py", line 25, in ReadConfigFile
    raise Exception('Section {section} not found in the {text_file_path} file'.format(section=section, text_file_path=text_file_path))
Exception: Section Postgresql not found in the /Users/anhho/Desktop/DataEngineer/CrawlStockData/ApacheAirflow/Authorization.ini file
[2024-01-18T10:01:03.178+0000] {taskinstance.py:1138} INFO - Marking task as FAILED. dag_id=company_profile_pipeline, task_id=CheckTableExisting, execution_date=20240116T000000, start_date=20240118T100103, end_date=20240118T100103
[2024-01-18T10:01:03.185+0000] {warnings.py:109} WARNING - /home/***/.local/lib/python3.8/site-packages/***/utils/email.py:154: RemovedInAirflow3Warning: Fetching SMTP credentials from configuration variables will be deprecated in a future release. Please set credentials using a connection instead.
  send_mime_email(e_from=mail_from, e_to=recipients, mime_msg=msg, conn_id=conn_id, dryrun=dryrun)

[2024-01-18T10:01:03.186+0000] {configuration.py:1046} WARNING - section/key [smtp/smtp_user] not found in config
[2024-01-18T10:01:03.186+0000] {email.py:270} INFO - Email alerting: attempt 1
[2024-01-18T10:01:03.190+0000] {configuration.py:1046} WARNING - section/key [smtp/smtp_user] not found in config
[2024-01-18T10:01:03.191+0000] {email.py:270} INFO - Email alerting: attempt 1
[2024-01-18T10:01:03.192+0000] {taskinstance.py:826} ERROR - Failed to send email to: anh.ho@tititada.com
Traceback (most recent call last):
  File "/home/airflow/.local/lib/python3.8/site-packages/airflow/models/taskinstance.py", line 2335, in _run_raw_task
    self._execute_task_with_callbacks(context, test_mode, session=session)
  File "/home/airflow/.local/lib/python3.8/site-packages/airflow/models/taskinstance.py", line 2500, in _execute_task_with_callbacks
    result = self._execute_task(context, task_orig)
  File "/home/airflow/.local/lib/python3.8/site-packages/airflow/models/taskinstance.py", line 2517, in _execute_task
    return _execute_task(self, context, task_orig)
  File "/home/airflow/.local/lib/python3.8/site-packages/airflow/models/taskinstance.py", line 433, in _execute_task
    result = execute_callable(context=context, **execute_callable_kwargs)
  File "/home/airflow/.local/lib/python3.8/site-packages/airflow/operators/python.py", line 233, in execute
    return self.do_branch(context, super().execute(context))
  File "/home/airflow/.local/lib/python3.8/site-packages/airflow/operators/python.py", line 199, in execute
    return_value = self.execute_callable()
  File "/home/airflow/.local/lib/python3.8/site-packages/airflow/operators/python.py", line 216, in execute_callable
    return self.python_callable(*self.op_args, **self.op_kwargs)
  File "/opt/airflow/dags/CrawlCompanyInfo.py", line 55, in CheckTableExisting
    cursor = ConnectPostgres().cursor()
  File "/opt/airflow/dags/CrawlCompanyInfo.py", line 27, in ConnectPostgres
    params = ReadConfigFile(relative_path,section)
  File "/opt/airflow/dags/GetAuthInfoFuncton.py", line 25, in ReadConfigFile
    raise Exception('Section {section} not found in the {text_file_path} file'.format(section=section, text_file_path=text_file_path))
Exception: Section Postgresql not found in the /Users/anhho/Desktop/DataEngineer/CrawlStockData/ApacheAirflow/Authorization.ini file

During handling of the above exception, another exception occurred:

Traceback (most recent call last):
  File "/home/airflow/.local/lib/python3.8/site-packages/airflow/models/taskinstance.py", line 1000, in _email_alert
    send_email(task.email, subject, html_content)
  File "/home/airflow/.local/lib/python3.8/site-packages/airflow/utils/email.py", line 80, in send_email
    return backend(
  File "/home/airflow/.local/lib/python3.8/site-packages/airflow/utils/email.py", line 154, in send_email_smtp
    send_mime_email(e_from=mail_from, e_to=recipients, mime_msg=msg, conn_id=conn_id, dryrun=dryrun)
  File "/home/airflow/.local/lib/python3.8/site-packages/airflow/utils/email.py", line 272, in send_mime_email
    smtp_conn = _get_smtp_connection(smtp_host, smtp_port, smtp_timeout, smtp_ssl)
  File "/home/airflow/.local/lib/python3.8/site-packages/airflow/utils/email.py", line 316, in _get_smtp_connection
    return smtplib.SMTP(host=host, port=port, timeout=timeout)
  File "/usr/local/lib/python3.8/smtplib.py", line 255, in __init__
    (code, msg) = self.connect(host, port)
  File "/usr/local/lib/python3.8/smtplib.py", line 339, in connect
    self.sock = self._get_socket(host, port, self.timeout)
  File "/usr/local/lib/python3.8/smtplib.py", line 310, in _get_socket
    return socket.create_connection((host, port), timeout,
  File "/usr/local/lib/python3.8/socket.py", line 808, in create_connection
    raise err
  File "/usr/local/lib/python3.8/socket.py", line 796, in create_connection
    sock.connect(sa)
OSError: [Errno 99] Cannot assign requested address

During handling of the above exception, another exception occurred:

Traceback (most recent call last):
  File "/home/airflow/.local/lib/python3.8/site-packages/airflow/models/taskinstance.py", line 824, in _handle_failure
    task_instance.email_alert(error, failure_context["task"])
  File "/home/airflow/.local/lib/python3.8/site-packages/airflow/models/taskinstance.py", line 2947, in email_alert
    _email_alert(task_instance=self, exception=exception, task=task)
  File "/home/airflow/.local/lib/python3.8/site-packages/airflow/models/taskinstance.py", line 1002, in _email_alert
    send_email(task.email, subject, html_content_err)
  File "/home/airflow/.local/lib/python3.8/site-packages/airflow/utils/email.py", line 80, in send_email
    return backend(
  File "/home/airflow/.local/lib/python3.8/site-packages/airflow/utils/email.py", line 154, in send_email_smtp
    send_mime_email(e_from=mail_from, e_to=recipients, mime_msg=msg, conn_id=conn_id, dryrun=dryrun)
  File "/home/airflow/.local/lib/python3.8/site-packages/airflow/utils/email.py", line 272, in send_mime_email
    smtp_conn = _get_smtp_connection(smtp_host, smtp_port, smtp_timeout, smtp_ssl)
  File "/home/airflow/.local/lib/python3.8/site-packages/airflow/utils/email.py", line 316, in _get_smtp_connection
    return smtplib.SMTP(host=host, port=port, timeout=timeout)
  File "/usr/local/lib/python3.8/smtplib.py", line 255, in __init__
    (code, msg) = self.connect(host, port)
  File "/usr/local/lib/python3.8/smtplib.py", line 339, in connect
    self.sock = self._get_socket(host, port, self.timeout)
  File "/usr/local/lib/python3.8/smtplib.py", line 310, in _get_socket
    return socket.create_connection((host, port), timeout,
  File "/usr/local/lib/python3.8/socket.py", line 808, in create_connection
    raise err
  File "/usr/local/lib/python3.8/socket.py", line 796, in create_connection
    sock.connect(sa)
OSError: [Errno 99] Cannot assign requested address
[2024-01-18T10:01:03.199+0000] {standard_task_runner.py:107} ERROR - Failed to execute job 51 for task CheckTableExisting (Section Postgresql not found in the /Users/anhho/Desktop/DataEngineer/CrawlStockData/ApacheAirflow/Authorization.ini file; 210)
[2024-01-18T10:01:03.229+0000] {local_task_job_runner.py:234} INFO - Task exited with return code 1
[2024-01-18T10:01:03.246+0000] {taskinstance.py:3281} INFO - 0 downstream tasks scheduled from follow-on schedule check
[2024-01-19T02:25:44.915+0000] {taskinstance.py:1957} INFO - Dependencies all met for dep_context=non-requeueable deps ti=<TaskInstance: company_profile_pipeline.CheckTableExisting scheduled__2024-01-16T00:00:00+00:00 [queued]>
[2024-01-19T02:25:44.919+0000] {taskinstance.py:1957} INFO - Dependencies all met for dep_context=requeueable deps ti=<TaskInstance: company_profile_pipeline.CheckTableExisting scheduled__2024-01-16T00:00:00+00:00 [queued]>
[2024-01-19T02:25:44.919+0000] {taskinstance.py:2171} INFO - Starting attempt 1 of 1
[2024-01-19T02:25:44.924+0000] {taskinstance.py:2192} INFO - Executing <Task(BranchPythonOperator): CheckTableExisting> on 2024-01-16 00:00:00+00:00
[2024-01-19T02:25:44.928+0000] {standard_task_runner.py:60} INFO - Started process 170 to run task
[2024-01-19T02:25:44.931+0000] {standard_task_runner.py:87} INFO - Running: ['***', 'tasks', 'run', 'company_profile_pipeline', 'CheckTableExisting', 'scheduled__2024-01-16T00:00:00+00:00', '--job-id', '85', '--raw', '--subdir', 'DAGS_FOLDER/CrawlCompanyInfo.py', '--cfg-path', '/tmp/tmp0km9hage']
[2024-01-19T02:25:44.931+0000] {standard_task_runner.py:88} INFO - Job 85: Subtask CheckTableExisting
[2024-01-19T02:25:44.956+0000] {task_command.py:423} INFO - Running <TaskInstance: company_profile_pipeline.CheckTableExisting scheduled__2024-01-16T00:00:00+00:00 [running]> on host a56b2d2a6d76
[2024-01-19T02:25:45.001+0000] {taskinstance.py:2481} INFO - Exporting env vars: AIRFLOW_CTX_DAG_EMAIL='anh.ho@tititada.com' AIRFLOW_CTX_DAG_OWNER='anh.ho' AIRFLOW_CTX_DAG_ID='company_profile_pipeline' AIRFLOW_CTX_TASK_ID='CheckTableExisting' AIRFLOW_CTX_EXECUTION_DATE='2024-01-16T00:00:00+00:00' AIRFLOW_CTX_TRY_NUMBER='1' AIRFLOW_CTX_DAG_RUN_ID='scheduled__2024-01-16T00:00:00+00:00'
[2024-01-19T02:25:45.001+0000] {logging_mixin.py:188} INFO - Connecting to the PostgreSQL database...
[2024-01-19T02:27:55.571+0000] {taskinstance.py:2699} ERROR - Task failed with exception
Traceback (most recent call last):
  File "/home/airflow/.local/lib/python3.8/site-packages/airflow/models/taskinstance.py", line 433, in _execute_task
    result = execute_callable(context=context, **execute_callable_kwargs)
  File "/home/airflow/.local/lib/python3.8/site-packages/airflow/operators/python.py", line 233, in execute
    return self.do_branch(context, super().execute(context))
  File "/home/airflow/.local/lib/python3.8/site-packages/airflow/operators/python.py", line 199, in execute
    return_value = self.execute_callable()
  File "/home/airflow/.local/lib/python3.8/site-packages/airflow/operators/python.py", line 216, in execute_callable
    return self.python_callable(*self.op_args, **self.op_kwargs)
  File "/opt/airflow/dags/CrawlCompanyInfo.py", line 50, in CheckTableExisting
    cursor = ConnectPostgres().cursor()
  File "/opt/airflow/dags/CrawlCompanyInfo.py", line 41, in ConnectPostgres
    raise e
  File "/opt/airflow/dags/CrawlCompanyInfo.py", line 26, in ConnectPostgres
    conn = psycopg2.connect(**params)
  File "/home/airflow/.local/lib/python3.8/site-packages/psycopg2/__init__.py", line 122, in connect
    conn = _connect(dsn, connection_factory=connection_factory, **kwasync)
psycopg2.OperationalError: connection to server at "172.17.0.2", port 5432 failed: Connection timed out
	Is the server running on that host and accepting TCP/IP connections?

[2024-01-19T02:27:55.609+0000] {taskinstance.py:1138} INFO - Marking task as FAILED. dag_id=company_profile_pipeline, task_id=CheckTableExisting, execution_date=20240116T000000, start_date=20240119T022544, end_date=20240119T022755
[2024-01-19T02:27:55.635+0000] {warnings.py:109} WARNING - /home/***/.local/lib/python3.8/site-packages/***/utils/email.py:154: RemovedInAirflow3Warning: Fetching SMTP credentials from configuration variables will be deprecated in a future release. Please set credentials using a connection instead.
  send_mime_email(e_from=mail_from, e_to=recipients, mime_msg=msg, conn_id=conn_id, dryrun=dryrun)

[2024-01-19T02:27:55.636+0000] {configuration.py:1046} WARNING - section/key [smtp/smtp_user] not found in config
[2024-01-19T02:27:55.636+0000] {email.py:270} INFO - Email alerting: attempt 1
[2024-01-19T02:27:55.640+0000] {configuration.py:1046} WARNING - section/key [smtp/smtp_user] not found in config
[2024-01-19T02:27:55.640+0000] {email.py:270} INFO - Email alerting: attempt 1
[2024-01-19T02:27:55.641+0000] {taskinstance.py:826} ERROR - Failed to send email to: anh.ho@tititada.com
Traceback (most recent call last):
  File "/home/airflow/.local/lib/python3.8/site-packages/airflow/models/taskinstance.py", line 2335, in _run_raw_task
    self._execute_task_with_callbacks(context, test_mode, session=session)
  File "/home/airflow/.local/lib/python3.8/site-packages/airflow/models/taskinstance.py", line 2500, in _execute_task_with_callbacks
    result = self._execute_task(context, task_orig)
  File "/home/airflow/.local/lib/python3.8/site-packages/airflow/models/taskinstance.py", line 2517, in _execute_task
    return _execute_task(self, context, task_orig)
  File "/home/airflow/.local/lib/python3.8/site-packages/airflow/models/taskinstance.py", line 433, in _execute_task
    result = execute_callable(context=context, **execute_callable_kwargs)
  File "/home/airflow/.local/lib/python3.8/site-packages/airflow/operators/python.py", line 233, in execute
    return self.do_branch(context, super().execute(context))
  File "/home/airflow/.local/lib/python3.8/site-packages/airflow/operators/python.py", line 199, in execute
    return_value = self.execute_callable()
  File "/home/airflow/.local/lib/python3.8/site-packages/airflow/operators/python.py", line 216, in execute_callable
    return self.python_callable(*self.op_args, **self.op_kwargs)
  File "/opt/airflow/dags/CrawlCompanyInfo.py", line 50, in CheckTableExisting
    cursor = ConnectPostgres().cursor()
  File "/opt/airflow/dags/CrawlCompanyInfo.py", line 41, in ConnectPostgres
    raise e
  File "/opt/airflow/dags/CrawlCompanyInfo.py", line 26, in ConnectPostgres
    conn = psycopg2.connect(**params)
  File "/home/airflow/.local/lib/python3.8/site-packages/psycopg2/__init__.py", line 122, in connect
    conn = _connect(dsn, connection_factory=connection_factory, **kwasync)
psycopg2.OperationalError: connection to server at "172.17.0.2", port 5432 failed: Connection timed out
	Is the server running on that host and accepting TCP/IP connections?


During handling of the above exception, another exception occurred:

Traceback (most recent call last):
  File "/home/airflow/.local/lib/python3.8/site-packages/airflow/models/taskinstance.py", line 1000, in _email_alert
    send_email(task.email, subject, html_content)
  File "/home/airflow/.local/lib/python3.8/site-packages/airflow/utils/email.py", line 80, in send_email
    return backend(
  File "/home/airflow/.local/lib/python3.8/site-packages/airflow/utils/email.py", line 154, in send_email_smtp
    send_mime_email(e_from=mail_from, e_to=recipients, mime_msg=msg, conn_id=conn_id, dryrun=dryrun)
  File "/home/airflow/.local/lib/python3.8/site-packages/airflow/utils/email.py", line 272, in send_mime_email
    smtp_conn = _get_smtp_connection(smtp_host, smtp_port, smtp_timeout, smtp_ssl)
  File "/home/airflow/.local/lib/python3.8/site-packages/airflow/utils/email.py", line 316, in _get_smtp_connection
    return smtplib.SMTP(host=host, port=port, timeout=timeout)
  File "/usr/local/lib/python3.8/smtplib.py", line 255, in __init__
    (code, msg) = self.connect(host, port)
  File "/usr/local/lib/python3.8/smtplib.py", line 339, in connect
    self.sock = self._get_socket(host, port, self.timeout)
  File "/usr/local/lib/python3.8/smtplib.py", line 310, in _get_socket
    return socket.create_connection((host, port), timeout,
  File "/usr/local/lib/python3.8/socket.py", line 808, in create_connection
    raise err
  File "/usr/local/lib/python3.8/socket.py", line 796, in create_connection
    sock.connect(sa)
OSError: [Errno 99] Cannot assign requested address

During handling of the above exception, another exception occurred:

Traceback (most recent call last):
  File "/home/airflow/.local/lib/python3.8/site-packages/airflow/models/taskinstance.py", line 824, in _handle_failure
    task_instance.email_alert(error, failure_context["task"])
  File "/home/airflow/.local/lib/python3.8/site-packages/airflow/models/taskinstance.py", line 2947, in email_alert
    _email_alert(task_instance=self, exception=exception, task=task)
  File "/home/airflow/.local/lib/python3.8/site-packages/airflow/models/taskinstance.py", line 1002, in _email_alert
    send_email(task.email, subject, html_content_err)
  File "/home/airflow/.local/lib/python3.8/site-packages/airflow/utils/email.py", line 80, in send_email
    return backend(
  File "/home/airflow/.local/lib/python3.8/site-packages/airflow/utils/email.py", line 154, in send_email_smtp
    send_mime_email(e_from=mail_from, e_to=recipients, mime_msg=msg, conn_id=conn_id, dryrun=dryrun)
  File "/home/airflow/.local/lib/python3.8/site-packages/airflow/utils/email.py", line 272, in send_mime_email
    smtp_conn = _get_smtp_connection(smtp_host, smtp_port, smtp_timeout, smtp_ssl)
  File "/home/airflow/.local/lib/python3.8/site-packages/airflow/utils/email.py", line 316, in _get_smtp_connection
    return smtplib.SMTP(host=host, port=port, timeout=timeout)
  File "/usr/local/lib/python3.8/smtplib.py", line 255, in __init__
    (code, msg) = self.connect(host, port)
  File "/usr/local/lib/python3.8/smtplib.py", line 339, in connect
    self.sock = self._get_socket(host, port, self.timeout)
  File "/usr/local/lib/python3.8/smtplib.py", line 310, in _get_socket
    return socket.create_connection((host, port), timeout,
  File "/usr/local/lib/python3.8/socket.py", line 808, in create_connection
    raise err
  File "/usr/local/lib/python3.8/socket.py", line 796, in create_connection
    sock.connect(sa)
OSError: [Errno 99] Cannot assign requested address
[2024-01-19T02:27:55.651+0000] {standard_task_runner.py:107} ERROR - Failed to execute job 85 for task CheckTableExisting (connection to server at "172.17.0.2", port 5432 failed: Connection timed out
	Is the server running on that host and accepting TCP/IP connections?
; 170)
[2024-01-19T02:27:55.700+0000] {local_task_job_runner.py:234} INFO - Task exited with return code 1
[2024-01-19T02:27:55.733+0000] {taskinstance.py:3281} INFO - 0 downstream tasks scheduled from follow-on schedule check
[2024-01-19T03:14:28.743+0000] {taskinstance.py:1957} INFO - Dependencies all met for dep_context=non-requeueable deps ti=<TaskInstance: company_profile_pipeline.CheckTableExisting scheduled__2024-01-16T00:00:00+00:00 [queued]>
[2024-01-19T03:14:28.749+0000] {taskinstance.py:1957} INFO - Dependencies all met for dep_context=requeueable deps ti=<TaskInstance: company_profile_pipeline.CheckTableExisting scheduled__2024-01-16T00:00:00+00:00 [queued]>
[2024-01-19T03:14:28.749+0000] {taskinstance.py:2171} INFO - Starting attempt 1 of 1
[2024-01-19T03:14:28.755+0000] {taskinstance.py:2192} INFO - Executing <Task(BranchPythonOperator): CheckTableExisting> on 2024-01-16 00:00:00+00:00
[2024-01-19T03:14:28.759+0000] {standard_task_runner.py:60} INFO - Started process 176 to run task
[2024-01-19T03:14:28.761+0000] {standard_task_runner.py:87} INFO - Running: ['***', 'tasks', 'run', 'company_profile_pipeline', 'CheckTableExisting', 'scheduled__2024-01-16T00:00:00+00:00', '--job-id', '158', '--raw', '--subdir', 'DAGS_FOLDER/CrawlCompanyInfo.py', '--cfg-path', '/tmp/tmp30pqdgwk']
[2024-01-19T03:14:28.763+0000] {standard_task_runner.py:88} INFO - Job 158: Subtask CheckTableExisting
[2024-01-19T03:14:28.796+0000] {task_command.py:423} INFO - Running <TaskInstance: company_profile_pipeline.CheckTableExisting scheduled__2024-01-16T00:00:00+00:00 [running]> on host a56b2d2a6d76
[2024-01-19T03:14:28.841+0000] {taskinstance.py:2481} INFO - Exporting env vars: AIRFLOW_CTX_DAG_EMAIL='anh.ho@tititada.com' AIRFLOW_CTX_DAG_OWNER='anh.ho' AIRFLOW_CTX_DAG_ID='company_profile_pipeline' AIRFLOW_CTX_TASK_ID='CheckTableExisting' AIRFLOW_CTX_EXECUTION_DATE='2024-01-16T00:00:00+00:00' AIRFLOW_CTX_TRY_NUMBER='1' AIRFLOW_CTX_DAG_RUN_ID='scheduled__2024-01-16T00:00:00+00:00'
[2024-01-19T03:14:28.845+0000] {logging_mixin.py:188} INFO - Connecting to the PostgreSQL database...
[2024-01-19T03:14:28.850+0000] {taskinstance.py:2699} ERROR - Task failed with exception
Traceback (most recent call last):
  File "/home/airflow/.local/lib/python3.8/site-packages/airflow/models/taskinstance.py", line 433, in _execute_task
    result = execute_callable(context=context, **execute_callable_kwargs)
  File "/home/airflow/.local/lib/python3.8/site-packages/airflow/operators/python.py", line 233, in execute
    return self.do_branch(context, super().execute(context))
  File "/home/airflow/.local/lib/python3.8/site-packages/airflow/operators/python.py", line 199, in execute
    return_value = self.execute_callable()
  File "/home/airflow/.local/lib/python3.8/site-packages/airflow/operators/python.py", line 216, in execute_callable
    return self.python_callable(*self.op_args, **self.op_kwargs)
  File "/opt/airflow/dags/CrawlCompanyInfo.py", line 50, in CheckTableExisting
    cursor = ConnectPostgres().cursor()
  File "/opt/airflow/dags/CrawlCompanyInfo.py", line 41, in ConnectPostgres
    raise e
  File "/opt/airflow/dags/CrawlCompanyInfo.py", line 26, in ConnectPostgres
    conn = psycopg2.connect(**params)
  File "/home/airflow/.local/lib/python3.8/site-packages/psycopg2/__init__.py", line 122, in connect
    conn = _connect(dsn, connection_factory=connection_factory, **kwasync)
psycopg2.OperationalError: connection to server at "0.0.0.0", port 5432 failed: Connection refused
	Is the server running on that host and accepting TCP/IP connections?

[2024-01-19T03:14:28.858+0000] {taskinstance.py:1138} INFO - Marking task as FAILED. dag_id=company_profile_pipeline, task_id=CheckTableExisting, execution_date=20240116T000000, start_date=20240119T031428, end_date=20240119T031428
[2024-01-19T03:14:28.868+0000] {warnings.py:109} WARNING - /home/***/.local/lib/python3.8/site-packages/***/utils/email.py:154: RemovedInAirflow3Warning: Fetching SMTP credentials from configuration variables will be deprecated in a future release. Please set credentials using a connection instead.
  send_mime_email(e_from=mail_from, e_to=recipients, mime_msg=msg, conn_id=conn_id, dryrun=dryrun)

[2024-01-19T03:14:28.870+0000] {configuration.py:1046} WARNING - section/key [smtp/smtp_user] not found in config
[2024-01-19T03:14:28.871+0000] {email.py:270} INFO - Email alerting: attempt 1
[2024-01-19T03:14:28.880+0000] {configuration.py:1046} WARNING - section/key [smtp/smtp_user] not found in config
[2024-01-19T03:14:28.880+0000] {email.py:270} INFO - Email alerting: attempt 1
[2024-01-19T03:14:28.881+0000] {taskinstance.py:826} ERROR - Failed to send email to: anh.ho@tititada.com
Traceback (most recent call last):
  File "/home/airflow/.local/lib/python3.8/site-packages/airflow/models/taskinstance.py", line 2335, in _run_raw_task
    self._execute_task_with_callbacks(context, test_mode, session=session)
  File "/home/airflow/.local/lib/python3.8/site-packages/airflow/models/taskinstance.py", line 2500, in _execute_task_with_callbacks
    result = self._execute_task(context, task_orig)
  File "/home/airflow/.local/lib/python3.8/site-packages/airflow/models/taskinstance.py", line 2517, in _execute_task
    return _execute_task(self, context, task_orig)
  File "/home/airflow/.local/lib/python3.8/site-packages/airflow/models/taskinstance.py", line 433, in _execute_task
    result = execute_callable(context=context, **execute_callable_kwargs)
  File "/home/airflow/.local/lib/python3.8/site-packages/airflow/operators/python.py", line 233, in execute
    return self.do_branch(context, super().execute(context))
  File "/home/airflow/.local/lib/python3.8/site-packages/airflow/operators/python.py", line 199, in execute
    return_value = self.execute_callable()
  File "/home/airflow/.local/lib/python3.8/site-packages/airflow/operators/python.py", line 216, in execute_callable
    return self.python_callable(*self.op_args, **self.op_kwargs)
  File "/opt/airflow/dags/CrawlCompanyInfo.py", line 50, in CheckTableExisting
    cursor = ConnectPostgres().cursor()
  File "/opt/airflow/dags/CrawlCompanyInfo.py", line 41, in ConnectPostgres
    raise e
  File "/opt/airflow/dags/CrawlCompanyInfo.py", line 26, in ConnectPostgres
    conn = psycopg2.connect(**params)
  File "/home/airflow/.local/lib/python3.8/site-packages/psycopg2/__init__.py", line 122, in connect
    conn = _connect(dsn, connection_factory=connection_factory, **kwasync)
psycopg2.OperationalError: connection to server at "0.0.0.0", port 5432 failed: Connection refused
	Is the server running on that host and accepting TCP/IP connections?


During handling of the above exception, another exception occurred:

Traceback (most recent call last):
  File "/home/airflow/.local/lib/python3.8/site-packages/airflow/models/taskinstance.py", line 1000, in _email_alert
    send_email(task.email, subject, html_content)
  File "/home/airflow/.local/lib/python3.8/site-packages/airflow/utils/email.py", line 80, in send_email
    return backend(
  File "/home/airflow/.local/lib/python3.8/site-packages/airflow/utils/email.py", line 154, in send_email_smtp
    send_mime_email(e_from=mail_from, e_to=recipients, mime_msg=msg, conn_id=conn_id, dryrun=dryrun)
  File "/home/airflow/.local/lib/python3.8/site-packages/airflow/utils/email.py", line 272, in send_mime_email
    smtp_conn = _get_smtp_connection(smtp_host, smtp_port, smtp_timeout, smtp_ssl)
  File "/home/airflow/.local/lib/python3.8/site-packages/airflow/utils/email.py", line 316, in _get_smtp_connection
    return smtplib.SMTP(host=host, port=port, timeout=timeout)
  File "/usr/local/lib/python3.8/smtplib.py", line 255, in __init__
    (code, msg) = self.connect(host, port)
  File "/usr/local/lib/python3.8/smtplib.py", line 339, in connect
    self.sock = self._get_socket(host, port, self.timeout)
  File "/usr/local/lib/python3.8/smtplib.py", line 310, in _get_socket
    return socket.create_connection((host, port), timeout,
  File "/usr/local/lib/python3.8/socket.py", line 808, in create_connection
    raise err
  File "/usr/local/lib/python3.8/socket.py", line 796, in create_connection
    sock.connect(sa)
OSError: [Errno 99] Cannot assign requested address

During handling of the above exception, another exception occurred:

Traceback (most recent call last):
  File "/home/airflow/.local/lib/python3.8/site-packages/airflow/models/taskinstance.py", line 824, in _handle_failure
    task_instance.email_alert(error, failure_context["task"])
  File "/home/airflow/.local/lib/python3.8/site-packages/airflow/models/taskinstance.py", line 2947, in email_alert
    _email_alert(task_instance=self, exception=exception, task=task)
  File "/home/airflow/.local/lib/python3.8/site-packages/airflow/models/taskinstance.py", line 1002, in _email_alert
    send_email(task.email, subject, html_content_err)
  File "/home/airflow/.local/lib/python3.8/site-packages/airflow/utils/email.py", line 80, in send_email
    return backend(
  File "/home/airflow/.local/lib/python3.8/site-packages/airflow/utils/email.py", line 154, in send_email_smtp
    send_mime_email(e_from=mail_from, e_to=recipients, mime_msg=msg, conn_id=conn_id, dryrun=dryrun)
  File "/home/airflow/.local/lib/python3.8/site-packages/airflow/utils/email.py", line 272, in send_mime_email
    smtp_conn = _get_smtp_connection(smtp_host, smtp_port, smtp_timeout, smtp_ssl)
  File "/home/airflow/.local/lib/python3.8/site-packages/airflow/utils/email.py", line 316, in _get_smtp_connection
    return smtplib.SMTP(host=host, port=port, timeout=timeout)
  File "/usr/local/lib/python3.8/smtplib.py", line 255, in __init__
    (code, msg) = self.connect(host, port)
  File "/usr/local/lib/python3.8/smtplib.py", line 339, in connect
    self.sock = self._get_socket(host, port, self.timeout)
  File "/usr/local/lib/python3.8/smtplib.py", line 310, in _get_socket
    return socket.create_connection((host, port), timeout,
  File "/usr/local/lib/python3.8/socket.py", line 808, in create_connection
    raise err
  File "/usr/local/lib/python3.8/socket.py", line 796, in create_connection
    sock.connect(sa)
OSError: [Errno 99] Cannot assign requested address
[2024-01-19T03:14:28.890+0000] {standard_task_runner.py:107} ERROR - Failed to execute job 158 for task CheckTableExisting (connection to server at "0.0.0.0", port 5432 failed: Connection refused
	Is the server running on that host and accepting TCP/IP connections?
; 176)
[2024-01-19T03:14:28.936+0000] {local_task_job_runner.py:234} INFO - Task exited with return code 1
[2024-01-19T03:14:28.963+0000] {taskinstance.py:3281} INFO - 0 downstream tasks scheduled from follow-on schedule check
[2024-01-19T03:16:06.917+0000] {taskinstance.py:1957} INFO - Dependencies all met for dep_context=non-requeueable deps ti=<TaskInstance: company_profile_pipeline.CheckTableExisting scheduled__2024-01-16T00:00:00+00:00 [queued]>
[2024-01-19T03:16:06.924+0000] {taskinstance.py:1957} INFO - Dependencies all met for dep_context=requeueable deps ti=<TaskInstance: company_profile_pipeline.CheckTableExisting scheduled__2024-01-16T00:00:00+00:00 [queued]>
[2024-01-19T03:16:06.925+0000] {taskinstance.py:2171} INFO - Starting attempt 1 of 1
[2024-01-19T03:16:06.934+0000] {taskinstance.py:2192} INFO - Executing <Task(BranchPythonOperator): CheckTableExisting> on 2024-01-16 00:00:00+00:00
[2024-01-19T03:16:06.938+0000] {standard_task_runner.py:60} INFO - Started process 255 to run task
[2024-01-19T03:16:06.941+0000] {standard_task_runner.py:87} INFO - Running: ['***', 'tasks', 'run', 'company_profile_pipeline', 'CheckTableExisting', 'scheduled__2024-01-16T00:00:00+00:00', '--job-id', '183', '--raw', '--subdir', 'DAGS_FOLDER/CrawlCompanyInfo.py', '--cfg-path', '/tmp/tmpf24ydk39']
[2024-01-19T03:16:06.942+0000] {standard_task_runner.py:88} INFO - Job 183: Subtask CheckTableExisting
[2024-01-19T03:16:06.976+0000] {task_command.py:423} INFO - Running <TaskInstance: company_profile_pipeline.CheckTableExisting scheduled__2024-01-16T00:00:00+00:00 [running]> on host a56b2d2a6d76
[2024-01-19T03:16:07.030+0000] {taskinstance.py:2481} INFO - Exporting env vars: AIRFLOW_CTX_DAG_EMAIL='anh.ho@tititada.com' AIRFLOW_CTX_DAG_OWNER='anh.ho' AIRFLOW_CTX_DAG_ID='company_profile_pipeline' AIRFLOW_CTX_TASK_ID='CheckTableExisting' AIRFLOW_CTX_EXECUTION_DATE='2024-01-16T00:00:00+00:00' AIRFLOW_CTX_TRY_NUMBER='1' AIRFLOW_CTX_DAG_RUN_ID='scheduled__2024-01-16T00:00:00+00:00'
[2024-01-19T03:16:07.032+0000] {logging_mixin.py:188} INFO - Connecting to the PostgreSQL database...
[2024-01-19T03:16:07.033+0000] {taskinstance.py:2699} ERROR - Task failed with exception
Traceback (most recent call last):
  File "/home/airflow/.local/lib/python3.8/site-packages/airflow/models/taskinstance.py", line 433, in _execute_task
    result = execute_callable(context=context, **execute_callable_kwargs)
  File "/home/airflow/.local/lib/python3.8/site-packages/airflow/operators/python.py", line 233, in execute
    return self.do_branch(context, super().execute(context))
  File "/home/airflow/.local/lib/python3.8/site-packages/airflow/operators/python.py", line 199, in execute
    return_value = self.execute_callable()
  File "/home/airflow/.local/lib/python3.8/site-packages/airflow/operators/python.py", line 216, in execute_callable
    return self.python_callable(*self.op_args, **self.op_kwargs)
  File "/opt/airflow/dags/CrawlCompanyInfo.py", line 50, in CheckTableExisting
    cursor = ConnectPostgres().cursor()
  File "/opt/airflow/dags/CrawlCompanyInfo.py", line 41, in ConnectPostgres
    raise e
  File "/opt/airflow/dags/CrawlCompanyInfo.py", line 26, in ConnectPostgres
    conn = psycopg2.connect(**params)
  File "/home/airflow/.local/lib/python3.8/site-packages/psycopg2/__init__.py", line 122, in connect
    conn = _connect(dsn, connection_factory=connection_factory, **kwasync)
psycopg2.OperationalError: connection to server at "0.0.0.0", port 5432 failed: Connection refused
	Is the server running on that host and accepting TCP/IP connections?

[2024-01-19T03:16:07.039+0000] {taskinstance.py:1138} INFO - Marking task as FAILED. dag_id=company_profile_pipeline, task_id=CheckTableExisting, execution_date=20240116T000000, start_date=20240119T031606, end_date=20240119T031607
[2024-01-19T03:16:07.048+0000] {warnings.py:109} WARNING - /home/***/.local/lib/python3.8/site-packages/***/utils/email.py:154: RemovedInAirflow3Warning: Fetching SMTP credentials from configuration variables will be deprecated in a future release. Please set credentials using a connection instead.
  send_mime_email(e_from=mail_from, e_to=recipients, mime_msg=msg, conn_id=conn_id, dryrun=dryrun)

[2024-01-19T03:16:07.049+0000] {configuration.py:1046} WARNING - section/key [smtp/smtp_user] not found in config
[2024-01-19T03:16:07.050+0000] {email.py:270} INFO - Email alerting: attempt 1
[2024-01-19T03:16:07.055+0000] {configuration.py:1046} WARNING - section/key [smtp/smtp_user] not found in config
[2024-01-19T03:16:07.055+0000] {email.py:270} INFO - Email alerting: attempt 1
[2024-01-19T03:16:07.056+0000] {taskinstance.py:826} ERROR - Failed to send email to: anh.ho@tititada.com
Traceback (most recent call last):
  File "/home/airflow/.local/lib/python3.8/site-packages/airflow/models/taskinstance.py", line 2335, in _run_raw_task
    self._execute_task_with_callbacks(context, test_mode, session=session)
  File "/home/airflow/.local/lib/python3.8/site-packages/airflow/models/taskinstance.py", line 2500, in _execute_task_with_callbacks
    result = self._execute_task(context, task_orig)
  File "/home/airflow/.local/lib/python3.8/site-packages/airflow/models/taskinstance.py", line 2517, in _execute_task
    return _execute_task(self, context, task_orig)
  File "/home/airflow/.local/lib/python3.8/site-packages/airflow/models/taskinstance.py", line 433, in _execute_task
    result = execute_callable(context=context, **execute_callable_kwargs)
  File "/home/airflow/.local/lib/python3.8/site-packages/airflow/operators/python.py", line 233, in execute
    return self.do_branch(context, super().execute(context))
  File "/home/airflow/.local/lib/python3.8/site-packages/airflow/operators/python.py", line 199, in execute
    return_value = self.execute_callable()
  File "/home/airflow/.local/lib/python3.8/site-packages/airflow/operators/python.py", line 216, in execute_callable
    return self.python_callable(*self.op_args, **self.op_kwargs)
  File "/opt/airflow/dags/CrawlCompanyInfo.py", line 50, in CheckTableExisting
    cursor = ConnectPostgres().cursor()
  File "/opt/airflow/dags/CrawlCompanyInfo.py", line 41, in ConnectPostgres
    raise e
  File "/opt/airflow/dags/CrawlCompanyInfo.py", line 26, in ConnectPostgres
    conn = psycopg2.connect(**params)
  File "/home/airflow/.local/lib/python3.8/site-packages/psycopg2/__init__.py", line 122, in connect
    conn = _connect(dsn, connection_factory=connection_factory, **kwasync)
psycopg2.OperationalError: connection to server at "0.0.0.0", port 5432 failed: Connection refused
	Is the server running on that host and accepting TCP/IP connections?


During handling of the above exception, another exception occurred:

Traceback (most recent call last):
  File "/home/airflow/.local/lib/python3.8/site-packages/airflow/models/taskinstance.py", line 1000, in _email_alert
    send_email(task.email, subject, html_content)
  File "/home/airflow/.local/lib/python3.8/site-packages/airflow/utils/email.py", line 80, in send_email
    return backend(
  File "/home/airflow/.local/lib/python3.8/site-packages/airflow/utils/email.py", line 154, in send_email_smtp
    send_mime_email(e_from=mail_from, e_to=recipients, mime_msg=msg, conn_id=conn_id, dryrun=dryrun)
  File "/home/airflow/.local/lib/python3.8/site-packages/airflow/utils/email.py", line 272, in send_mime_email
    smtp_conn = _get_smtp_connection(smtp_host, smtp_port, smtp_timeout, smtp_ssl)
  File "/home/airflow/.local/lib/python3.8/site-packages/airflow/utils/email.py", line 316, in _get_smtp_connection
    return smtplib.SMTP(host=host, port=port, timeout=timeout)
  File "/usr/local/lib/python3.8/smtplib.py", line 255, in __init__
    (code, msg) = self.connect(host, port)
  File "/usr/local/lib/python3.8/smtplib.py", line 339, in connect
    self.sock = self._get_socket(host, port, self.timeout)
  File "/usr/local/lib/python3.8/smtplib.py", line 310, in _get_socket
    return socket.create_connection((host, port), timeout,
  File "/usr/local/lib/python3.8/socket.py", line 808, in create_connection
    raise err
  File "/usr/local/lib/python3.8/socket.py", line 796, in create_connection
    sock.connect(sa)
OSError: [Errno 99] Cannot assign requested address

During handling of the above exception, another exception occurred:

Traceback (most recent call last):
  File "/home/airflow/.local/lib/python3.8/site-packages/airflow/models/taskinstance.py", line 824, in _handle_failure
    task_instance.email_alert(error, failure_context["task"])
  File "/home/airflow/.local/lib/python3.8/site-packages/airflow/models/taskinstance.py", line 2947, in email_alert
    _email_alert(task_instance=self, exception=exception, task=task)
  File "/home/airflow/.local/lib/python3.8/site-packages/airflow/models/taskinstance.py", line 1002, in _email_alert
    send_email(task.email, subject, html_content_err)
  File "/home/airflow/.local/lib/python3.8/site-packages/airflow/utils/email.py", line 80, in send_email
    return backend(
  File "/home/airflow/.local/lib/python3.8/site-packages/airflow/utils/email.py", line 154, in send_email_smtp
    send_mime_email(e_from=mail_from, e_to=recipients, mime_msg=msg, conn_id=conn_id, dryrun=dryrun)
  File "/home/airflow/.local/lib/python3.8/site-packages/airflow/utils/email.py", line 272, in send_mime_email
    smtp_conn = _get_smtp_connection(smtp_host, smtp_port, smtp_timeout, smtp_ssl)
  File "/home/airflow/.local/lib/python3.8/site-packages/airflow/utils/email.py", line 316, in _get_smtp_connection
    return smtplib.SMTP(host=host, port=port, timeout=timeout)
  File "/usr/local/lib/python3.8/smtplib.py", line 255, in __init__
    (code, msg) = self.connect(host, port)
  File "/usr/local/lib/python3.8/smtplib.py", line 339, in connect
    self.sock = self._get_socket(host, port, self.timeout)
  File "/usr/local/lib/python3.8/smtplib.py", line 310, in _get_socket
    return socket.create_connection((host, port), timeout,
  File "/usr/local/lib/python3.8/socket.py", line 808, in create_connection
    raise err
  File "/usr/local/lib/python3.8/socket.py", line 796, in create_connection
    sock.connect(sa)
OSError: [Errno 99] Cannot assign requested address
[2024-01-19T03:16:07.064+0000] {standard_task_runner.py:107} ERROR - Failed to execute job 183 for task CheckTableExisting (connection to server at "0.0.0.0", port 5432 failed: Connection refused
	Is the server running on that host and accepting TCP/IP connections?
; 255)
[2024-01-19T03:16:07.073+0000] {local_task_job_runner.py:234} INFO - Task exited with return code 1
[2024-01-19T03:16:07.089+0000] {taskinstance.py:3281} INFO - 0 downstream tasks scheduled from follow-on schedule check
[2024-01-19T04:05:40.822+0000] {taskinstance.py:1957} INFO - Dependencies all met for dep_context=non-requeueable deps ti=<TaskInstance: company_profile_pipeline.CheckTableExisting scheduled__2024-01-16T00:00:00+00:00 [queued]>
[2024-01-19T04:05:40.826+0000] {taskinstance.py:1957} INFO - Dependencies all met for dep_context=requeueable deps ti=<TaskInstance: company_profile_pipeline.CheckTableExisting scheduled__2024-01-16T00:00:00+00:00 [queued]>
[2024-01-19T04:05:40.826+0000] {taskinstance.py:2171} INFO - Starting attempt 1 of 1
[2024-01-19T04:05:40.833+0000] {taskinstance.py:2192} INFO - Executing <Task(BranchPythonOperator): CheckTableExisting> on 2024-01-16 00:00:00+00:00
[2024-01-19T04:05:40.837+0000] {standard_task_runner.py:60} INFO - Started process 120 to run task
[2024-01-19T04:05:40.839+0000] {standard_task_runner.py:87} INFO - Running: ['***', 'tasks', 'run', 'company_profile_pipeline', 'CheckTableExisting', 'scheduled__2024-01-16T00:00:00+00:00', '--job-id', '217', '--raw', '--subdir', 'DAGS_FOLDER/CrawlCompanyInfo.py', '--cfg-path', '/tmp/tmpym3hl0o_']
[2024-01-19T04:05:40.841+0000] {standard_task_runner.py:88} INFO - Job 217: Subtask CheckTableExisting
[2024-01-19T04:05:40.870+0000] {task_command.py:423} INFO - Running <TaskInstance: company_profile_pipeline.CheckTableExisting scheduled__2024-01-16T00:00:00+00:00 [running]> on host f27b64f975c2
[2024-01-19T04:05:40.905+0000] {taskinstance.py:2481} INFO - Exporting env vars: AIRFLOW_CTX_DAG_EMAIL='anh.ho@tititada.com' AIRFLOW_CTX_DAG_OWNER='anh.ho' AIRFLOW_CTX_DAG_ID='company_profile_pipeline' AIRFLOW_CTX_TASK_ID='CheckTableExisting' AIRFLOW_CTX_EXECUTION_DATE='2024-01-16T00:00:00+00:00' AIRFLOW_CTX_TRY_NUMBER='1' AIRFLOW_CTX_DAG_RUN_ID='scheduled__2024-01-16T00:00:00+00:00'
[2024-01-19T04:05:40.906+0000] {logging_mixin.py:188} INFO - Connecting to the PostgreSQL database...
[2024-01-19T04:05:40.908+0000] {logging_mixin.py:188} INFO - PostgreSQL database version:
[2024-01-19T04:05:40.909+0000] {logging_mixin.py:188} INFO - Successfully connect to Postgresql
[2024-01-19T04:05:40.909+0000] {logging_mixin.py:188} INFO - ('PostgreSQL 13.13 (Debian 13.13-1.pgdg120+1) on aarch64-unknown-linux-gnu, compiled by gcc (Debian 12.2.0-14) 12.2.0, 64-bit',)
[2024-01-19T04:05:40.909+0000] {logging_mixin.py:188} INFO - Checking existing table...
[2024-01-19T04:05:40.911+0000] {python.py:201} INFO - Done. Returned value was: InsertDataFunction
[2024-01-19T04:05:40.911+0000] {branch.py:35} INFO - Branch into InsertDataFunction
[2024-01-19T04:05:40.911+0000] {skipmixin.py:178} INFO - Following branch InsertDataFunction
[2024-01-19T04:05:40.915+0000] {taskinstance.py:2699} ERROR - Task failed with exception
Traceback (most recent call last):
  File "/home/airflow/.local/lib/python3.8/site-packages/airflow/models/taskinstance.py", line 433, in _execute_task
    result = execute_callable(context=context, **execute_callable_kwargs)
  File "/home/airflow/.local/lib/python3.8/site-packages/airflow/operators/python.py", line 233, in execute
    return self.do_branch(context, super().execute(context))
  File "/home/airflow/.local/lib/python3.8/site-packages/airflow/operators/branch.py", line 36, in do_branch
    self.skip_all_except(context["ti"], branches_to_execute)
  File "/home/airflow/.local/lib/python3.8/site-packages/airflow/models/skipmixin.py", line 213, in skip_all_except
    raise AirflowException(
airflow.exceptions.AirflowException: 'branch_task_ids' must contain only valid task_ids. Invalid tasks found: {'InsertDataFunction'}.
[2024-01-19T04:05:40.917+0000] {taskinstance.py:1138} INFO - Marking task as FAILED. dag_id=company_profile_pipeline, task_id=CheckTableExisting, execution_date=20240116T000000, start_date=20240119T040540, end_date=20240119T040540
[2024-01-19T04:05:40.924+0000] {warnings.py:109} WARNING - /home/***/.local/lib/python3.8/site-packages/***/utils/email.py:154: RemovedInAirflow3Warning: Fetching SMTP credentials from configuration variables will be deprecated in a future release. Please set credentials using a connection instead.
  send_mime_email(e_from=mail_from, e_to=recipients, mime_msg=msg, conn_id=conn_id, dryrun=dryrun)

[2024-01-19T04:05:40.924+0000] {configuration.py:1046} WARNING - section/key [smtp/smtp_user] not found in config
[2024-01-19T04:05:40.925+0000] {email.py:270} INFO - Email alerting: attempt 1
[2024-01-19T04:05:40.928+0000] {configuration.py:1046} WARNING - section/key [smtp/smtp_user] not found in config
[2024-01-19T04:05:40.928+0000] {email.py:270} INFO - Email alerting: attempt 1
[2024-01-19T04:05:40.928+0000] {taskinstance.py:826} ERROR - Failed to send email to: anh.ho@tititada.com
Traceback (most recent call last):
  File "/home/airflow/.local/lib/python3.8/site-packages/airflow/models/taskinstance.py", line 2335, in _run_raw_task
    self._execute_task_with_callbacks(context, test_mode, session=session)
  File "/home/airflow/.local/lib/python3.8/site-packages/airflow/models/taskinstance.py", line 2500, in _execute_task_with_callbacks
    result = self._execute_task(context, task_orig)
  File "/home/airflow/.local/lib/python3.8/site-packages/airflow/models/taskinstance.py", line 2517, in _execute_task
    return _execute_task(self, context, task_orig)
  File "/home/airflow/.local/lib/python3.8/site-packages/airflow/models/taskinstance.py", line 433, in _execute_task
    result = execute_callable(context=context, **execute_callable_kwargs)
  File "/home/airflow/.local/lib/python3.8/site-packages/airflow/operators/python.py", line 233, in execute
    return self.do_branch(context, super().execute(context))
  File "/home/airflow/.local/lib/python3.8/site-packages/airflow/operators/branch.py", line 36, in do_branch
    self.skip_all_except(context["ti"], branches_to_execute)
  File "/home/airflow/.local/lib/python3.8/site-packages/airflow/models/skipmixin.py", line 213, in skip_all_except
    raise AirflowException(
airflow.exceptions.AirflowException: 'branch_task_ids' must contain only valid task_ids. Invalid tasks found: {'InsertDataFunction'}.

During handling of the above exception, another exception occurred:

Traceback (most recent call last):
  File "/home/airflow/.local/lib/python3.8/site-packages/airflow/models/taskinstance.py", line 1000, in _email_alert
    send_email(task.email, subject, html_content)
  File "/home/airflow/.local/lib/python3.8/site-packages/airflow/utils/email.py", line 80, in send_email
    return backend(
  File "/home/airflow/.local/lib/python3.8/site-packages/airflow/utils/email.py", line 154, in send_email_smtp
    send_mime_email(e_from=mail_from, e_to=recipients, mime_msg=msg, conn_id=conn_id, dryrun=dryrun)
  File "/home/airflow/.local/lib/python3.8/site-packages/airflow/utils/email.py", line 272, in send_mime_email
    smtp_conn = _get_smtp_connection(smtp_host, smtp_port, smtp_timeout, smtp_ssl)
  File "/home/airflow/.local/lib/python3.8/site-packages/airflow/utils/email.py", line 316, in _get_smtp_connection
    return smtplib.SMTP(host=host, port=port, timeout=timeout)
  File "/usr/local/lib/python3.8/smtplib.py", line 255, in __init__
    (code, msg) = self.connect(host, port)
  File "/usr/local/lib/python3.8/smtplib.py", line 339, in connect
    self.sock = self._get_socket(host, port, self.timeout)
  File "/usr/local/lib/python3.8/smtplib.py", line 310, in _get_socket
    return socket.create_connection((host, port), timeout,
  File "/usr/local/lib/python3.8/socket.py", line 808, in create_connection
    raise err
  File "/usr/local/lib/python3.8/socket.py", line 796, in create_connection
    sock.connect(sa)
OSError: [Errno 99] Cannot assign requested address

During handling of the above exception, another exception occurred:

Traceback (most recent call last):
  File "/home/airflow/.local/lib/python3.8/site-packages/airflow/models/taskinstance.py", line 824, in _handle_failure
    task_instance.email_alert(error, failure_context["task"])
  File "/home/airflow/.local/lib/python3.8/site-packages/airflow/models/taskinstance.py", line 2947, in email_alert
    _email_alert(task_instance=self, exception=exception, task=task)
  File "/home/airflow/.local/lib/python3.8/site-packages/airflow/models/taskinstance.py", line 1002, in _email_alert
    send_email(task.email, subject, html_content_err)
  File "/home/airflow/.local/lib/python3.8/site-packages/airflow/utils/email.py", line 80, in send_email
    return backend(
  File "/home/airflow/.local/lib/python3.8/site-packages/airflow/utils/email.py", line 154, in send_email_smtp
    send_mime_email(e_from=mail_from, e_to=recipients, mime_msg=msg, conn_id=conn_id, dryrun=dryrun)
  File "/home/airflow/.local/lib/python3.8/site-packages/airflow/utils/email.py", line 272, in send_mime_email
    smtp_conn = _get_smtp_connection(smtp_host, smtp_port, smtp_timeout, smtp_ssl)
  File "/home/airflow/.local/lib/python3.8/site-packages/airflow/utils/email.py", line 316, in _get_smtp_connection
    return smtplib.SMTP(host=host, port=port, timeout=timeout)
  File "/usr/local/lib/python3.8/smtplib.py", line 255, in __init__
    (code, msg) = self.connect(host, port)
  File "/usr/local/lib/python3.8/smtplib.py", line 339, in connect
    self.sock = self._get_socket(host, port, self.timeout)
  File "/usr/local/lib/python3.8/smtplib.py", line 310, in _get_socket
    return socket.create_connection((host, port), timeout,
  File "/usr/local/lib/python3.8/socket.py", line 808, in create_connection
    raise err
  File "/usr/local/lib/python3.8/socket.py", line 796, in create_connection
    sock.connect(sa)
OSError: [Errno 99] Cannot assign requested address
[2024-01-19T04:05:40.938+0000] {standard_task_runner.py:107} ERROR - Failed to execute job 217 for task CheckTableExisting ('branch_task_ids' must contain only valid task_ids. Invalid tasks found: {'InsertDataFunction'}.; 120)
[2024-01-19T04:05:40.971+0000] {local_task_job_runner.py:234} INFO - Task exited with return code 1
[2024-01-19T04:05:40.989+0000] {taskinstance.py:3281} INFO - 0 downstream tasks scheduled from follow-on schedule check
[2024-01-19T04:39:28.792+0000] {taskinstance.py:1957} INFO - Dependencies all met for dep_context=non-requeueable deps ti=<TaskInstance: company_profile_pipeline.CheckTableExisting scheduled__2024-01-16T00:00:00+00:00 [queued]>
[2024-01-19T04:39:28.797+0000] {taskinstance.py:1957} INFO - Dependencies all met for dep_context=requeueable deps ti=<TaskInstance: company_profile_pipeline.CheckTableExisting scheduled__2024-01-16T00:00:00+00:00 [queued]>
[2024-01-19T04:39:28.797+0000] {taskinstance.py:2171} INFO - Starting attempt 1 of 1
[2024-01-19T04:39:28.803+0000] {taskinstance.py:2192} INFO - Executing <Task(BranchPythonOperator): CheckTableExisting> on 2024-01-16 00:00:00+00:00
[2024-01-19T04:39:28.806+0000] {standard_task_runner.py:60} INFO - Started process 242 to run task
[2024-01-19T04:39:28.808+0000] {standard_task_runner.py:87} INFO - Running: ['***', 'tasks', 'run', 'company_profile_pipeline', 'CheckTableExisting', 'scheduled__2024-01-16T00:00:00+00:00', '--job-id', '25', '--raw', '--subdir', 'DAGS_FOLDER/CrawlCompanyInfo.py', '--cfg-path', '/tmp/tmp34yjrznu']
[2024-01-19T04:39:28.809+0000] {standard_task_runner.py:88} INFO - Job 25: Subtask CheckTableExisting
[2024-01-19T04:39:28.833+0000] {task_command.py:423} INFO - Running <TaskInstance: company_profile_pipeline.CheckTableExisting scheduled__2024-01-16T00:00:00+00:00 [running]> on host ae6c997f1cf2
[2024-01-19T04:39:28.869+0000] {taskinstance.py:2481} INFO - Exporting env vars: AIRFLOW_CTX_DAG_EMAIL='anh.ho@tititada.com' AIRFLOW_CTX_DAG_OWNER='anh.ho' AIRFLOW_CTX_DAG_ID='company_profile_pipeline' AIRFLOW_CTX_TASK_ID='CheckTableExisting' AIRFLOW_CTX_EXECUTION_DATE='2024-01-16T00:00:00+00:00' AIRFLOW_CTX_TRY_NUMBER='1' AIRFLOW_CTX_DAG_RUN_ID='scheduled__2024-01-16T00:00:00+00:00'
[2024-01-19T04:39:28.870+0000] {logging_mixin.py:188} INFO - Connecting to the PostgreSQL database...
[2024-01-19T04:39:28.872+0000] {logging_mixin.py:188} INFO - PostgreSQL database version:
[2024-01-19T04:39:28.872+0000] {logging_mixin.py:188} INFO - Successfully connect to Postgresql
[2024-01-19T04:39:28.873+0000] {logging_mixin.py:188} INFO - ('PostgreSQL 13.13 (Debian 13.13-1.pgdg120+1) on aarch64-unknown-linux-gnu, compiled by gcc (Debian 12.2.0-14) 12.2.0, 64-bit',)
[2024-01-19T04:39:28.873+0000] {logging_mixin.py:188} INFO - Checking existing table...
[2024-01-19T04:39:28.874+0000] {python.py:201} INFO - Done. Returned value was: InsertDataFunction
[2024-01-19T04:39:28.874+0000] {branch.py:35} INFO - Branch into InsertDataFunction
[2024-01-19T04:39:28.874+0000] {skipmixin.py:178} INFO - Following branch InsertDataFunction
[2024-01-19T04:39:28.879+0000] {taskinstance.py:2699} ERROR - Task failed with exception
Traceback (most recent call last):
  File "/home/airflow/.local/lib/python3.8/site-packages/airflow/models/taskinstance.py", line 433, in _execute_task
    result = execute_callable(context=context, **execute_callable_kwargs)
  File "/home/airflow/.local/lib/python3.8/site-packages/airflow/operators/python.py", line 233, in execute
    return self.do_branch(context, super().execute(context))
  File "/home/airflow/.local/lib/python3.8/site-packages/airflow/operators/branch.py", line 36, in do_branch
    self.skip_all_except(context["ti"], branches_to_execute)
  File "/home/airflow/.local/lib/python3.8/site-packages/airflow/models/skipmixin.py", line 213, in skip_all_except
    raise AirflowException(
airflow.exceptions.AirflowException: 'branch_task_ids' must contain only valid task_ids. Invalid tasks found: {'InsertDataFunction'}.
[2024-01-19T04:39:28.881+0000] {taskinstance.py:1138} INFO - Marking task as FAILED. dag_id=company_profile_pipeline, task_id=CheckTableExisting, execution_date=20240116T000000, start_date=20240119T043928, end_date=20240119T043928
[2024-01-19T04:39:28.888+0000] {warnings.py:109} WARNING - /home/***/.local/lib/python3.8/site-packages/***/utils/email.py:154: RemovedInAirflow3Warning: Fetching SMTP credentials from configuration variables will be deprecated in a future release. Please set credentials using a connection instead.
  send_mime_email(e_from=mail_from, e_to=recipients, mime_msg=msg, conn_id=conn_id, dryrun=dryrun)

[2024-01-19T04:39:28.888+0000] {configuration.py:1046} WARNING - section/key [smtp/smtp_user] not found in config
[2024-01-19T04:39:28.889+0000] {email.py:270} INFO - Email alerting: attempt 1
[2024-01-19T04:39:28.892+0000] {configuration.py:1046} WARNING - section/key [smtp/smtp_user] not found in config
[2024-01-19T04:39:28.893+0000] {email.py:270} INFO - Email alerting: attempt 1
[2024-01-19T04:39:28.893+0000] {taskinstance.py:826} ERROR - Failed to send email to: anh.ho@tititada.com
Traceback (most recent call last):
  File "/home/airflow/.local/lib/python3.8/site-packages/airflow/models/taskinstance.py", line 2335, in _run_raw_task
    self._execute_task_with_callbacks(context, test_mode, session=session)
  File "/home/airflow/.local/lib/python3.8/site-packages/airflow/models/taskinstance.py", line 2500, in _execute_task_with_callbacks
    result = self._execute_task(context, task_orig)
  File "/home/airflow/.local/lib/python3.8/site-packages/airflow/models/taskinstance.py", line 2517, in _execute_task
    return _execute_task(self, context, task_orig)
  File "/home/airflow/.local/lib/python3.8/site-packages/airflow/models/taskinstance.py", line 433, in _execute_task
    result = execute_callable(context=context, **execute_callable_kwargs)
  File "/home/airflow/.local/lib/python3.8/site-packages/airflow/operators/python.py", line 233, in execute
    return self.do_branch(context, super().execute(context))
  File "/home/airflow/.local/lib/python3.8/site-packages/airflow/operators/branch.py", line 36, in do_branch
    self.skip_all_except(context["ti"], branches_to_execute)
  File "/home/airflow/.local/lib/python3.8/site-packages/airflow/models/skipmixin.py", line 213, in skip_all_except
    raise AirflowException(
airflow.exceptions.AirflowException: 'branch_task_ids' must contain only valid task_ids. Invalid tasks found: {'InsertDataFunction'}.

During handling of the above exception, another exception occurred:

Traceback (most recent call last):
  File "/home/airflow/.local/lib/python3.8/site-packages/airflow/models/taskinstance.py", line 1000, in _email_alert
    send_email(task.email, subject, html_content)
  File "/home/airflow/.local/lib/python3.8/site-packages/airflow/utils/email.py", line 80, in send_email
    return backend(
  File "/home/airflow/.local/lib/python3.8/site-packages/airflow/utils/email.py", line 154, in send_email_smtp
    send_mime_email(e_from=mail_from, e_to=recipients, mime_msg=msg, conn_id=conn_id, dryrun=dryrun)
  File "/home/airflow/.local/lib/python3.8/site-packages/airflow/utils/email.py", line 272, in send_mime_email
    smtp_conn = _get_smtp_connection(smtp_host, smtp_port, smtp_timeout, smtp_ssl)
  File "/home/airflow/.local/lib/python3.8/site-packages/airflow/utils/email.py", line 316, in _get_smtp_connection
    return smtplib.SMTP(host=host, port=port, timeout=timeout)
  File "/usr/local/lib/python3.8/smtplib.py", line 255, in __init__
    (code, msg) = self.connect(host, port)
  File "/usr/local/lib/python3.8/smtplib.py", line 339, in connect
    self.sock = self._get_socket(host, port, self.timeout)
  File "/usr/local/lib/python3.8/smtplib.py", line 310, in _get_socket
    return socket.create_connection((host, port), timeout,
  File "/usr/local/lib/python3.8/socket.py", line 808, in create_connection
    raise err
  File "/usr/local/lib/python3.8/socket.py", line 796, in create_connection
    sock.connect(sa)
OSError: [Errno 99] Cannot assign requested address

During handling of the above exception, another exception occurred:

Traceback (most recent call last):
  File "/home/airflow/.local/lib/python3.8/site-packages/airflow/models/taskinstance.py", line 824, in _handle_failure
    task_instance.email_alert(error, failure_context["task"])
  File "/home/airflow/.local/lib/python3.8/site-packages/airflow/models/taskinstance.py", line 2947, in email_alert
    _email_alert(task_instance=self, exception=exception, task=task)
  File "/home/airflow/.local/lib/python3.8/site-packages/airflow/models/taskinstance.py", line 1002, in _email_alert
    send_email(task.email, subject, html_content_err)
  File "/home/airflow/.local/lib/python3.8/site-packages/airflow/utils/email.py", line 80, in send_email
    return backend(
  File "/home/airflow/.local/lib/python3.8/site-packages/airflow/utils/email.py", line 154, in send_email_smtp
    send_mime_email(e_from=mail_from, e_to=recipients, mime_msg=msg, conn_id=conn_id, dryrun=dryrun)
  File "/home/airflow/.local/lib/python3.8/site-packages/airflow/utils/email.py", line 272, in send_mime_email
    smtp_conn = _get_smtp_connection(smtp_host, smtp_port, smtp_timeout, smtp_ssl)
  File "/home/airflow/.local/lib/python3.8/site-packages/airflow/utils/email.py", line 316, in _get_smtp_connection
    return smtplib.SMTP(host=host, port=port, timeout=timeout)
  File "/usr/local/lib/python3.8/smtplib.py", line 255, in __init__
    (code, msg) = self.connect(host, port)
  File "/usr/local/lib/python3.8/smtplib.py", line 339, in connect
    self.sock = self._get_socket(host, port, self.timeout)
  File "/usr/local/lib/python3.8/smtplib.py", line 310, in _get_socket
    return socket.create_connection((host, port), timeout,
  File "/usr/local/lib/python3.8/socket.py", line 808, in create_connection
    raise err
  File "/usr/local/lib/python3.8/socket.py", line 796, in create_connection
    sock.connect(sa)
OSError: [Errno 99] Cannot assign requested address
[2024-01-19T04:39:28.899+0000] {standard_task_runner.py:107} ERROR - Failed to execute job 25 for task CheckTableExisting ('branch_task_ids' must contain only valid task_ids. Invalid tasks found: {'InsertDataFunction'}.; 242)
[2024-01-19T04:39:28.946+0000] {local_task_job_runner.py:234} INFO - Task exited with return code 1
[2024-01-19T04:39:28.963+0000] {taskinstance.py:3281} INFO - 0 downstream tasks scheduled from follow-on schedule check
[2024-01-19T08:13:37.176+0000] {taskinstance.py:1957} INFO - Dependencies all met for dep_context=non-requeueable deps ti=<TaskInstance: company_profile_pipeline.CheckTableExisting scheduled__2024-01-16T00:00:00+00:00 [queued]>
[2024-01-19T08:13:37.180+0000] {taskinstance.py:1957} INFO - Dependencies all met for dep_context=requeueable deps ti=<TaskInstance: company_profile_pipeline.CheckTableExisting scheduled__2024-01-16T00:00:00+00:00 [queued]>
[2024-01-19T08:13:37.180+0000] {taskinstance.py:2171} INFO - Starting attempt 1 of 1
[2024-01-19T08:13:37.186+0000] {taskinstance.py:2192} INFO - Executing <Task(BranchPythonOperator): CheckTableExisting> on 2024-01-16 00:00:00+00:00
[2024-01-19T08:13:37.190+0000] {standard_task_runner.py:60} INFO - Started process 677 to run task
[2024-01-19T08:13:37.192+0000] {standard_task_runner.py:87} INFO - Running: ['***', 'tasks', 'run', 'company_profile_pipeline', 'CheckTableExisting', 'scheduled__2024-01-16T00:00:00+00:00', '--job-id', '59', '--raw', '--subdir', 'DAGS_FOLDER/CrawlCompanyInfo.py', '--cfg-path', '/tmp/tmpyquf42cp']
[2024-01-19T08:13:37.193+0000] {standard_task_runner.py:88} INFO - Job 59: Subtask CheckTableExisting
[2024-01-19T08:13:37.216+0000] {task_command.py:423} INFO - Running <TaskInstance: company_profile_pipeline.CheckTableExisting scheduled__2024-01-16T00:00:00+00:00 [running]> on host 945ee41ba0c4
[2024-01-19T08:13:37.255+0000] {taskinstance.py:2481} INFO - Exporting env vars: AIRFLOW_CTX_DAG_EMAIL='anh.ho@tititada.com' AIRFLOW_CTX_DAG_OWNER='anh.ho' AIRFLOW_CTX_DAG_ID='company_profile_pipeline' AIRFLOW_CTX_TASK_ID='CheckTableExisting' AIRFLOW_CTX_EXECUTION_DATE='2024-01-16T00:00:00+00:00' AIRFLOW_CTX_TRY_NUMBER='1' AIRFLOW_CTX_DAG_RUN_ID='scheduled__2024-01-16T00:00:00+00:00'
[2024-01-19T08:13:37.255+0000] {logging_mixin.py:188} INFO - Connecting to the PostgreSQL database...
[2024-01-19T08:13:37.257+0000] {logging_mixin.py:188} INFO - PostgreSQL database version:
[2024-01-19T08:13:37.258+0000] {logging_mixin.py:188} INFO - Successfully connect to Postgresql
[2024-01-19T08:13:37.258+0000] {logging_mixin.py:188} INFO - ('PostgreSQL 13.13 (Debian 13.13-1.pgdg120+1) on aarch64-unknown-linux-gnu, compiled by gcc (Debian 12.2.0-14) 12.2.0, 64-bit',)
[2024-01-19T08:13:37.258+0000] {logging_mixin.py:188} INFO - Checking existing table...
[2024-01-19T08:13:37.259+0000] {python.py:201} INFO - Done. Returned value was: ExistingCompanyProfile
[2024-01-19T08:13:37.259+0000] {branch.py:35} INFO - Branch into ExistingCompanyProfile
[2024-01-19T08:13:37.259+0000] {skipmixin.py:178} INFO - Following branch ExistingCompanyProfile
[2024-01-19T08:13:37.266+0000] {skipmixin.py:244} INFO - Skipping tasks [('CreateCompanyProfileTable', -1)]
[2024-01-19T08:13:37.285+0000] {taskinstance.py:1138} INFO - Marking task as SUCCESS. dag_id=company_profile_pipeline, task_id=CheckTableExisting, execution_date=20240116T000000, start_date=20240119T081337, end_date=20240119T081337
[2024-01-19T08:13:37.326+0000] {local_task_job_runner.py:234} INFO - Task exited with return code 0
[2024-01-19T08:13:37.343+0000] {taskinstance.py:3281} INFO - 1 downstream tasks scheduled from follow-on schedule check
